Workbook

Sheet a143
C1: scrid_start | D1: scrid_end | E1: msg_arc_sel | F1: msg_arc_name | G1: msg_dat_id | H1: a092_member_id | J1: scrid_start | K1: scrid_end | L1: msg_arc_sel | M1: msg_arc_name | N1: msg_dat_id | O1: a092_member_id
A2: 0000 | B2: =MID(Sheet2!$A$1,1+(ROW(B2)-2)*20,20) -> E803B70B01000A000000 | C2: =MID($B2,1+4*(COLUMN(C2)-3),4) -> E803 | D2: =MID($B2,1+LEN(_xlfn.CONCAT($C2:C2)),4) -> B70B | E2: =MID($B2,1+LEN(_xlfn.CONCAT($C2:D2)),2) -> 01 | F2: =MID($B2,1+LEN(_xlfn.CONCAT($C2:E2)),2) -> 00 | G2: =MID($B2,1+LEN(_xlfn.CONCAT($C2:F2)),4) -> 0A00 | H2: =MID($B2,1+LEN(_xlfn.CONCAT($C2:G2)),4) -> 0000 | I2: =MID($B2,1+LEN(_xlfn.CONCAT($C2:H2)),4) | J2: =HEX2DEC(MID(C2,3,2)&MID(C2,1,2)) -> 1000 | K2: =HEX2DEC(MID(D2,3,2)&MID(D2,1,2)) -> 2999 | L2: =HEX2DEC(MID(E2,3,2)&MID(E2,1,2)) -> 1 | M2: =HEX2DEC(MID(F2,3,2)&MID(F2,1,2)) -> 0 | N2: =HEX2DEC(MID(G2,3,2)&MID(G2,1,2)) -> 10 | O2: =HEX2DEC(MID(H2,3,2)&MID(H2,1,2)) -> 0
A3: =DEC2HEX(HEX2DEC(A2)+LEN(B2)/2,4) -> 000A | B3: =MID(Sheet2!$A$1,1+(ROW(B3)-2)*20,20) -> B80B871301000A000000 | C3: =MID($B3,1+4*(COLUMN(C3)-3),4) -> B80B | D3: =MID($B3,1+LEN(_xlfn.CONCAT($C3:C3)),4) -> 8713 | E3: =MID($B3,1+LEN(_xlfn.CONCAT($C3:D3)),2) -> 01 | F3: =MID($B3,1+LEN(_xlfn.CONCAT($C3:E3)),2) -> 00 | G3: =MID($B3,1+LEN(_xlfn.CONCAT($C3:F3)),4) -> 0A00 | H3: =MID($B3,1+LEN(_xlfn.CONCAT($C3:G3)),4) -> 0000 | I3: =MID($B3,1+LEN(_xlfn.CONCAT($C3:H3)),4) | J3: =HEX2DEC(MID(C3,3,2)&MID(C3,1,2)) -> 3000 | K3: =HEX2DEC(MID(D3,3,2)&MID(D3,1,2)) -> 4999 | L3: =HEX2DEC(MID(E3,3,2)&MID(E3,1,2)) -> 1 | M3: =HEX2DEC(MID(F3,3,2)&MID(F3,1,2)) -> 0 | N3: =HEX2DEC(MID(G3,3,2)&MID(G3,1,2)) -> 10 | O3: =HEX2DEC(MID(H3,3,2)&MID(H3,1,2)) -> 0
A4: =DEC2HEX(HEX2DEC(A3)+LEN(B3)/2,4) -> 0014 | B4: =MID(Sheet2!$A$1,1+(ROW(B4)-2)*20,20) -> 8813911301000A000100 | C4: =MID($B4,1+4*(COLUMN(C4)-3),4) -> 8813 | D4: =MID($B4,1+LEN(_xlfn.CONCAT($C4:C4)),4) -> 9113 | E4: =MID($B4,1+LEN(_xlfn.CONCAT($C4:D4)),2) -> 01 | F4: =MID($B4,1+LEN(_xlfn.CONCAT($C4:E4)),2) -> 00 | G4: =MID($B4,1+LEN(_xlfn.CONCAT($C4:F4)),4) -> 0A00 | H4: =MID($B4,1+LEN(_xlfn.CONCAT($C4:G4)),4) -> 0100 | I4: =MID($B4,1+LEN(_xlfn.CONCAT($C4:H4)),4) | J4: =HEX2DEC(MID(C4,3,2)&MID(C4,1,2)) -> 5000 | K4: =HEX2DEC(MID(D4,3,2)&MID(D4,1,2)) -> 5009 | L4: =HEX2DEC(MID(E4,3,2)&MID(E4,1,2)) -> 1 | M4: =HEX2DEC(MID(F4,3,2)&MID(F4,1,2)) -> 0 | N4: =HEX2DEC(MID(G4,3,2)&MID(G4,1,2)) -> 10 | O4: =HEX2DEC(MID(H4,3,2)&MID(H4,1,2)) -> 1
A5: =DEC2HEX(HEX2DEC(A4)+LEN(B4)/2,4) -> 001E | B5: =MID(Sheet2!$A$1,1+(ROW(B5)-2)*20,20) -> 9213A51301000A000200 | C5: =MID($B5,1+4*(COLUMN(C5)-3),4) -> 9213 | D5: =MID($B5,1+LEN(_xlfn.CONCAT($C5:C5)),4) -> A513 | E5: =MID($B5,1+LEN(_xlfn.CONCAT($C5:D5)),2) -> 01 | F5: =MID($B5,1+LEN(_xlfn.CONCAT($C5:E5)),2) -> 00 | G5: =MID($B5,1+LEN(_xlfn.CONCAT($C5:F5)),4) -> 0A00 | H5: =MID($B5,1+LEN(_xlfn.CONCAT($C5:G5)),4) -> 0200 | I5: =MID($B5,1+LEN(_xlfn.CONCAT($C5:H5)),4) | J5: =HEX2DEC(MID(C5,3,2)&MID(C5,1,2)) -> 5010 | K5: =HEX2DEC(MID(D5,3,2)&MID(D5,1,2)) -> 5029 | L5: =HEX2DEC(MID(E5,3,2)&MID(E5,1,2)) -> 1 | M5: =HEX2DEC(MID(F5,3,2)&MID(F5,1,2)) -> 0 | N5: =HEX2DEC(MID(G5,3,2)&MID(G5,1,2)) -> 10 | O5: =HEX2DEC(MID(H5,3,2)&MID(H5,1,2)) -> 2
A6: =DEC2HEX(HEX2DEC(A5)+LEN(B5)/2,4) -> 0028 | B6: =MID(Sheet2!$A$1,1+(ROW(B6)-2)*20,20) -> A613AF130100F8010300 | C6: =MID($B6,1+4*(COLUMN(C6)-3),4) -> A613 | D6: =MID($B6,1+LEN(_xlfn.CONCAT($C6:C6)),4) -> AF13 | E6: =MID($B6,1+LEN(_xlfn.CONCAT($C6:D6)),2) -> 01 | F6: =MID($B6,1+LEN(_xlfn.CONCAT($C6:E6)),2) -> 00 | G6: =MID($B6,1+LEN(_xlfn.CONCAT($C6:F6)),4) -> F801 | H6: =MID($B6,1+LEN(_xlfn.CONCAT($C6:G6)),4) -> 0300 | I6: =MID($B6,1+LEN(_xlfn.CONCAT($C6:H6)),4) | J6: =HEX2DEC(MID(C6,3,2)&MID(C6,1,2)) -> 5030 | K6: =HEX2DEC(MID(D6,3,2)&MID(D6,1,2)) -> 5039 | L6: =HEX2DEC(MID(E6,3,2)&MID(E6,1,2)) -> 1 | M6: =HEX2DEC(MID(F6,3,2)&MID(F6,1,2)) -> 0 | N6: =HEX2DEC(MID(G6,3,2)&MID(G6,1,2)) -> 504 | O6: =HEX2DEC(MID(H6,3,2)&MID(H6,1,2)) -> 3
A7: =DEC2HEX(HEX2DEC(A6)+LEN(B6)/2,4) -> 0032 | B7: =MID(Sheet2!$A$1,1+(ROW(B7)-2)*20,20) -> B013C31301000C000400 | C7: =MID($B7,1+4*(COLUMN(C7)-3),4) -> B013 | D7: =MID($B7,1+LEN(_xlfn.CONCAT($C7:C7)),4) -> C313 | E7: =MID($B7,1+LEN(_xlfn.CONCAT($C7:D7)),2) -> 01 | F7: =MID($B7,1+LEN(_xlfn.CONCAT($C7:E7)),2) -> 00 | G7: =MID($B7,1+LEN(_xlfn.CONCAT($C7:F7)),4) -> 0C00 | H7: =MID($B7,1+LEN(_xlfn.CONCAT($C7:G7)),4) -> 0400 | I7: =MID($B7,1+LEN(_xlfn.CONCAT($C7:H7)),4) | J7: =HEX2DEC(MID(C7,3,2)&MID(C7,1,2)) -> 5040 | K7: =HEX2DEC(MID(D7,3,2)&MID(D7,1,2)) -> 5059 | L7: =HEX2DEC(MID(E7,3,2)&MID(E7,1,2)) -> 1 | M7: =HEX2DEC(MID(F7,3,2)&MID(F7,1,2)) -> 0 | N7: =HEX2DEC(MID(G7,3,2)&MID(G7,1,2)) -> 12 | O7: =HEX2DEC(MID(H7,3,2)&MID(H7,1,2)) -> 4
A8: =DEC2HEX(HEX2DEC(A7)+LEN(B7)/2,4) -> 003C | B8: =MID(Sheet2!$A$1,1+(ROW(B8)-2)*20,20) -> C413CD130100F2010500 | C8: =MID($B8,1+4*(COLUMN(C8)-3),4) -> C413 | D8: =MID($B8,1+LEN(_xlfn.CONCAT($C8:C8)),4) -> CD13 | E8: =MID($B8,1+LEN(_xlfn.CONCAT($C8:D8)),2) -> 01 | F8: =MID($B8,1+LEN(_xlfn.CONCAT($C8:E8)),2) -> 00 | G8: =MID($B8,1+LEN(_xlfn.CONCAT($C8:F8)),4) -> F201 | H8: =MID($B8,1+LEN(_xlfn.CONCAT($C8:G8)),4) -> 0500 | I8: =MID($B8,1+LEN(_xlfn.CONCAT($C8:H8)),4) | J8: =HEX2DEC(MID(C8,3,2)&MID(C8,1,2)) -> 5060 | K8: =HEX2DEC(MID(D8,3,2)&MID(D8,1,2)) -> 5069 | L8: =HEX2DEC(MID(E8,3,2)&MID(E8,1,2)) -> 1 | M8: =HEX2DEC(MID(F8,3,2)&MID(F8,1,2)) -> 0 | N8: =HEX2DEC(MID(G8,3,2)&MID(G8,1,2)) -> 498 | O8: =HEX2DEC(MID(H8,3,2)&MID(H8,1,2)) -> 5
A9: =DEC2HEX(HEX2DEC(A8)+LEN(B8)/2,4) -> 0046 | B9: =MID(Sheet2!$A$1,1+(ROW(B9)-2)*20,20) -> EC131D14010012000600 | C9: =MID($B9,1+4*(COLUMN(C9)-3),4) -> EC13 | D9: =MID($B9,1+LEN(_xlfn.CONCAT($C9:C9)),4) -> 1D14 | E9: =MID($B9,1+LEN(_xlfn.CONCAT($C9:D9)),2) -> 01 | F9: =MID($B9,1+LEN(_xlfn.CONCAT($C9:E9)),2) -> 00 | G9: =MID($B9,1+LEN(_xlfn.CONCAT($C9:F9)),4) -> 1200 | H9: =MID($B9,1+LEN(_xlfn.CONCAT($C9:G9)),4) -> 0600 | I9: =MID($B9,1+LEN(_xlfn.CONCAT($C9:H9)),4) | J9: =HEX2DEC(MID(C9,3,2)&MID(C9,1,2)) -> 5100 | K9: =HEX2DEC(MID(D9,3,2)&MID(D9,1,2)) -> 5149 | L9: =HEX2DEC(MID(E9,3,2)&MID(E9,1,2)) -> 1 | M9: =HEX2DEC(MID(F9,3,2)&MID(F9,1,2)) -> 0 | N9: =HEX2DEC(MID(G9,3,2)&MID(G9,1,2)) -> 18 | O9: =HEX2DEC(MID(H9,3,2)&MID(H9,1,2)) -> 6
A10: =DEC2HEX(HEX2DEC(A9)+LEN(B9)/2,4) -> 0050 | B10: =MID(Sheet2!$A$1,1+(ROW(B10)-2)*20,20) -> 1E142214010010000700 | C10: =MID($B10,1+4*(COLUMN(C10)-3),4) -> 1E14 | D10: =MID($B10,1+LEN(_xlfn.CONCAT($C10:C10)),4) -> 2214 | E10: =MID($B10,1+LEN(_xlfn.CONCAT($C10:D10)),2) -> 01 | F10: =MID($B10,1+LEN(_xlfn.CONCAT($C10:E10)),2) -> 00 | G10: =MID($B10,1+LEN(_xlfn.CONCAT($C10:F10)),4) -> 1000 | H10: =MID($B10,1+LEN(_xlfn.CONCAT($C10:G10)),4) -> 0700 | I10: =MID($B10,1+LEN(_xlfn.CONCAT($C10:H10)),4) | J10: =HEX2DEC(MID(C10,3,2)&MID(C10,1,2)) -> 5150 | K10: =HEX2DEC(MID(D10,3,2)&MID(D10,1,2)) -> 5154 | L10: =HEX2DEC(MID(E10,3,2)&MID(E10,1,2)) -> 1 | M10: =HEX2DEC(MID(F10,3,2)&MID(F10,1,2)) -> 0 | N10: =HEX2DEC(MID(G10,3,2)&MID(G10,1,2)) -> 16 | O10: =HEX2DEC(MID(H10,3,2)&MID(H10,1,2)) -> 7
A11: =DEC2HEX(HEX2DEC(A10)+LEN(B10)/2,4) -> 005A | B11: =MID(Sheet2!$A$1,1+(ROW(B11)-2)*20,20) -> 2314271401000F000800 | C11: =MID($B11,1+4*(COLUMN(C11)-3),4) -> 2314 | D11: =MID($B11,1+LEN(_xlfn.CONCAT($C11:C11)),4) -> 2714 | E11: =MID($B11,1+LEN(_xlfn.CONCAT($C11:D11)),2) -> 01 | F11: =MID($B11,1+LEN(_xlfn.CONCAT($C11:E11)),2) -> 00 | G11: =MID($B11,1+LEN(_xlfn.CONCAT($C11:F11)),4) -> 0F00 | H11: =MID($B11,1+LEN(_xlfn.CONCAT($C11:G11)),4) -> 0800 | I11: =MID($B11,1+LEN(_xlfn.CONCAT($C11:H11)),4) | J11: =HEX2DEC(MID(C11,3,2)&MID(C11,1,2)) -> 5155 | K11: =HEX2DEC(MID(D11,3,2)&MID(D11,1,2)) -> 5159 | L11: =HEX2DEC(MID(E11,3,2)&MID(E11,1,2)) -> 1 | M11: =HEX2DEC(MID(F11,3,2)&MID(F11,1,2)) -> 0 | N11: =HEX2DEC(MID(G11,3,2)&MID(G11,1,2)) -> 15 | O11: =HEX2DEC(MID(H11,3,2)&MID(H11,1,2)) -> 8
A12: =DEC2HEX(HEX2DEC(A11)+LEN(B11)/2,4) -> 0064 | B12: =MID(Sheet2!$A$1,1+(ROW(B12)-2)*20,20) -> 28142C14010014000900 | C12: =MID($B12,1+4*(COLUMN(C12)-3),4) -> 2814 | D12: =MID($B12,1+LEN(_xlfn.CONCAT($C12:C12)),4) -> 2C14 | E12: =MID($B12,1+LEN(_xlfn.CONCAT($C12:D12)),2) -> 01 | F12: =MID($B12,1+LEN(_xlfn.CONCAT($C12:E12)),2) -> 00 | G12: =MID($B12,1+LEN(_xlfn.CONCAT($C12:F12)),4) -> 1400 | H12: =MID($B12,1+LEN(_xlfn.CONCAT($C12:G12)),4) -> 0900 | I12: =MID($B12,1+LEN(_xlfn.CONCAT($C12:H12)),4) | J12: =HEX2DEC(MID(C12,3,2)&MID(C12,1,2)) -> 5160 | K12: =HEX2DEC(MID(D12,3,2)&MID(D12,1,2)) -> 5164 | L12: =HEX2DEC(MID(E12,3,2)&MID(E12,1,2)) -> 1 | M12: =HEX2DEC(MID(F12,3,2)&MID(F12,1,2)) -> 0 | N12: =HEX2DEC(MID(G12,3,2)&MID(G12,1,2)) -> 20 | O12: =HEX2DEC(MID(H12,3,2)&MID(H12,1,2)) -> 9
A13: =DEC2HEX(HEX2DEC(A12)+LEN(B12)/2,4) -> 006E | B13: =MID(Sheet2!$A$1,1+(ROW(B13)-2)*20,20) -> 2D143114010004000A00 | C13: =MID($B13,1+4*(COLUMN(C13)-3),4) -> 2D14 | D13: =MID($B13,1+LEN(_xlfn.CONCAT($C13:C13)),4) -> 3114 | E13: =MID($B13,1+LEN(_xlfn.CONCAT($C13:D13)),2) -> 01 | F13: =MID($B13,1+LEN(_xlfn.CONCAT($C13:E13)),2) -> 00 | G13: =MID($B13,1+LEN(_xlfn.CONCAT($C13:F13)),4) -> 0400 | H13: =MID($B13,1+LEN(_xlfn.CONCAT($C13:G13)),4) -> 0A00 | I13: =MID($B13,1+LEN(_xlfn.CONCAT($C13:H13)),4) | J13: =HEX2DEC(MID(C13,3,2)&MID(C13,1,2)) -> 5165 | K13: =HEX2DEC(MID(D13,3,2)&MID(D13,1,2)) -> 5169 | L13: =HEX2DEC(MID(E13,3,2)&MID(E13,1,2)) -> 1 | M13: =HEX2DEC(MID(F13,3,2)&MID(F13,1,2)) -> 0 | N13: =HEX2DEC(MID(G13,3,2)&MID(G13,1,2)) -> 4 | O13: =HEX2DEC(MID(H13,3,2)&MID(H13,1,2)) -> 10
A14: =DEC2HEX(HEX2DEC(A13)+LEN(B13)/2,4) -> 0078 | B14: =MID(Sheet2!$A$1,1+(ROW(B14)-2)*20,20) -> 32143614010016000B00 | C14: =MID($B14,1+4*(COLUMN(C14)-3),4) -> 3214 | D14: =MID($B14,1+LEN(_xlfn.CONCAT($C14:C14)),4) -> 3614 | E14: =MID($B14,1+LEN(_xlfn.CONCAT($C14:D14)),2) -> 01 | F14: =MID($B14,1+LEN(_xlfn.CONCAT($C14:E14)),2) -> 00 | G14: =MID($B14,1+LEN(_xlfn.CONCAT($C14:F14)),4) -> 1600 | H14: =MID($B14,1+LEN(_xlfn.CONCAT($C14:G14)),4) -> 0B00 | I14: =MID($B14,1+LEN(_xlfn.CONCAT($C14:H14)),4) | J14: =HEX2DEC(MID(C14,3,2)&MID(C14,1,2)) -> 5170 | K14: =HEX2DEC(MID(D14,3,2)&MID(D14,1,2)) -> 5174 | L14: =HEX2DEC(MID(E14,3,2)&MID(E14,1,2)) -> 1 | M14: =HEX2DEC(MID(F14,3,2)&MID(F14,1,2)) -> 0 | N14: =HEX2DEC(MID(G14,3,2)&MID(G14,1,2)) -> 22 | O14: =HEX2DEC(MID(H14,3,2)&MID(H14,1,2)) -> 11
... A18: =DEC2HEX(HEX2DEC(A17)+LEN(B17)/2,4) -> 00A0 | B18: =MID(Sheet2!$A$1,1+(ROW(B18)-2)*20,20) -> 7814A914010005000F00 | C18: =MID($B18,1+4*(COLUMN(C18)-3),4) -> 7814 | D18: =MID($B18,1+LEN(_xlfn.CONCAT($C18:C18)),4) -> A914 | E18: =MID($B18,1+LEN(_xlfn.CONCAT($C18:D18)),2) -> 01 | F18: =MID($B18,1+LEN(_xlfn.CONCAT($C18:E18)),2) -> 00 | G18: =MID($B18,1+LEN(_xlfn.CONCAT($C18:F18)),4) -> 0500 | H18: =MID($B18,1+LEN(_xlfn.CONCAT($C18:G18)),4) -> 0F00 | I18: =MID($B18,1+LEN(_xlfn.CONCAT($C18:H18)),4) | J18: =HEX2DEC(MID(C18,3,2)&MID(C18,1,2)) -> 5240 | K18: =HEX2DEC(MID(D18,3,2)&MID(D18,1,2)) -> 5289 | L18: =HEX2DEC(MID(E18,3,2)&MID(E18,1,2)) -> 1 | M18: =HEX2DEC(MID(F18,3,2)&MID(F18,1,2)) -> 0 | N18: =HEX2DEC(MID(G18,3,2)&MID(G18,1,2)) -> 5 | O18: =HEX2DEC(MID(H18,3,2)&MID(H18,1,2)) -> 15
A19: =DEC2HEX(HEX2DEC(A18)+LEN(B18)/2,4) -> 00AA | B19: =MID(Sheet2!$A$1,1+(ROW(B19)-2)*20,20) -> AA14BD14010006001000 | C19: =MID($B19,1+4*(COLUMN(C19)-3),4) -> AA14 | D19: =MID($B19,1+LEN(_xlfn.CONCAT($C19:C19)),4) -> BD14 | E19: =MID($B19,1+LEN(_xlfn.CONCAT($C19:D19)),2) -> 01 | F19: =MID($B19,1+LEN(_xlfn.CONCAT($C19:E19)),2) -> 00 | G19: =MID($B19,1+LEN(_xlfn.CONCAT($C19:F19)),4) -> 0600 | H19: =MID($B19,1+LEN(_xlfn.CONCAT($C19:G19)),4) -> 1000 | I19: Café | J19: =HEX2DEC(MID(C19,3,2)&MID(C19,1,2)) -> 5290 | K19: =HEX2DEC(MID(D19,3,2)&MID(D19,1,2)) -> 5309 | L19: =HEX2DEC(MID(E19,3,2)&MID(E19,1,2)) -> 1 | M19: =HEX2DEC(MID(F19,3,2)&MID(F19,1,2)) -> 0 | N19: =HEX2DEC(MID(G19,3,2)&MID(G19,1,2)) -> 6 | O19: =HEX2DEC(MID(H19,3,2)&MID(H19,1,2)) -> 16
A20: =DEC2HEX(HEX2DEC(A19)+LEN(B19)/2,4) -> 00B4 | B20: =MID(Sheet2!$A$1,1+(ROW(B20)-2)*20,20) -> BE14DB1401000B001100 | C20: =MID($B20,1+4*(COLUMN(C20)-3),4) -> BE14 | D20: =MID($B20,1+LEN(_xlfn.CONCAT($C20:C20)),4) -> DB14 | E20: =MID($B20,1+LEN(_xlfn.CONCAT($C20:D20)),2) -> 01 | F20: =MID($B20,1+LEN(_xlfn.CONCAT($C20:E20)),2) -> 00 | G20: =MID($B20,1+LEN(_xlfn.CONCAT($C20:F20)),4) -> 0B00 | H20: =MID($B20,1+LEN(_xlfn.CONCAT($C20:G20)),4) -> 1100 | I20: =MID($B20,1+LEN(_xlfn.CONCAT($C20:H20)),4) | J20: =HEX2DEC(MID(C20,3,2)&MID(C20,1,2)) -> 5310 | K20: =HEX2DEC(MID(D20,3,2)&MID(D20,1,2)) -> 5339 | L20: =HEX2DEC(MID(E20,3,2)&MID(E20,1,2)) -> 1 | M20: =HEX2DEC(MID(F20,3,2)&MID(F20,1,2)) -> 0 | N20: =HEX2DEC(MID(G20,3,2)&MID(G20,1,2)) -> 11 | O20: =HEX2DEC(MID(H20,3,2)&MID(H20,1,2)) -> 17
A21: =DEC2HEX(HEX2DEC(A20)+LEN(B20)/2,4) -> 00BE | B21: =MID(Sheet2!$A$1,1+(ROW(B21)-2)*20,20) -> 1815491500005F001200 | C21: =MID($B21,1+4*(COLUMN(C21)-3),4) -> 1815 | D21: =MID($B21,1+LEN(_xlfn.CONCAT($C21:C21)),4) -> 4915 | E21: =MID($B21,1+LEN(_xlfn.CONCAT($C21:D21)),2) -> 00 | F21: =MID($B21,1+LEN(_xlfn.CONCAT($C21:E21)),2) -> 00 | G21: =MID($B21,1+LEN(_xlfn.CONCAT($C21:F21)),4) -> 5F00 | H21: =MID($B21,1+LEN(_xlfn.CONCAT($C21:G21)),4) -> 1200 | I21: =MID($B21,1+LEN(_xlfn.CONCAT($C21:H21)),4) | J21: =HEX2DEC(MID(C21,3,2)&MID(C21,1,2)) -> 5400 | K21: =HEX2DEC(MID(D21,3,2)&MID(D21,1,2)) -> 5449 | L21: =HEX2DEC(MID(E21,3,2)&MID(E21,1,2)) -> 0 | M21: =HEX2DEC(MID(F21,3,2)&MID(F21,1,2)) -> 0 | N21: =HEX2DEC(MID(G21,3,2)&MID(G21,1,2)) -> 95 | O21: =HEX2DEC(MID(H21,3,2)&MID(H21,1,2)) -> 18
A22: =DEC2HEX(HEX2DEC(A21)+LEN(B21)/2,4) -> 00C8 | B22: =MID(Sheet2!$A$1,1+(ROW(B22)-2)*20,20) -> 4A155D15010011001300 | C22: =MID($B22,1+4*(COLUMN(C22)-3),4) -> 4A15 | D22: =MID($B22,1+LEN(_xlfn.CONCAT($C22:C22)),4) -> 5D15 | E22: =MID($B22,1+LEN(_xlfn.CONCAT($C22:D22)),2) -> 01 | F22: =MID($B22,1+LEN(_xlfn.CONCAT($C22:E22)),2) -> 00 | G22: =MID($B22,1+LEN(_xlfn.CONCAT($C22:F22)),4) -> 1100 | H22: =MID($B22,1+LEN(_xlfn.CONCAT($C22:G22)),4) -> 1300 | I22: =MID($B22,1+LEN(_xlfn.CONCAT($C22:H22)),4) | J22: =HEX2DEC(MID(C22,3,2)&MID(C22,1,2)) -> 5450 | K22: =HEX2DEC(MID(D22,3,2)&MID(D22,1,2)) -> 5469 | L22: =HEX2DEC(MID(E22,3,2)&MID(E22,1,2)) -> 1 | M22: =HEX2DEC(MID(F22,3,2)&MID(F22,1,2)) -> 0 | N22: =HEX2DEC(MID(G22,3,2)&MID(G22,1,2)) -> 17 | O22: =HEX2DEC(MID(H22,3,2)&MID(H22,1,2)) -> 19
A23: =DEC2HEX(HEX2DEC(A22)+LEN(B22)/2,4) -> 00D2 | B23: =MID(Sheet2!$A$1,1+(ROW(B23)-2)*20,20) -> 5E156215010013001400 | C23: =MID($B23,1+4*(COLUMN(C23)-3),4) -> 5E15 | D23: =MID($B23,1+LEN(_xlfn.CONCAT($C23:C23)),4) -> 6215 | E23: =MID($B23,1+LEN(_xlfn.CONCAT($C23:D23)),2) -> 01 | F23: =MID($B23,1+LEN(_xlfn.CONCAT($C23:E23)),2) -> 00 | G23: =MID($B23,1+LEN(_xlfn.CONCAT($C23:F23)),4) -> 1300 | H23: =MID($B23,1+LEN(_xlfn.CONCAT($C23:G23)),4) -> 1400 | I23: =MID($B23,1+LEN(_xlfn.CONCAT($C23:H23)),4) | J23: =HEX2DEC(MID(C23,3,2)&MID(C23,1,2)) -> 5470 | K23: =HEX2DEC(MID(D23,3,2)&MID(D23,1,2)) -> 5474 | L23: =HEX2DEC(MID(E23,3,2)&MID(E23,1,2)) -> 1 | M23: =HEX2DEC(MID(F23,3,2)&MID(F23,1,2)) -> 0 | N23: =HEX2DEC(MID(G23,3,2)&MID(G23,1,2)) -> 19 | O23: =HEX2DEC(MID(H23,3,2)&MID(H23,1,2)) -> 20
A24: =DEC2HEX(HEX2DEC(A23)+LEN(B23)/2,4) -> 00DC | B24: =MID(Sheet2!$A$1,1+(ROW(B24)-2)*20,20) -> 63156C150100F2011500 | C24: =MID($B24,1+4*(COLUMN(C24)-3),4) -> 6315 | D24: =MID($B24,1+LEN(_xlfn.CONCAT($C24:C24)),4) -> 6C15 | E24: =MID($B24,1+LEN(_xlfn.CONCAT($C24:D24)),2) -> 01 | F24: =MID($B24,1+LEN(_xlfn.CONCAT($C24:E24)),2) -> 00 | G24: =MID($B24,1+LEN(_xlfn.CONCAT($C24:F24)),4) -> F201 | H24: =MID($B24,1+LEN(_xlfn.CONCAT($C24:G24)),4) -> 1500 | I24: =MID($B24,1+LEN(_xlfn.CONCAT($C24:H24)),4) | J24: =HEX2DEC(MID(C24,3,2)&MID(C24,1,2)) -> 5475 | K24: =HEX2DEC(MID(D24,3,2)&MID(D24,1,2)) -> 5484 | L24: =HEX2DEC(MID(E24,3,2)&MID(E24,1,2)) -> 1 | M24: =HEX2DEC(MID(F24,3,2)&MID(F24,1,2)) -> 0 | N24: =HEX2DEC(MID(G24,3,2)&MID(G24,1,2)) -> 498 | O24: =HEX2DEC(MID(H24,3,2)&MID(H24,1,2)) -> 21
A25: =DEC2HEX(HEX2DEC(A24)+LEN(B24)/2,4) -> 00E6 | B25: =MID(Sheet2!$A$1,1+(ROW(B25)-2)*20,20) -> 6D1571150100F1011600 | C25: =MID($B25,1+4*(COLUMN(C25)-3),4) -> 6D15 | D25: =MID($B25,1+LEN(_xlfn.CONCAT($C25:C25)),4) -> 7115 | E25: =MID($B25,1+LEN(_xlfn.CONCAT($C25:D25)),2) -> 01 | F25: =MID($B25,1+LEN(_xlfn.CONCAT($C25:E25)),2) -> 00 | G25: =MID($B25,1+LEN(_xlfn.CONCAT($C25:F25)),4) -> F101 | H25: =MID($B25,1+LEN(_xlfn.CONCAT($C25:G25)),4) -> 1600 | I25: =MID($B25,1+LEN(_xlfn.CONCAT($C25:H25)),4) | J25: =HEX2DEC(MID(C25,3,2)&MID(C25,1,2)) -> 5485 | K25: =HEX2DEC(MID(D25,3,2)&MID(D25,1,2)) -> 5489 | L25: =HEX2DEC(MID(E25,3,2)&MID(E25,1,2)) -> 1 | M25: =HEX2DEC(MID(F25,3,2)&MID(F25,1,2)) -> 0 | N25: =HEX2DEC(MID(G25,3,2)&MID(G25,1,2)) -> 497 | O25: =HEX2DEC(MID(H25,3,2)&MID(H25,1,2)) -> 22
A26: =DEC2HEX(HEX2DEC(A25)+LEN(B25)/2,4) -> 00F0 | B26: =MID(Sheet2!$A$1,1+(ROW(B26)-2)*20,20) -> 7C1580150100F2011700 | C26: =MID($B26,1+4*(COLUMN(C26)-3),4) -> 7C15 | D26: =MID($B26,1+LEN(_xlfn.CONCAT($C26:C26)),4) -> 8015 | E26: =MID($B26,1+LEN(_xlfn.CONCAT($C26:D26)),2) -> 01 | F26: =MID($B26,1+LEN(_xlfn.CONCAT($C26:E26)),2) -> 00 | G26: =MID($B26,1+LEN(_xlfn.CONCAT($C26:F26)),4) -> F201 | H26: =MID($B26,1+LEN(_xlfn.CONCAT($C26:G26)),4) -> 1700 | I26: Move Relearner | J26: =HEX2DEC(MID(C26,3,2)&MID(C26,1,2)) -> 5500 | K26: =HEX2DEC(MID(D26,3,2)&MID(D26,1,2)) -> 5504 | L26: =HEX2DEC(MID(E26,3,2)&MID(E26,1,2)) -> 1 | M26: =HEX2DEC(MID(F26,3,2)&MID(F26,1,2)) -> 0 | N26: =HEX2DEC(MID(G26,3,2)&MID(G26,1,2)) -> 498 | O26: =HEX2DEC(MID(H26,3,2)&MID(H26,1,2)) -> 23
A27: =DEC2HEX(HEX2DEC(A26)+LEN(B26)/2,4) -> 00FA | B27: =MID(Sheet2!$A$1,1+(ROW(B27)-2)*20,20) -> 811599150100EF011800 | C27: =MID($B27,1+4*(COLUMN(C27)-3),4) -> 8115 | D27: =MID($B27,1+LEN(_xlfn.CONCAT($C27:C27)),4) -> 9915 | E27: =MID($B27,1+LEN(_xlfn.CONCAT($C27:D27)),2) -> 01 | F27: =MID($B27,1+LEN(_xlfn.CONCAT($C27:E27)),2) -> 00 | G27: =MID($B27,1+LEN(_xlfn.CONCAT($C27:F27)),4) -> EF01 | H27: =MID($B27,1+LEN(_xlfn.CONCAT($C27:G27)),4) -> 1800 | I27: =MID($B27,1+LEN(_xlfn.CONCAT($C27:H27)),4) | J27: =HEX2DEC(MID(C27,3,2)&MID(C27,1,2)) -> 5505 | K27: =HEX2DEC(MID(D27,3,2)&MID(D27,1,2)) -> 5529 | L27: =HEX2DEC(MID(E27,3,2)&MID(E27,1,2)) -> 1 | M27: =HEX2DEC(MID(F27,3,2)&MID(F27,1,2)) -> 0 | N27: =HEX2DEC(MID(G27,3,2)&MID(G27,1,2)) -> 495 | O27: =HEX2DEC(MID(H27,3,2)&MID(H27,1,2)) -> 24
A28: =DEC2HEX(HEX2DEC(A27)+LEN(B27)/2,4) -> 0104 | B28: =MID(Sheet2!$A$1,1+(ROW(B28)-2)*20,20) -> 9A15A3150100FD011900 | C28: =MID($B28,1+4*(COLUMN(C28)-3),4) -> 9A15 | D28: =MID($B28,1+LEN(_xlfn.CONCAT($C28:C28)),4) -> A315 | E28: =MID($B28,1+LEN(_xlfn.CONCAT($C28:D28)),2) -> 01 | F28: =MID($B28,1+LEN(_xlfn.CONCAT($C28:E28)),2) -> 00 | G28: =MID($B28,1+LEN(_xlfn.CONCAT($C28:F28)),4) -> FD01 | H28: =MID($B28,1+LEN(_xlfn.CONCAT($C28:G28)),4) -> 1900 | I28: =MID($B28,1+LEN(_xlfn.CONCAT($C28:H28)),4) | J28: =HEX2DEC(MID(C28,3,2)&MID(C28,1,2)) -> 5530 | K28: =HEX2DEC(MID(D28,3,2)&MID(D28,1,2)) -> 5539 | L28: =HEX2DEC(MID(E28,3,2)&MID(E28,1,2)) -> 1 | M28: =HEX2DEC(MID(F28,3,2)&MID(F28,1,2)) -> 0 | N28: =HEX2DEC(MID(G28,3,2)&MID(G28,1,2)) -> 509 | O28: =HEX2DEC(MID(H28,3,2)&MID(H28,1,2)) -> 25
A29: =DEC2HEX(HEX2DEC(A28)+LEN(B28)/2,4) -> 010E | B29: =MID(Sheet2!$A$1,1+(ROW(B29)-2)*20,20) -> A415AD15010000001A00 | C29: =MID($B29,1+4*(COLUMN(C29)-3),4) -> A415 | D29: =MID($B29,1+LEN(_xlfn.CONCAT($C29:C29)),4) -> AD15 | E29: =MID($B29,1+LEN(_xlfn.CONCAT($C29:D29)),2) -> 01 | F29: =MID($B29,1+LEN(_xlfn.CONCAT($C29:E29)),2) -> 00 | G29: =MID($B29,1+LEN(_xlfn.CONCAT($C29:F29)),4) -> 0000 | H29: =MID($B29,1+LEN(_xlfn.CONCAT($C29:G29)),4) -> 1A00 | I29: =MID($B29,1+LEN(_xlfn.CONCAT($C29:H29)),4) | J29: =HEX2DEC(MID(C29,3,2)&MID(C29,1,2)) -> 5540 | K29: =HEX2DEC(MID(D29,3,2)&MID(D29,1,2)) -> 5549 | L29: =HEX2DEC(MID(E29,3,2)&MID(E29,1,2)) -> 1 | M29: =HEX2DEC(MID(F29,3,2)&MID(F29,1,2)) -> 0 | N29: =HEX2DEC(MID(G29,3,2)&MID(G29,1,2)) -> 0 | O29: =HEX2DEC(MID(H29,3,2)&MID(H29,1,2)) -> 26
A30: =DEC2HEX(HEX2DEC(A29)+LEN(B29)/2,4) -> 0118 | B30: =MID(Sheet2!$A$1,1+(ROW(B30)-2)*20,20) -> AE15B215010007001B00 | C30: =MID($B30,1+4*(COLUMN(C30)-3),4) -> AE15 | D30: =MID($B30,1+LEN(_xlfn.CONCAT($C30:C30)),4) -> B215 | E30: =MID($B30,1+LEN(_xlfn.CONCAT($C30:D30)),2) -> 01 | F30: =MID($B30,1+LEN(_xlfn.CONCAT($C30:E30)),2) -> 00 | G30: =MID($B30,1+LEN(_xlfn.CONCAT($C30:F30)),4) -> 0700 | H30: =MID($B30,1+LEN(_xlfn.CONCAT($C30:G30)),4) -> 1B00 | I30: =MID($B30,1+LEN(_xlfn.CONCAT($C30:H30)),4) | J30: =HEX2DEC(MID(C30,3,2)&MID(C30,1,2)) -> 5550 | K30: =HEX2DEC(MID(D30,3,2)&MID(D30,1,2)) -> 5554 | L30: =HEX2DEC(MID(E30,3,2)&MID(E30,1,2)) -> 1 | M30: =HEX2DEC(MID(F30,3,2)&MID(F30,1,2)) -> 0 | N30: =HEX2DEC(MID(G30,3,2)&MID(G30,1,2)) -> 7 | O30: =HEX2DEC(MID(H30,3,2)&MID(H30,1,2)) -> 27
A31: =DEC2HEX(HEX2DEC(A30)+LEN(B30)/2,4) -> 0122 | B31: =MID(Sheet2!$A$1,1+(ROW(B31)-2)*20,20) -> E015E415010008001C00 | C31: =MID($B31,1+4*(COLUMN(C31)-3),4) -> E015 | D31: =MID($B31,1+LEN(_xlfn.CONCAT($C31:C31)),4) -> E415 | E31: =MID($B31,1+LEN(_xlfn.CONCAT($C31:D31)),2) -> 01 | F31: =MID($B31,1+LEN(_xlfn.CONCAT($C31:E31)),2) -> 00 | G31: =MID($B31,1+LEN(_xlfn.CONCAT($C31:F31)),4) -> 0800 | H31: =MID($B31,1+LEN(_xlfn.CONCAT($C31:G31)),4) -> 1C00 | I31: =MID($B31,1+LEN(_xlfn.CONCAT($C31:H31)),4) | J31: =HEX2DEC(MID(C31,3,2)&MID(C31,1,2)) -> 5600 | K31: =HEX2DEC(MID(D31,3,2)&MID(D31,1,2)) -> 5604 | L31: =HEX2DEC(MID(E31,3,2)&MID(E31,1,2)) -> 1 | M31: =HEX2DEC(MID(F31,3,2)&MID(F31,1,2)) -> 0 | N31: =HEX2DEC(MID(G31,3,2)&MID(G31,1,2)) -> 8 | O31: =HEX2DEC(MID(H31,3,2)&MID(H31,1,2)) -> 28
A32: =DEC2HEX(HEX2DEC(A31)+LEN(B31)/2,4) -> 012C | B32: =MID(Sheet2!$A$1,1+(ROW(B32)-2)*20,20) -> E515E915010009001D00 | C32: =MID($B32,1+4*(COLUMN(C32)-3),4) -> E515 | D32: =MID($B32,1+LEN(_xlfn.CONCAT($C32:C32)),4) -> E915 | E32: =MID($B32,1+LEN(_xlfn.CONCAT($C32:D32)),2) -> 01 | F32: =MID($B32,1+LEN(_xlfn.CONCAT($C32:E32)),2) -> 00 | G32: =MID($B32,1+LEN(_xlfn.CONCAT($C32:F32)),4) -> 0900 | H32: =MID($B32,1+LEN(_xlfn.CONCAT($C32:G32)),4) -> 1D00 | I32: =MID($B32,1+LEN(_xlfn.CONCAT($C32:H32)),4) | J32: =HEX2DEC(MID(C32,3,2)&MID(C32,1,2)) -> 5605 | K32: =HEX2DEC(MID(D32,3,2)&MID(D32,1,2)) -> 5609 | L32: =HEX2DEC(MID(E32,3,2)&MID(E32,1,2)) -> 1 | M32: =HEX2DEC(MID(F32,3,2)&MID(F32,1,2)) -> 0 | N32: =HEX2DEC(MID(G32,3,2)&MID(G32,1,2)) -> 9 | O32: =HEX2DEC(MID(H32,3,2)&MID(H32,1,2)) -> 29
A33: =DEC2HEX(HEX2DEC(A32)+LEN(B32)/2,4) -> 0136 | B33: =MID(Sheet2!$A$1,1+(ROW(B33)-2)*20,20) -> FE1516160100FE011E00 | C33: =MID($B33,1+4*(COLUMN(C33)-3),4) -> FE15 | D33: =MID($B33,1+LEN(_xlfn.CONCAT($C33:C33)),4) -> 1616 | E33: =MID($B33,1+LEN(_xlfn.CONCAT($C33:D33)),2) -> 01 | F33: =MID($B33,1+LEN(_xlfn.CONCAT($C33:E33)),2) -> 00 | G33: =MID($B33,1+LEN(_xlfn.CONCAT($C33:F33)),4) -> FE01 | H33: =MID($B33,1+LEN(_xlfn.CONCAT($C33:G33)),4) -> 1E00 | I33: =MID($B33,1+LEN(_xlfn.CONCAT($C33:H33)),4) | J33: =HEX2DEC(MID(C33,3,2)&MID(C33,1,2)) -> 5630 | K33: =HEX2DEC(MID(D33,3,2)&MID(D33,1,2)) -> 5654 | L33: =HEX2DEC(MID(E33,3,2)&MID(E33,1,2)) -> 1 | M33: =HEX2DEC(MID(F33,3,2)&MID(F33,1,2)) -> 0 | N33: =HEX2DEC(MID(G33,3,2)&MID(G33,1,2)) -> 510 | O33: =HEX2DEC(MID(H33,3,2)&MID(H33,1,2)) -> 30
A34: =DEC2HEX(HEX2DEC(A33)+LEN(B33)/2,4) -> 0140 | B34: =MID(Sheet2!$A$1,1+(ROW(B34)-2)*20,20) -> 17161B160100DD021F00 | C34: =MID($B34,1+4*(COLUMN(C34)-3),4) -> 1716 | D34: =MID($B34,1+LEN(_xlfn.CONCAT($C34:C34)),4) -> 1B16 | E34: =MID($B34,1+LEN(_xlfn.CONCAT($C34:D34)),2) -> 01 | F34: =MID($B34,1+LEN(_xlfn.CONCAT($C34:E34)),2) -> 00 | G34: =MID($B34,1+LEN(_xlfn.CONCAT($C34:F34)),4) -> DD02 | H34: =MID($B34,1+LEN(_xlfn.CONCAT($C34:G34)),4) -> 1F00 | I34: Hyper Training | J34: =HEX2DEC(MID(C34,3,2)&MID(C34,1,2)) -> 5655 | K34: =HEX2DEC(MID(D34,3,2)&MID(D34,1,2)) -> 5659 | L34: =HEX2DEC(MID(E34,3,2)&MID(E34,1,2)) -> 1 | M34: =HEX2DEC(MID(F34,3,2)&MID(F34,1,2)) -> 0 | N34: =HEX2DEC(MID(G34,3,2)&MID(G34,1,2)) -> 733 | O34: =HEX2DEC(MID(H34,3,2)&MID(H34,1,2)) -> 31
A35: =DEC2HEX(HEX2DEC(A34)+LEN(B34)/2,4) -> 014A | B35: =MID(Sheet2!$A$1,1+(ROW(B35)-2)*20,20) -> 1C163416010001002000 | C35: =MID($B35,1+4*(COLUMN(C35)-3),4) -> 1C16 | D35: =MID($B35,1+LEN(_xlfn.CONCAT($C35:C35)),4) -> 3416 | E35: =MID($B35,1+LEN(_xlfn.CONCAT($C35:D35)),2) -> 01 | F35: =MID($B35,1+LEN(_xlfn.CONCAT($C35:E35)),2) -> 00 | G35: =MID($B35,1+LEN(_xlfn.CONCAT($C35:F35)),4) -> 0100 | H35: =MID($B35,1+LEN(_xlfn.CONCAT($C35:G35)),4) -> 2000 | I35: =MID($B35,1+LEN(_xlfn.CONCAT($C35:H35)),4) | J35: =HEX2DEC(MID(C35,3,2)&MID(C35,1,2)) -> 5660 | K35: =HEX2DEC(MID(D35,3,2)&MID(D35,1,2)) -> 5684 | L35: =HEX2DEC(MID(E35,3,2)&MID(E35,1,2)) -> 1 | M35: =HEX2DEC(MID(F35,3,2)&MID(F35,1,2)) -> 0 | N35: =HEX2DEC(MID(G35,3,2)&MID(G35,1,2)) -> 1 | O35: =HEX2DEC(MID(H35,3,2)&MID(H35,1,2)) -> 32
A36: =DEC2HEX(HEX2DEC(A35)+LEN(B35)/2,4) -> 0154 | B36: =MID(Sheet2!$A$1,1+(ROW(B36)-2)*20,20) -> 441661160100FB012100 | C36: =MID($B36,1+4*(COLUMN(C36)-3),4) -> 4416 | D36: =MID($B36,1+LEN(_xlfn.CONCAT($C36:C36)),4) -> 6116 | E36: =MID($B36,1+LEN(_xlfn.CONCAT($C36:D36)),2) -> 01 | F36: =MID($B36,1+LEN(_xlfn.CONCAT($C36:E36)),2) -> 00 | G36: =MID($B36,1+LEN(_xlfn.CONCAT($C36:F36)),4) -> FB01 | H36: =MID($B36,1+LEN(_xlfn.CONCAT($C36:G36)),4) -> 2100 | I36: =MID($B36,1+LEN(_xlfn.CONCAT($C36:H36)),4) | J36: =HEX2DEC(MID(C36,3,2)&MID(C36,1,2)) -> 5700 | K36: =HEX2DEC(MID(D36,3,2)&MID(D36,1,2)) -> 5729 | L36: =HEX2DEC(MID(E36,3,2)&MID(E36,1,2)) -> 1 | M36: =HEX2DEC(MID(F36,3,2)&MID(F36,1,2)) -> 0 | N36: =HEX2DEC(MID(G36,3,2)&MID(G36,1,2)) -> 507 | O36: =HEX2DEC(MID(H36,3,2)&MID(H36,1,2)) -> 33
A37: =DEC2HEX(HEX2DEC(A36)+LEN(B36)/2,4) -> 015E | B37: =MID(Sheet2!$A$1,1+(ROW(B37)-2)*20,20) -> 62166616010063042200 | C37: =MID($B37,1+4*(COLUMN(C37)-3),4) -> 6216 | D37: =MID($B37,1+LEN(_xlfn.CONCAT($C37:C37)),4) -> 6616 | E37: =MID($B37,1+LEN(_xlfn.CONCAT($C37:D37)),2) -> 01 | F37: =MID($B37,1+LEN(_xlfn.CONCAT($C37:E37)),2) -> 00 | G37: =MID($B37,1+LEN(_xlfn.CONCAT($C37:F37)),4) -> 6304 | H37: =MID($B37,1+LEN(_xlfn.CONCAT($C37:G37)),4) -> 2200 | I37: =MID($B37,1+LEN(_xlfn.CONCAT($C37:H37)),4) | J37: =HEX2DEC(MID(C37,3,2)&MID(C37,1,2)) -> 5730 | K37: =HEX2DEC(MID(D37,3,2)&MID(D37,1,2)) -> 5734 | L37: =HEX2DEC(MID(E37,3,2)&MID(E37,1,2)) -> 1 | M37: =HEX2DEC(MID(F37,3,2)&MID(F37,1,2)) -> 0 | N37: =HEX2DEC(MID(G37,3,2)&MID(G37,1,2)) -> 1123 | O37: =HEX2DEC(MID(H37,3,2)&MID(H37,1,2)) -> 34
A38: =DEC2HEX(HEX2DEC(A37)+LEN(B37)/2,4) -> 0168 | B38: =MID(Sheet2!$A$1,1+(ROW(B38)-2)*20,20) -> 67166B16010002002300 | C38: =MID($B38,1+4*(COLUMN(C38)-3),4) -> 6716 | D38: =MID($B38,1+LEN(_xlfn.CONCAT($C38:C38)),4) -> 6B16 | E38: =MID($B38,1+LEN(_xlfn.CONCAT($C38:D38)),2) -> 01 | F38: =MID($B38,1+LEN(_xlfn.CONCAT($C38:E38)),2) -> 00 | G38: =MID($B38,1+LEN(_xlfn.CONCAT($C38:F38)),4) -> 0200 | H38: =MID($B38,1+LEN(_xlfn.CONCAT($C38:G38)),4) -> 2300 | I38: =MID($B38,1+LEN(_xlfn.CONCAT($C38:H38)),4) | J38: =HEX2DEC(MID(C38,3,2)&MID(C38,1,2)) -> 5735 | K38: =HEX2DEC(MID(D38,3,2)&MID(D38,1,2)) -> 5739 | L38: =HEX2DEC(MID(E38,3,2)&MID(E38,1,2)) -> 1 | M38: =HEX2DEC(MID(F38,3,2)&MID(F38,1,2)) -> 0 | N38: =HEX2DEC(MID(G38,3,2)&MID(G38,1,2)) -> 2 | O38: =HEX2DEC(MID(H38,3,2)&MID(H38,1,2)) -> 35
A39: =DEC2HEX(HEX2DEC(A38)+LEN(B38)/2,4) -> 0172 | B39: =MID(Sheet2!$A$1,1+(ROW(B39)-2)*20,20) -> 6C167016010001002400 | C39: =MID($B39,1+4*(COLUMN(C39)-3),4) -> 6C16 | D39: =MID($B39,1+LEN(_xlfn.CONCAT($C39:C39)),4) -> 7016 | E39: =MID($B39,1+LEN(_xlfn.CONCAT($C39:D39)),2) -> 01 | F39: =MID($B39,1+LEN(_xlfn.CONCAT($C39:E39)),2) -> 00 | G39: =MID($B39,1+LEN(_xlfn.CONCAT($C39:F39)),4) -> 0100 | H39: =MID($B39,1+LEN(_xlfn.CONCAT($C39:G39)),4) -> 2400 | I39: =MID($B39,1+LEN(_xlfn.CONCAT($C39:H39)),4) | J39: =HEX2DEC(MID(C39,3,2)&MID(C39,1,2)) -> 5740 | K39: =HEX2DEC(MID(D39,3,2)&MID(D39,1,2)) -> 5744 | L39: =HEX2DEC(MID(E39,3,2)&MID(E39,1,2)) -> 1 | M39: =HEX2DEC(MID(F39,3,2)&MID(F39,1,2)) -> 0 | N39: =HEX2DEC(MID(G39,3,2)&MID(G39,1,2)) -> 1 | O39: =HEX2DEC(MID(H39,3,2)&MID(H39,1,2)) -> 36
A40: =DEC2HEX(HEX2DEC(A39)+LEN(B39)/2,4) -> 017C | B40: =MID(Sheet2!$A$1,1+(ROW(B40)-2)*20,20) -> 71167516010015002500 | C40: =MID($B40,1+4*(COLUMN(C40)-3),4) -> 7116 | D40: =MID($B40,1+LEN(_xlfn.CONCAT($C40:C40)),4) -> 7516 | E40: =MID($B40,1+LEN(_xlfn.CONCAT($C40:D40)),2) -> 01 | F40: =MID($B40,1+LEN(_xlfn.CONCAT($C40:E40)),2) -> 00 | G40: =MID($B40,1+LEN(_xlfn.CONCAT($C40:F40)),4) -> 1500 | H40: =MID($B40,1+LEN(_xlfn.CONCAT($C40:G40)),4) -> 2500 | I40: =MID($B40,1+LEN(_xlfn.CONCAT($C40:H40)),4) | J40: =HEX2DEC(MID(C40,3,2)&MID(C40,1,2)) -> 5745 | K40: =HEX2DEC(MID(D40,3,2)&MID(D40,1,2)) -> 5749 | L40: =HEX2DEC(MID(E40,3,2)&MID(E40,1,2)) -> 1 | M40: =HEX2DEC(MID(F40,3,2)&MID(F40,1,2)) -> 0 | N40: =HEX2DEC(MID(G40,3,2)&MID(G40,1,2)) -> 21 | O40: =HEX2DEC(MID(H40,3,2)&MID(H40,1,2)) -> 37
A41: =DEC2HEX(HEX2DEC(A40)+LEN(B40)/2,4) -> 0186 | B41: =MID(Sheet2!$A$1,1+(ROW(B41)-2)*20,20) -> 76167A160100FD012600 | C41: =MID($B41,1+4*(COLUMN(C41)-3),4) -> 7616 | D41: =MID($B41,1+LEN(_xlfn.CONCAT($C41:C41)),4) -> 7A16 | E41: =MID($B41,1+LEN(_xlfn.CONCAT($C41:D41)),2) -> 01 | F41: =MID($B41,1+LEN(_xlfn.CONCAT($C41:E41)),2) -> 00 | G41: =MID($B41,1+LEN(_xlfn.CONCAT($C41:F41)),4) -> FD01 | H41: =MID($B41,1+LEN(_xlfn.CONCAT($C41:G41)),4) -> 2600 | I41: =MID($B41,1+LEN(_xlfn.CONCAT($C41:H41)),4) | J41: =HEX2DEC(MID(C41,3,2)&MID(C41,1,2)) -> 5750 | K41: =HEX2DEC(MID(D41,3,2)&MID(D41,1,2)) -> 5754 | L41: =HEX2DEC(MID(E41,3,2)&MID(E41,1,2)) -> 1 | M41: =HEX2DEC(MID(F41,3,2)&MID(F41,1,2)) -> 0 | N41: =HEX2DEC(MID(G41,3,2)&MID(G41,1,2)) -> 509 | O41: =HEX2DEC(MID(H41,3,2)&MID(H41,1,2)) -> 38
A42: =DEC2HEX(HEX2DEC(A41)+LEN(B41)/2,4) -> 0190 | B42: =MID(Sheet2!$A$1,1+(ROW(B42)-2)*20,20) -> 7B167F160100FA012700 | C42: =MID($B42,1+4*(COLUMN(C42)-3),4) -> 7B16 | D42: =MID($B42,1+LEN(_xlfn.CONCAT($C42:C42)),4) -> 7F16 | E42: =MID($B42,1+LEN(_xlfn.CONCAT($C42:D42)),2) -> 01 | F42: =MID($B42,1+LEN(_xlfn.CONCAT($C42:E42)),2) -> 00 | G42: =MID($B42,1+LEN(_xlfn.CONCAT($C42:F42)),4) -> FA01 | H42: =MID($B42,1+LEN(_xlfn.CONCAT($C42:G42)),4) -> 2700 | I42: =MID($B42,1+LEN(_xlfn.CONCAT($C42:H42)),4) | J42: =HEX2DEC(MID(C42,3,2)&MID(C42,1,2)) -> 5755 | K42: =HEX2DEC(MID(D42,3,2)&MID(D42,1,2)) -> 5759 | L42: =HEX2DEC(MID(E42,3,2)&MID(E42,1,2)) -> 1 | M42: =HEX2DEC(MID(F42,3,2)&MID(F42,1,2)) -> 0 | N42: =HEX2DEC(MID(G42,3,2)&MID(G42,1,2)) -> 506 | O42: =HEX2DEC(MID(H42,3,2)&MID(H42,1,2)) -> 39
A43: =DEC2HEX(HEX2DEC(A42)+LEN(B42)/2,4) -> 019A | B43: =MID(Sheet2!$A$1,1+(ROW(B43)-2)*20,20) -> 80169316010024042800 | C43: =MID($B43,1+4*(COLUMN(C43)-3),4) -> 8016 | D43: =MID($B43,1+LEN(_xlfn.CONCAT($C43:C43)),4) -> 9316 | E43: =MID($B43,1+LEN(_xlfn.CONCAT($C43:D43)),2) -> 01 | F43: =MID($B43,1+LEN(_xlfn.CONCAT($C43:E43)),2) -> 00 | G43: =MID($B43,1+LEN(_xlfn.CONCAT($C43:F43)),4) -> 2404 | H43: =MID($B43,1+LEN(_xlfn.CONCAT($C43:G43)),4) -> 2800 | I43: =MID($B43,1+LEN(_xlfn.CONCAT($C43:H43)),4) | J43: =HEX2DEC(MID(C43,3,2)&MID(C43,1,2)) -> 5760 | K43: =HEX2DEC(MID(D43,3,2)&MID(D43,1,2)) -> 5779 | L43: =HEX2DEC(MID(E43,3,2)&MID(E43,1,2)) -> 1 | M43: =HEX2DEC(MID(F43,3,2)&MID(F43,1,2)) -> 0 | N43: =HEX2DEC(MID(G43,3,2)&MID(G43,1,2)) -> 1060 | O43: =HEX2DEC(MID(H43,3,2)&MID(H43,1,2)) -> 40
...

Sheet Sheet2
A1: E803B70B01000A000000B80B871301000A0000008813911301000A0001009213A51301000A000200A613AF130100F8010300B013C31301000C000400C413CD130100F2010500EC131D140100120006001E1422140100100007002314271401000F00080028142C140100140009002D143114010004000A0032143614010016000B00371440140100FC010C00501463140100DF020D006414771401000E000E007814A914010005000F00AA14BD14010006001000BE14DB1401000B0011001815491500005F0012004A155D150100110013005E15621501001300140063156C150100F20115006D1571150100F10116007C1580150100F2011700811599150100EF0118009A15A3150100FD011900A415AD15010000001A00AE15B215010007001B00E015E415010008001C00E515E915010009001D00FE1516160100FE011E0017161B160100DD021F001C163416010001002000441661160100FB0121006216661601006304220067166B160100020023006C1670160100010024007116751601001500250076167A160100FD0126007B167F160100FA0127008016931601002404280094169D160100250429009E16A716010024042A00A816B116010024042B00B216B616010024042C00B716BB16010062042D00BC16C516010000002E00C616CF16010018002F00D016E3160100EE013000E416151701000A0031001617291701000D0032002A1733170100F0013300307543750100190034004475577501001A00350058756B7501001B0036006C757F7501001D0037008075937501001E0038009475A77501001F003900A875BB7501002C003A00BC75CF7501002D003B00D075E375010030003C00E475F775010031003D00F8750B76010033003E000C761F76010035003F002076337601003A0040003476477601003B00410048765B7601003C0042005C766F7601003E0043007076837601003F004400847697760100400045009876AB76010042004600AC76BF76010044004700C076D376010045004800D476E776010046004900E876FB76010048004A00FC760F77010049004B001077237701004C004C002477377701004D004D0038774B7701004E004E004C775F7701004F004F00607773770100500050007477877701005100510088779B770100520052009C77AF77010053005300B077C377010054005400C477D777010055005500D877EB77010057005600EC77FF77010058005700007813780100590058001478277801005A00590028783B7801005D005A003C784F78010060005B0050786378010061005C0064787778010069005D0078788B7801006A005E008C789F7801006B005F00A078B37801006C006000B478C77801006D006100C878DB7801006E006200DC78EF7801006F006300F07803790100700064000479177901007300650018792B790100740066002C793F79010076006700407953790100770068005479677901007800690068797B7901007D006A007C798F7901007E006B009079A37901007F006C00A479B779010080006D00B879CB79010081006E00CC79DF79010082006F00E079F379010088007000F479077A01002E007100087A1B7A0100390072001C7A2F7A010036007300307A437A010037007400447A577A010038007500587A6B7A01004A0076006C7A7F7A010043007700807A937A010071007800947AA77A010020007900A87ABB7A010021007A00BC7ACF7A010022007B00D07AE37A010023007C00E47AF77A010034007D00F87A0B7B01005E007E000C7B1F7B01005F007F00207B337B010062008000347B477B010063008100487B5B7B0100790082005C7B6F7B01007A008300707B837B010094008400847B977B010095008500987BAB7B010096008600AC7BBF7B010097008700C07BC97B010098008800CA7BD37B010099008900D47BDD7B01009A008A00DE7BE77B01009B008B00E87BF17B01009C008C00F27BFB7B01009D008D00FC7B0F7C0100A6008E00107C237C0100A7008F00247C377C0100A8009000387C4B7C0100A90091004C7C5F7C0100AA009200607C737C0100AB009300747C877C0100AC009400887C9B7C0100AD0095009C7CAF7C0100AE009600B07CC37C010047009700C47CD77C01002F009800D87CEB7C01008C009900EC7CFF7C01008D009A00007D137D01008E009B00147D277D01008F009C00287D3B7D010090009D003C7D4F7D010092009E00507D637D010093009F00647D777D0100A000A000787D8B7D0100A200A1008C7D9F7D0100A300A200A07DB37D0100A400A300B47DC77D0100A500A400C87DDB7D0100AF00A500DC7DEF7D0100B700A600F07D037E0100B800A700047E177E0100BC00A800187E2B7E0100BD00A9002C7E3F7E0100BE00AA00407E537E0100BF00AB00547E677E0100C000AC00687E7B7E0100C100AD007C7E8F7E0100C200AE00907EA37E0100C300AF00A47EB77E0100C400B000B87ECB7E0100C600B100CC7EDF7E0100C700B200E07EF37E0100C800B300F47E077F0100C900B400087F1B7F0100CA00B5001C7F2F7F0100CB00B600307F437F0100CC00B700447F577F0100CD00B800587F6B7F0100CE00B9006C7F7F7F0100CF00BA00807F937F0100B000BB00947FA77F0100B100BC00A87FBB7F0100B200BD00BC7FCF7F0100B300BE00D07FE37F0100B400BF00E47FF77F01009100C000F87F0B800100D000C1000C801F800100D100C200208033800100D300C300348047800100D500C40048805B800100D600C5005C806F800100D700C600708083800100D800C700848097800100D900C8009880AB800100DA00C900AC80BF800100DB00CA00C080D3800100DC00CB00D480E7800100DD00CC00E880FB800100DE00CD00FC800F810100E000CE00108123810100E100CF00248137810100E200D00038814B810100E300D1004C815F810100E500D200608173810100E600D300748187810100E700D40088819B810100E800D5009C81AF810100E900D600B081C3810100EB00D700C481D7810100EC00D800D881EB8101000000D900EC81FF8101000000DA000082138201000000DB001482278201000000DC0028823B8201000000DD003C824F8201000000DE005082638201000000DF00648277820100EE00E00078828B820100F000E1008C829F820100F300E200A082B3820100F400E300B482C7820100F500E400C882DB820100F600E500DC82EF820100F700E600F08203830100F800E700048317830100F100E80018832B830100EF00E9002C833F830100FB00EA00408353830100FE00EB00548367830100FF00EC0068837B8301000001ED007C838F8301000101EE009083A38301000201EF00A483B78301000401F000B883CB8301000501F100CC83DF8301000601F200E083F38301000701F300F483078401000901F40008841B8401000A01F5001C842F8401000B01F6003084438401000000F7004484578401000000F80058846B8401000000F9006C847F8401000000FA008084938401000000FB009484A78401000000FC00A884BB8401000000FD00BC84CF8401000C01FE00D084E38401000D01FF00E484F78401000E010001F8840B8501000F0101010C851F85010010010201208533850100110103013485478501000000040148855B850100000005015C856F8501000000060170858385010000000701848597850100120108019885AB85010013010901AC85BF85010014010A01C085D385010015010B01D485E785010016010C01E885FB85010017010D01FC850F86010018010E0110862386010019010F012486378601001A01100138864B8601001D0111014C865F8601001E0112016086738601001F0113017486878601002001140188869B860100210115019C86AF86010022011601B086C386010023011701C486D786010024011801D886EB86010025011901EC86FF86010026011A0100871387010027011B0114872787010028011C0128873B87010029011D013C874F8701002A011E015087638701002B011F016487778701002C01200178878B8701002D0121018C879F8701002E012201A087B38701002F012301B487C787010030012401C887DB87010031012501DC87EF87010032012601F08703880100360127010488178801003A01280118882B8801003B0129012C883F8801003E012A014088538801003F012B0154886788010040012C0168887B88010041012D017C888F88010043012E019088A388010044012F01A488B788010045013001B888CB88010046013101CC88DF88010047013201E088F388010048013301F488078901004901340108891B8901004A0135011C892F8901004B0136013089438901004C0137014489578901004D01380158896B8901004F0139016C897F89010050013A0180899389010052013B019489A789010056013C01A889BB89010057013D01BC89CF89010058013E01D089E389010059013F01E489F78901005A014001F8890B8A01005B0141010C8A1F8A01005C014201208A338A01005D014301348A478A01005E014401488A5B8A01005F0145015C8A6F8A010060014601708A838A010061014701848A978A010000004801988AAB8A010000004901AC8ABF8A010000004A01C08AD38A010000004B01D48AE78A010000004C01E88AFB8A010062014D01FC8A0F8B010063014E01108B238B010064014F01248B378B010066015001388B4B8B0100670151014C8B5F8B010068015201608B738B010072015301748B878B010075015401888B9B8B0100760155019C8BAF8B010077015601B08BC38B010078015701C48BD78B010079015801D88BEB8B01007A015901EC8BFF8B01007C015A01008C138C01007D015B01148C278C01007E015C01288C3B8C01007F015D013C8C4F8C010087015E01508C638C01008A015F01648C778C01008B016001788C8B8C01008C0161018C8C9F8C01008D016201A08CB38C01008F016301B48CC78C010090016401C88CDB8C010091016501DC8CEF8C010092016601F08C038D010093016701048D178D01009B016801188D2B8D0100000069012C8D3F8D010000006A01408D538D010000006B01548D678D01009C016C01688D7B8D0100D2006D017C8D8F8D0100D4006E01908DA38D010042016F01A48DB78D01003C017001B88DCB8D01003D017101CC8DDF8D01004E017201E08DF38D010053017301F48D078E010054017401088E1B8E0100510175011C8E2F8E010065017601308E438E010033017701448E578E0100E4007801588E6B8E0100610179016C8E7F8E01000D017A01808E938E01000D017B01948EA78E01000D017C01A88EBB8E01000D017D01BC8ECF8E0100AB007E01D08EE38E0100A1007F01E48EF78E0100A1008001F88E0B8F0100720081010C8F1F8F01009D01820138904B900100A20183016090739001009F018401749087900100A001850188909B900100A10186019C90AF90010032008701B090C39001001B008801C490D79001009E008901D890EB90010003018A01EC90FF900100B9008B010091139101001C008C011491279101001B018D0128913B9101001C018E013C914F91010056008F01509163910100800190016491779101001B00910178918B910100240092018C919F9101005C009301A091B391010094019401B491C791010095019501C891DB91010096019601DC91EF91010097019701F09103920100980198010492179201009901990118922B9201009A019A012C923F9201005B009B0140925392010075009C01549267920100BA009D0168927B92010088019E017C928F9201002B009F019092A39201003D00A001A492B79201006400A101B892CB9201006500A201CC92DF9201006600A301E092F39201006700A401F492079301002500A50108931B9301002600A6011C932F9301002700A7013093439301002800A8014493579301008A00A90158936B9301008B00AA016C937F930100B500AB01809393930100C401AC019493A7930100C501AD01A893BB930100C601AE01BC93CF930100C701AF01D093E3930100C801B001E493F7930100C901B101F8930B940100CA01B2010C941F940100C500B301209433940100DF00B401349447940100FD00B50148945B9401008700B6015C946F9401008300B7017094839401002900B8018494979401002A00B9019894AB940100CB01BA01AC94BF940100CC01BB01C094D3940100CD01BC01D494E7940100CE01BD01E894FB940100CF01BE01FC940F950100D001BF01109523950100D101C001249537950100D201C10138954B950100D301C2014C955F950100D401C3016095739501008E01C4017495879501005501C50188959B950100E401C6019C95AF950100EC01C701B095C3950100ED01C801C495D79501008201C901D895EB9501008301CA01EC95FF9501008401CB010096139601008501CC011496279601008601CD0128963B9601003401CE013C964F9601003501CF015096639601006901D0016496779601006A01D10178968B960100D501D2018C969F960100D601D301A096B3960100D701D401B496C7960100D801D501C896DB960100D901D601DC96EF960100DA01D701F09603970100DB01D801049717970100DC01D90118972B970100DD01DA012C973F970100DE01DB01409753970100DF01DC01549767970100E001DD0168977B970100E101DE017C978F970100E201DF019097A3970100E301E001A497B79701006B01E101B897CB9701006C01E201CC97DF9701006D01E301E097F39701006E01E401F497079801006F01E50108981B9801007001E6011C982F9801007101E7013098439801008901E8014498579801004100E90158986B9801004B00EA016C987F980100A901EB01809893980100AA01EC019498A7980100AB01ED01A898BB980100AC01EE01BC98CF980100AD01EF01D098E3980100AE01F001E498F7980100AF01F101F8980B990100B001F2010C991F990100B101F301209933990100B201F401349947990100B301F50148995B990100B401F6015C996F990100B501F701709983990100B601F801849997990100B701F9019899AB990100B801FA01AC99D3990100B901FB01D499E7990100BA01FC01E899FB990100BB01FD01FC990F9A0100BC01FE01109A239A0100BD01FF01249A4B9A0100BE0100024C9A5F9A0100BF010102609A739A0100C0010202749A879A0100C1010302889A9B9A0100C20104029C9AAF9A0100C3010502B09AC39A0100E5010602C49AD79A0100E6010702D89AEB9A0100E7010802EC9AFF9A0100E8010902009B139B0100E9010A02149B279B0100EA010B02289B3B9B0100EB010C023C9B4F9B010084000D02509B639B010085000E02649B779B010086000F02789B8B9B0100680010028C9B9F9B0100B6001102A09BB39B010008011202B49BC79B0100BB001302C89BDB9B010081011402DC9BEF9B01007B001502F09B039C0100A5011602049C179C0100A6011702189C2B9C0100A70118022C9C3F9C0100A8011902409C539C01009F001A02549C679C010074011B0250C363C30100FF011C0264C377C3010012021D0278C38BC301002D021E028CC39FC3010038021F02A0C3B3C301005002200218C42BC40100410221022CC43FC401004202220254C467C401002702230268C46CC401002C0224026DC471C401003C02250272C476C401003D02260277C480C401000F02270281C485C401001E02280286C48AC40100220229028BC499C4010023022A029AC49EC401004C022B029FC4A8C4010024022C02A9C4ADC401000E022D02AEC4B2C4010039022E02B3C4B7C401003A022F02B8C4BCC4010046023002BDC4C1C401000A023102C2C4C6C401002E023202C7C4D0C4010016023302D1C4DAC4010025023402DBC4EEC4010005023502EFC4F3C401001C023602F4C4F8C401001D023702F9C4FDC4010021023802FEC402C501004A02390203C507C501003B023A0208C50CC501003E023B020DC511C5010048023C0212C516C5010049023D0217C51BC5010019023E021CC520C501001A023F0221C525C501001B02400226C52AC50100150241022BC52FC501000B02420230C539C501002F0243023AC543C501003102440244C54DC50100330245024EC557C501003402460258C561C501003502470262C56BC50100360248026CC575C501003702490276C57FC5010014024A0280C589C501001F024B028AC593C5010020024C0294C59DC5010026024D029EC5A7C5010040024E02D0C5D9C5010045024F02DAC5E3C5010047025002E4C5EDC501004B025102EEC5F7C501004E025202F8C501C601000402530202C60BC60100280254020CC615C601002902550216C61FC601003202560220C624C601002A02570225C629C601004D0258022AC633C601000002590234C63DC6010001025A023EC647C6010002025B0248C651C6010017025C0252C65BC601000D025D025CC665C6010018025E0266C66FC601002B025F0270C683C601005102600284C697C601005202610298C6ABC6010053026202ACC6BFC6010054026302C0C6D3C6010055026402D4C6E7C6010056026502E8C6FBC6010057026602FCC60FC701005802670210C723C701005902680224C737C701005A02690238C74BC701005B026A024CC755C7010003026B0256C75FC7010010026C0260C769C7010030026D026AC773C7010007026E0274C77DC7010013026F027EC787C701000602700288C791C701005C02710292C79BC701000C0272029CC7A5C7010011027302A6C7AFC7010043027402B0C7B9C7010008027502BAC7C3C7010009027602C4C7D7C701005D027702D8C7EBC701005E027802ECC7FFC701005F02790200C813C8010060027A0214C827C8010061027B0228C83BC8010062027C023CC84FC8010063027D0250C863C8010064027E0264C877C8010065027F0278C88BC80100660280028CC89FC8010067028102A0C8B3C8010068028202B4C8C7C8010069028302C8C8DBC801006A028402DCC8EFC801006B028502F0C803C901006C02860204C917C901006D02870218C92BC901006E0288022CC93FC901006F02890240C953C9010070028A0254C967C9010071028B0268C97BC9010072028C027CC98FC9010073028D0290C9A3C9010074028E02A4C9B7C9010075028F02B8C9CBC9010076029002CCC9DFC9010077029102E0C9F3C9010078029202F4C907CA01007902930208CA1BCA01007A0294021CCA2FCA01007B02950230CA43CA01007C02960244CA57CA01007D02970258CA6BCA01007E0298026CCA7FCA01007F02990280CA93CA010080029A0294CAA7CA010081029B02A8CABBCA010082029C02BCCACFCA010083029D02D0CAE3CA010084029E02E4CAF7CA010085029F02F8CA0BCB01008602A0020CCB1FCB01008702A10220CB33CB01008802A20234CB47CB01008902A30248CB5BCB01008A02A4025CCB6FCB01008B02A50270CB83CB01008C02A60284CB97CB01008D02A70298CBABCB01008E02A802ACCBBFCB01008F02A902C0CBD3CB01009002AA02D4CBE7CB01009102AB02E8CBFBCB01009202AC02FCCB0FCC01009302AD0210CC23CC01009402AE0224CC37CC01009502AF0238CC4BCC01009602B0024CCC5FCC01009702B10260CC73CC01009802B20274CC87CC01009902B30288CC9BCC01009A02B4029CCCAFCC01009B02B502B0CCC3CC01009C02B602C4CCD7CC01009D02B702D8CCEBCC01009E02B802ECCCFFCC01009F02B90200CD13CD0100A002BA0214CD27CD0100A102BB0228CD3BCD0100A202BC023CCD4FCD0100A302BD0250CD63CD0100A402BE0264CD77CD0100A502BF0278CD8BCD0100A602C0028CCD9FCD0100A702C102A0CDB3CD0100A802C202B4CDC7CD0100A902C302C8CDDBCD0100AB02C402DCCDEFCD0100AC02C502F0CD03CE0100AD02C60204CE17CE0100AE02C70218CE2BCE0100AF02C8022CCE3FCE0100B002C90240CE53CE0100B102CA0254CE67CE0100B202CB0268CE7BCE0100B302CC027CCE8FCE0100B402CD0290CEA3CE0100B502CE02A4CEB7CE0100B602CF02B8CECBCE0100B702D002CCCEDFCE0100B802D102E0CEF3CE0100B902D202F4CE07CF0100BA02D30208CF1BCF0100BB02D4021CCF2FCF0100BC02D50230CF43CF0100BD02D60244CF57CF0100BE02D70258CF6BCF0100BF02D8026CCF7FCF0100C002D90280CF93CF0100C102DA0294CFA7CF0100C202DB02A8CFBBCF0100C302DC02BCCFCFCF0100C402DD02D0CFE3CF0100C502DE02E4CFF7CF0100C602DF02F8CF0BD00100C702E0020CD01FD00100C802E10220D033D00100C902E20234D047D00100CA02E30248D05BD00100CB02E4025CD06FD00100CC02E50270D083D00100CD02E60284D097D00100CE02E70298D0ABD00100CF02E802ACD0BFD00100D002E902C0D0D3D00100D102EA02D4D0E7D00100D202EB02E8D0FBD00100D302EC02FCD00FD10100D402ED0210D123D10100D502EE0224D137D10100D602EF0238D14BD10100D702F0024CD15FD10100D802F10260D173D10100D902F20274D187D10100DA02F30288D19BD10100DB02F4029CD1AFD10100AA02F502B0D1C3D10100DC02F602
