Workbook

Sheet Format
A1: Offset (dec) | B1: Offset (Hex) | C1: Field
A3: 0 | B3: =DEC2HEX(A3) -> 0 | C3: HP
A4: 1 | B4: =DEC2HEX(A4) -> 1 | C4: Attack
A5: 2 | B5: =DEC2HEX(A5) -> 2 | C5: Defense
A6: 3 | B6: =DEC2HEX(A6) -> 3 | C6: Speed
A7: 4 | B7: =DEC2HEX(A7) -> 4 | C7: Special Attack
A8: 5 | B8: =DEC2HEX(A8) -> 5 | C8: Special Defense
A9: 6 | B9: =DEC2HEX(A9) -> 6 | C9: Type 1
A10: 7 | B10: =DEC2HEX(A10) -> 7 | C10: Type 2
A11: 8 | B11: =DEC2HEX(A11) -> 8 | C11: Catch Rate
A12: 9 | B12: =DEC2HEX(A12) -> 9 | C12: Evolution Stage
A13: 10 | B13: =DEC2HEX(A13) -> A | C13: Effort Values
A14: 11 | B14: =DEC2HEX(A14) -> B | C14: Effort Values
... A31: 28 | B31: =DEC2HEX(A31) -> 1C | C31: Forme pointer
A32: 29 | B32: =DEC2HEX(A32) -> 1D
A33: 30 | B33: =DEC2HEX(A33) -> 1E | C33: Forme Sprite
A34: 31 | B34: =DEC2HEX(A34) -> 1F
A35: 32 | B35: =DEC2HEX(A35) -> 20 | C35: Forme Count
A36: 33 | B36: =DEC2HEX(A36) -> 21 | C36: Color
A37: 34 | B37: =DEC2HEX(A37) -> 22 | C37: Base Exp.
A38: 35 | B38: =DEC2HEX(A38) -> 23
A39: 36 | B39: =DEC2HEX(A39) -> 24 | C39: Height in decimeters
A40: 37 | B40: =DEC2HEX(A40) -> 25
A41: 38 | B41: =DEC2HEX(A41) -> 26 | C41: Mass in decigrams
A42: 39 | B42: =DEC2HEX(A42) -> 27
A43: 40 | B43: =DEC2HEX(A43) -> 28 | C43: =_xlfn.CONCAT("TM ",(ROW(C43)-43)*8+1," - ",(ROW(C43)-43)*8+8) -> TM 1 - 8
A44: 41 | B44: =DEC2HEX(A44) -> 29 | C44: =_xlfn.CONCAT("TM ",(ROW(C44)-43)*8+1," - ",(ROW(C44)-43)*8+8) -> TM 9 - 16
A45: 42 | B45: =DEC2HEX(A45) -> 2A | C45: =_xlfn.CONCAT("TM ",(ROW(C45)-43)*8+1," - ",(ROW(C45)-43)*8+8) -> TM 17 - 24
A46: 43 | B46: =DEC2HEX(A46) -> 2B | C46: =_xlfn.CONCAT("TM ",(ROW(C46)-43)*8+1," - ",(ROW(C46)-43)*8+8) -> TM 25 - 32
A47: 44 | B47: =DEC2HEX(A47) -> 2C | C47: =_xlfn.CONCAT("TM ",(ROW(C47)-43)*8+1," - ",(ROW(C47)-43)*8+8) -> TM 33 - 40
A48: 45 | B48: =DEC2HEX(A48) -> 2D | C48: =_xlfn.CONCAT("TM ",(ROW(C48)-43)*8+1," - ",(ROW(C48)-43)*8+8) -> TM 41 - 48
A49: 46 | B49: =DEC2HEX(A49) -> 2E | C49: =_xlfn.CONCAT("TM ",(ROW(C49)-43)*8+1," - ",(ROW(C49)-43)*8+8) -> TM 49 - 56
A50: 47 | B50: =DEC2HEX(A50) -> 2F | C50: =_xlfn.CONCAT("TM ",(ROW(C50)-43)*8+1," - ",(ROW(C50)-43)*8+8) -> TM 57 - 64
A51: 48 | B51: =DEC2HEX(A51) -> 30 | C51: =_xlfn.CONCAT("TM ",(ROW(C51)-43)*8+1," - ",(ROW(C51)-43)*8+8) -> TM 65 - 72
A52: 49 | B52: =DEC2HEX(A52) -> 31 | C52: =_xlfn.CONCAT("TM ",(ROW(C52)-43)*8+1," - ",(ROW(C52)-43)*8+8) -> TM 73 - 80
A53: 50 | B53: =DEC2HEX(A53) -> 32 | C53: =_xlfn.CONCAT("TM ",(ROW(C53)-43)*8+1," - ",(ROW(C53)-43)*8+8) -> TM 81 - 88
A54: 51 | B54: =DEC2HEX(A54) -> 33 | C54: =_xlfn.CONCAT("TM ",(ROW(C54)-43)*8+1," - ",(ROW(C54)-43)*8+8) -> TM 89 - 96
A55: 52 | B55: =DEC2HEX(A55) -> 34 | C55: TM 97 - 100, HM 1-4
A56: 53 | B56: =DEC2HEX(A56) -> 35 | C56: HM 5 - 12
A57: 54 | B57: =DEC2HEX(A57) -> 36 | C57: HM 13 - 20
...

Sheet Sheet1 (2)
A1: Offset | B1: Hex | C1: Dec | D1: Means | G1: =SUBSTITUTE(G2," ","") -> 2A2E2E2A3D3D0B032D0100010000000000001F144603010741A622002803000003032B0046004500F88723869B9A304C0028A92209000000090000004000C8C0C42A0601C2940000000000000000000000000000 | H1: =LEN(G1) -> 168
A2: 0 | B2: =LEFT(RIGHT(G$1,H$1-2*(ROW(B2)-2)),2) -> 2A | C2: =HEX2DEC(B2) -> 42 | D2: HP | G2: 2A 2E 2E 2A 3D 3D 0B 03 2D 01 00 01 00 00 00 00 00 00 1F 14 46 03 01 07 41 A6 22 00 28 03 00 00 03 03 2B 00 46 00 45 00 F8 87 23 86 9B 9A 30 4C 00 28 A9 22 09 00 00 00 09 00 00 00 40 00 C8 C0 C4 2A 06 01 C2 94 00 00 00 00 00 00 00 00 00 00 00 00 00 00 | I2: 1117 | J2: =DEC2HEX(I2) -> 45D | K2: 5D40 | M2: 00 | N2: =HEX2BIN(B2,8) -> 00101010 | O2: =MID($N2,9-(COLUMN(O1)-14),1) -> 0 | P2: =MID($N2,9-(COLUMN(P1)-14),1) -> 1 | Q2: =MID($N2,9-(COLUMN(Q1)-14),1) -> 0 | R2: =MID($N2,9-(COLUMN(R1)-14),1) -> 1 | S2: =MID($N2,9-(COLUMN(S1)-14),1) -> 0 | T2: =MID($N2,9-(COLUMN(T1)-14),1) -> 1 | U2: =MID($N2,9-(COLUMN(U1)-14),1) -> 0 | V2: =MID($N2,9-(COLUMN(V1)-14),1) -> 0 | W2: =_xlfn.CONCAT(O2:V2) -> 01010100 | X2: =_xlfn.CONCAT(W2:W85) -> 010101000111010001110100010101001011110010111100110100001100000010110100100000000000000010000000000000000000000000000000000000000000000000000000111110000010100001100010110000001000000011100000100000100110010101000100000000000001010011000000000000000000000011000000110000001101010000000000011000100000000010100010000000000001111111100001110001000110000111011001010110010000110000110010000000000001010010010101010001001001000000000000000000000000000010010000000000000000000000000000000000100000000000010011000000110010001101010100011000001000000001000011001010010000000000000000000000000000000000000000000000000000000000000000000000000000000000000000000000000000000000000000 | Y2: =FIND("0001001",X2) -> 196 | Z2: =SUM(Y$2:Y2)/8 -> 24.5 | AA2: =DEC2HEX(INT(Z2),2) -> 18
A3: =DEC2HEX(1+HEX2DEC(A2)) -> 1 | B3: =LEFT(RIGHT(G$1,H$1-2*(ROW(B3)-2)),2) -> 2E | C3: =HEX2DEC(B3) -> 46 | D3: ATK | I3: 100 | J3: =DEC2HEX(I3) -> 64 | M3: =DEC2HEX(1+HEX2DEC(M2),2) -> 01 | N3: =HEX2BIN(B3,8) -> 00101110 | O3: =MID($N3,9-(COLUMN(O2)-14),1) -> 0 | P3: =MID($N3,9-(COLUMN(P2)-14),1) -> 1 | Q3: =MID($N3,9-(COLUMN(Q2)-14),1) -> 1 | R3: =MID($N3,9-(COLUMN(R2)-14),1) -> 1 | S3: =MID($N3,9-(COLUMN(S2)-14),1) -> 0 | T3: =MID($N3,9-(COLUMN(T2)-14),1) -> 1 | U3: =MID($N3,9-(COLUMN(U2)-14),1) -> 0 | V3: =MID($N3,9-(COLUMN(V2)-14),1) -> 0 | W3: =_xlfn.CONCAT(O3:V3) -> 01110100 | X3: =RIGHT(X2,LEN(X2)-Y2) -> 00100110010101000100000000000001010011000000000000000000000011000000110000001101010000000000011000100000000010100010000000000001111111100001110001000110000111011001010110010000110000110010000000000001010010010101010001001001000000000000000000000000000010010000000000000000000000000000000000100000000000010011000000110010001101010100011000001000000001000011001010010000000000000000000000000000000000000000000000000000000000000000000000000000000000000000000000000000000000000000 | Y3: =FIND("0001001",X3) -> 215 | Z3: =SUM(Y$2:Y3)/8 -> 51.375 | AA3: =DEC2HEX(INT(Z3),2) -> 33
A4: =DEC2HEX(1+HEX2DEC(A3)) -> 2 | B4: =LEFT(RIGHT(G$1,H$1-2*(ROW(B4)-2)),2) -> 2E | C4: =HEX2DEC(B4) -> 46 | D4: DEF | I4: 125 | J4: =DEC2HEX(I4) -> 7D | M4: =DEC2HEX(1+HEX2DEC(M3),2) -> 02 | N4: =HEX2BIN(B4,8) -> 00101110 | O4: =MID($N4,9-(COLUMN(O3)-14),1) -> 0 | P4: =MID($N4,9-(COLUMN(P3)-14),1) -> 1 | Q4: =MID($N4,9-(COLUMN(Q3)-14),1) -> 1 | R4: =MID($N4,9-(COLUMN(R3)-14),1) -> 1 | S4: =MID($N4,9-(COLUMN(S3)-14),1) -> 0 | T4: =MID($N4,9-(COLUMN(T3)-14),1) -> 1 | U4: =MID($N4,9-(COLUMN(U3)-14),1) -> 0 | V4: =MID($N4,9-(COLUMN(V3)-14),1) -> 0 | W4: =_xlfn.CONCAT(O4:V4) -> 01110100 | X4: =RIGHT(X3,LEN(X3)-Y3) -> 001001001000000000000000000000000000010010000000000000000000000000000000000100000000000010011000000110010001101010100011000001000000001000011001010010000000000000000000000000000000000000000000000000000000000000000000000000000000000000000000000000000000000000000 | Y4: =FIND("0001001",X4) -> 35 | Z4: =SUM(Y$2:Y4)/8 -> 55.75 | AA4: =DEC2HEX(INT(Z4),2) -> 37
A5: =DEC2HEX(1+HEX2DEC(A4)) -> 3 | B5: =LEFT(RIGHT(G$1,H$1-2*(ROW(B5)-2)),2) -> 2A | C5: =HEX2DEC(B5) -> 42 | D5: SPE | M5: =DEC2HEX(1+HEX2DEC(M4),2) -> 03 | N5: =HEX2BIN(B5,8) -> 00101010 | O5: =MID($N5,9-(COLUMN(O4)-14),1) -> 0 | P5: =MID($N5,9-(COLUMN(P4)-14),1) -> 1 | Q5: =MID($N5,9-(COLUMN(Q4)-14),1) -> 0 | R5: =MID($N5,9-(COLUMN(R4)-14),1) -> 1 | S5: =MID($N5,9-(COLUMN(S4)-14),1) -> 0 | T5: =MID($N5,9-(COLUMN(T4)-14),1) -> 1 | U5: =MID($N5,9-(COLUMN(U4)-14),1) -> 0 | V5: =MID($N5,9-(COLUMN(V4)-14),1) -> 0 | W5: =_xlfn.CONCAT(O5:V5) -> 01010100 | X5: =RIGHT(X4,LEN(X4)-Y4) -> 0010010000000000000000000000000000000000100000000000010011000000110010001101010100011000001000000001000011001010010000000000000000000000000000000000000000000000000000000000000000000000000000000000000000000000000000000000000000 | Y5: =FIND("0001001",X5) -> 51 | Z5: =SUM(Y$2:Y5)/8 -> 62.125 | AA5: =DEC2HEX(INT(Z5),2) -> 3E
A6: =DEC2HEX(1+HEX2DEC(A5)) -> 4 | B6: =LEFT(RIGHT(G$1,H$1-2*(ROW(B6)-2)),2) -> 3D | C6: =HEX2DEC(B6) -> 61 | D6: SPA | M6: =DEC2HEX(1+HEX2DEC(M5),2) -> 04 | N6: =HEX2BIN(B6,8) -> 00111101 | O6: =MID($N6,9-(COLUMN(O5)-14),1) -> 1 | P6: =MID($N6,9-(COLUMN(P5)-14),1) -> 0 | Q6: =MID($N6,9-(COLUMN(Q5)-14),1) -> 1 | R6: =MID($N6,9-(COLUMN(R5)-14),1) -> 1 | S6: =MID($N6,9-(COLUMN(S5)-14),1) -> 1 | T6: =MID($N6,9-(COLUMN(T5)-14),1) -> 1 | U6: =MID($N6,9-(COLUMN(U5)-14),1) -> 0 | V6: =MID($N6,9-(COLUMN(V5)-14),1) -> 0 | W6: =_xlfn.CONCAT(O6:V6) -> 10111100 | X6: =RIGHT(X5,LEN(X5)-Y5) -> 0010011000000110010001101010100011000001000000001000011001010010000000000000000000000000000000000000000000000000000000000000000000000000000000000000000000000000000000000000000 | Y6: =FIND("0001001",X6) -> #VALUE! | Z6: =SUM(Y$2:Y6)/8 -> #VALUE! | AA6: =DEC2HEX(INT(Z6),2) -> #VALUE!
A7: =DEC2HEX(1+HEX2DEC(A6)) -> 5 | B7: =LEFT(RIGHT(G$1,H$1-2*(ROW(B7)-2)),2) -> 3D | C7: =HEX2DEC(B7) -> 61 | D7: SPD | M7: =DEC2HEX(1+HEX2DEC(M6),2) -> 05 | N7: =HEX2BIN(B7,8) -> 00111101 | O7: =MID($N7,9-(COLUMN(O6)-14),1) -> 1 | P7: =MID($N7,9-(COLUMN(P6)-14),1) -> 0 | Q7: =MID($N7,9-(COLUMN(Q6)-14),1) -> 1 | R7: =MID($N7,9-(COLUMN(R6)-14),1) -> 1 | S7: =MID($N7,9-(COLUMN(S6)-14),1) -> 1 | T7: =MID($N7,9-(COLUMN(T6)-14),1) -> 1 | U7: =MID($N7,9-(COLUMN(U6)-14),1) -> 0 | V7: =MID($N7,9-(COLUMN(V6)-14),1) -> 0 | W7: =_xlfn.CONCAT(O7:V7) -> 10111100 | X7: =RIGHT(X6,LEN(X6)-Y6) -> #VALUE! | Y7: =FIND("0001001",X7) -> #VALUE! | Z7: =SUM(Y$2:Y7)/8 -> #VALUE! | AA7: =DEC2HEX(INT(Z7),2) -> #VALUE!
A8: =DEC2HEX(1+HEX2DEC(A7)) -> 6 | B8: =LEFT(RIGHT(G$1,H$1-2*(ROW(B8)-2)),2) -> 0B | C8: =HEX2DEC(B8) -> 11 | D8: Type1 | M8: =DEC2HEX(1+HEX2DEC(M7),2) -> 06 | N8: =HEX2BIN(B8,8) -> 00001011 | O8: =MID($N8,9-(COLUMN(O7)-14),1) -> 1 | P8: =MID($N8,9-(COLUMN(P7)-14),1) -> 1 | Q8: =MID($N8,9-(COLUMN(Q7)-14),1) -> 0 | R8: =MID($N8,9-(COLUMN(R7)-14),1) -> 1 | S8: =MID($N8,9-(COLUMN(S7)-14),1) -> 0 | T8: =MID($N8,9-(COLUMN(T7)-14),1) -> 0 | U8: =MID($N8,9-(COLUMN(U7)-14),1) -> 0 | V8: =MID($N8,9-(COLUMN(V7)-14),1) -> 0 | W8: =_xlfn.CONCAT(O8:V8) -> 11010000 | X8: =RIGHT(X7,LEN(X7)-Y7) -> #VALUE! | Y8: =FIND("0001001",X8) -> #VALUE! | Z8: =SUM(Y$2:Y8)/8 -> #VALUE! | AA8: =DEC2HEX(INT(Z8),2) -> #VALUE!
A9: =DEC2HEX(1+HEX2DEC(A8)) -> 7 | B9: =LEFT(RIGHT(G$1,H$1-2*(ROW(B9)-2)),2) -> 03 | C9: =HEX2DEC(B9) -> 3 | D9: Type2 | M9: =DEC2HEX(1+HEX2DEC(M8),2) -> 07 | N9: =HEX2BIN(B9,8) -> 00000011 | O9: =MID($N9,9-(COLUMN(O8)-14),1) -> 1 | P9: =MID($N9,9-(COLUMN(P8)-14),1) -> 1 | Q9: =MID($N9,9-(COLUMN(Q8)-14),1) -> 0 | R9: =MID($N9,9-(COLUMN(R8)-14),1) -> 0 | S9: =MID($N9,9-(COLUMN(S8)-14),1) -> 0 | T9: =MID($N9,9-(COLUMN(T8)-14),1) -> 0 | U9: =MID($N9,9-(COLUMN(U8)-14),1) -> 0 | V9: =MID($N9,9-(COLUMN(V8)-14),1) -> 0 | W9: =_xlfn.CONCAT(O9:V9) -> 11000000 | X9: =RIGHT(X8,LEN(X8)-Y8) -> #VALUE! | Y9: =FIND("0001001",X9) -> #VALUE! | Z9: =SUM(Y$2:Y9)/8 -> #VALUE! | AA9: =DEC2HEX(INT(Z9),2) -> #VALUE!
A10: =DEC2HEX(1+HEX2DEC(A9)) -> 8 | B10: =LEFT(RIGHT(G$1,H$1-2*(ROW(B10)-2)),2) -> 2D | C10: =HEX2DEC(B10) -> 45 | D10: CatchRate | M10: =DEC2HEX(1+HEX2DEC(M9),2) -> 08 | N10: =HEX2BIN(B10,8) -> 00101101 | O10: =MID($N10,9-(COLUMN(O9)-14),1) -> 1 | P10: =MID($N10,9-(COLUMN(P9)-14),1) -> 0 | Q10: =MID($N10,9-(COLUMN(Q9)-14),1) -> 1 | R10: =MID($N10,9-(COLUMN(R9)-14),1) -> 1 | S10: =MID($N10,9-(COLUMN(S9)-14),1) -> 0 | T10: =MID($N10,9-(COLUMN(T9)-14),1) -> 1 | U10: =MID($N10,9-(COLUMN(U9)-14),1) -> 0 | V10: =MID($N10,9-(COLUMN(V9)-14),1) -> 0 | W10: =_xlfn.CONCAT(O10:V10) -> 10110100 | X10: =RIGHT(X9,LEN(X9)-Y9) -> #VALUE! | Y10: =FIND("0001001",X10) -> #VALUE! | Z10: =SUM(Y$2:Y10)/8 -> #VALUE! | AA10: =DEC2HEX(INT(Z10),2) -> #VALUE!
A11: =DEC2HEX(1+HEX2DEC(A10)) -> 9 | B11: =LEFT(RIGHT(G$1,H$1-2*(ROW(B11)-2)),2) -> 01 | C11: =HEX2DEC(B11) -> 1 | D11: EvoStage | M11: =DEC2HEX(1+HEX2DEC(M10),2) -> 09 | N11: =HEX2BIN(B11,8) -> 00000001 | O11: =MID($N11,9-(COLUMN(O10)-14),1) -> 1 | P11: =MID($N11,9-(COLUMN(P10)-14),1) -> 0 | Q11: =MID($N11,9-(COLUMN(Q10)-14),1) -> 0 | R11: =MID($N11,9-(COLUMN(R10)-14),1) -> 0 | S11: =MID($N11,9-(COLUMN(S10)-14),1) -> 0 | T11: =MID($N11,9-(COLUMN(T10)-14),1) -> 0 | U11: =MID($N11,9-(COLUMN(U10)-14),1) -> 0 | V11: =MID($N11,9-(COLUMN(V10)-14),1) -> 0 | W11: =_xlfn.CONCAT(O11:V11) -> 10000000 | X11: =RIGHT(X10,LEN(X10)-Y10) -> #VALUE! | Y11: =FIND("0001001",X11) -> #VALUE! | Z11: =SUM(Y$2:Y11)/8 -> #VALUE! | AA11: =DEC2HEX(INT(Z11),2) -> #VALUE!
A12: =DEC2HEX(1+HEX2DEC(A11)) -> A | B12: =LEFT(RIGHT(G$1,H$1-2*(ROW(B12)-2)),2) -> 00 | C12: =HEX2DEC(B12) -> 0 | D12: EvYield | M12: =DEC2HEX(1+HEX2DEC(M11),2) -> 0A | N12: =HEX2BIN(B12,8) -> 00000000 | O12: =MID($N12,9-(COLUMN(O11)-14),1) -> 0 | P12: =MID($N12,9-(COLUMN(P11)-14),1) -> 0 | Q12: =MID($N12,9-(COLUMN(Q11)-14),1) -> 0 | R12: =MID($N12,9-(COLUMN(R11)-14),1) -> 0 | S12: =MID($N12,9-(COLUMN(S11)-14),1) -> 0 | T12: =MID($N12,9-(COLUMN(T11)-14),1) -> 0 | U12: =MID($N12,9-(COLUMN(U11)-14),1) -> 0 | V12: =MID($N12,9-(COLUMN(V11)-14),1) -> 0 | W12: =_xlfn.CONCAT(O12:V12) -> 00000000 | X12: =RIGHT(X11,LEN(X11)-Y11) -> #VALUE! | Y12: =FIND("0001001",X12) -> #VALUE! | Z12: =SUM(Y$2:Y12)/8 -> #VALUE! | AA12: =DEC2HEX(INT(Z12),2) -> #VALUE!
A13: =DEC2HEX(1+HEX2DEC(A12)) -> B | B13: =LEFT(RIGHT(G$1,H$1-2*(ROW(B13)-2)),2) -> 01 | C13: =HEX2DEC(B13) -> 1 | D13: EvYield | M13: =DEC2HEX(1+HEX2DEC(M12),2) -> 0B | N13: =HEX2BIN(B13,8) -> 00000001 | O13: =MID($N13,9-(COLUMN(O12)-14),1) -> 1 | P13: =MID($N13,9-(COLUMN(P12)-14),1) -> 0 | Q13: =MID($N13,9-(COLUMN(Q12)-14),1) -> 0 | R13: =MID($N13,9-(COLUMN(R12)-14),1) -> 0 | S13: =MID($N13,9-(COLUMN(S12)-14),1) -> 0 | T13: =MID($N13,9-(COLUMN(T12)-14),1) -> 0 | U13: =MID($N13,9-(COLUMN(U12)-14),1) -> 0 | V13: =MID($N13,9-(COLUMN(V12)-14),1) -> 0 | W13: =_xlfn.CONCAT(O13:V13) -> 10000000 | X13: =RIGHT(X12,LEN(X12)-Y12) -> #VALUE! | Y13: =FIND("0001001",X13) -> #VALUE! | Z13: =SUM(Y$2:Y13)/8 -> #VALUE! | AA13: =DEC2HEX(INT(Z13),2) -> #VALUE!
A14: =DEC2HEX(1+HEX2DEC(A13)) -> C | B14: =LEFT(RIGHT(G$1,H$1-2*(ROW(B14)-2)),2) -> 00 | C14: =HEX2DEC(B14) -> 0 | D14: Item1 | M14: =DEC2HEX(1+HEX2DEC(M13),2) -> 0C | N14: =HEX2BIN(B14,8) -> 00000000 | O14: =MID($N14,9-(COLUMN(O13)-14),1) -> 0 | P14: =MID($N14,9-(COLUMN(P13)-14),1) -> 0 | Q14: =MID($N14,9-(COLUMN(Q13)-14),1) -> 0 | R14: =MID($N14,9-(COLUMN(R13)-14),1) -> 0 | S14: =MID($N14,9-(COLUMN(S13)-14),1) -> 0 | T14: =MID($N14,9-(COLUMN(T13)-14),1) -> 0 | U14: =MID($N14,9-(COLUMN(U13)-14),1) -> 0 | V14: =MID($N14,9-(COLUMN(V13)-14),1) -> 0 | W14: =_xlfn.CONCAT(O14:V14) -> 00000000 | X14: =RIGHT(X13,LEN(X13)-Y13) -> #VALUE! | Y14: =FIND("0001001",X14) -> #VALUE! | Z14: =SUM(Y$2:Y14)/8 -> #VALUE! | AA14: =DEC2HEX(INT(Z14),2) -> #VALUE!
A15: =DEC2HEX(1+HEX2DEC(A14)) -> D | B15: =LEFT(RIGHT(G$1,H$1-2*(ROW(B15)-2)),2) -> 00 | C15: =HEX2DEC(B15) -> 0 | D15: Item1 | M15: =DEC2HEX(1+HEX2DEC(M14),2) -> 0D | N15: =HEX2BIN(B15,8) -> 00000000 | O15: =MID($N15,9-(COLUMN(O14)-14),1) -> 0 | P15: =MID($N15,9-(COLUMN(P14)-14),1) -> 0 | Q15: =MID($N15,9-(COLUMN(Q14)-14),1) -> 0 | R15: =MID($N15,9-(COLUMN(R14)-14),1) -> 0 | S15: =MID($N15,9-(COLUMN(S14)-14),1) -> 0 | T15: =MID($N15,9-(COLUMN(T14)-14),1) -> 0 | U15: =MID($N15,9-(COLUMN(U14)-14),1) -> 0 | V15: =MID($N15,9-(COLUMN(V14)-14),1) -> 0 | W15: =_xlfn.CONCAT(O15:V15) -> 00000000 | X15: =RIGHT(X14,LEN(X14)-Y14) -> #VALUE! | Y15: =FIND("0001001",X15) -> #VALUE! | Z15: =SUM(Y$2:Y15)/8 -> #VALUE! | AA15: =DEC2HEX(INT(Z15),2) -> #VALUE!
A16: =DEC2HEX(1+HEX2DEC(A15)) -> E | B16: =LEFT(RIGHT(G$1,H$1-2*(ROW(B16)-2)),2) -> 00 | C16: =HEX2DEC(B16) -> 0 | D16: Item2 | M16: =DEC2HEX(1+HEX2DEC(M15),2) -> 0E | N16: =HEX2BIN(B16,8) -> 00000000 | O16: =MID($N16,9-(COLUMN(O15)-14),1) -> 0 | P16: =MID($N16,9-(COLUMN(P15)-14),1) -> 0 | Q16: =MID($N16,9-(COLUMN(Q15)-14),1) -> 0 | R16: =MID($N16,9-(COLUMN(R15)-14),1) -> 0 | S16: =MID($N16,9-(COLUMN(S15)-14),1) -> 0 | T16: =MID($N16,9-(COLUMN(T15)-14),1) -> 0 | U16: =MID($N16,9-(COLUMN(U15)-14),1) -> 0 | V16: =MID($N16,9-(COLUMN(V15)-14),1) -> 0 | W16: =_xlfn.CONCAT(O16:V16) -> 00000000 | X16: =RIGHT(X15,LEN(X15)-Y15) -> #VALUE! | Y16: =FIND("0001001",X16) -> #VALUE! | Z16: =SUM(Y$2:Y16)/8 -> #VALUE! | AA16: =DEC2HEX(INT(Z16),2) -> #VALUE!
... A20: =DEC2HEX(1+HEX2DEC(A19)) -> 12 | B20: =LEFT(RIGHT(G$1,H$1-2*(ROW(B20)-2)),2) -> 1F | C20: =HEX2DEC(B20) -> 31 | D20: Gender% | M20: =DEC2HEX(1+HEX2DEC(M19),2) -> 12 | N20: =HEX2BIN(B20,8) -> 00011111 | O20: =MID($N20,9-(COLUMN(O19)-14),1) -> 1 | P20: =MID($N20,9-(COLUMN(P19)-14),1) -> 1 | Q20: =MID($N20,9-(COLUMN(Q19)-14),1) -> 1 | R20: =MID($N20,9-(COLUMN(R19)-14),1) -> 1 | S20: =MID($N20,9-(COLUMN(S19)-14),1) -> 1 | T20: =MID($N20,9-(COLUMN(T19)-14),1) -> 0 | U20: =MID($N20,9-(COLUMN(U19)-14),1) -> 0 | V20: =MID($N20,9-(COLUMN(V19)-14),1) -> 0 | W20: =_xlfn.CONCAT(O20:V20) -> 11111000 | X20: =RIGHT(X19,LEN(X19)-Y19) -> #VALUE! | Y20: =FIND("0001001",X20) -> #VALUE! | Z20: =SUM(Y$2:Y20)/8 -> #VALUE! | AA20: =DEC2HEX(INT(Z20),2) -> #VALUE!
A21: =DEC2HEX(1+HEX2DEC(A20)) -> 13 | B21: =LEFT(RIGHT(G$1,H$1-2*(ROW(B21)-2)),2) -> 14 | C21: =HEX2DEC(B21) -> 20 | D21: HatchCycles | M21: =DEC2HEX(1+HEX2DEC(M20),2) -> 13 | N21: =HEX2BIN(B21,8) -> 00010100 | O21: =MID($N21,9-(COLUMN(O20)-14),1) -> 0 | P21: =MID($N21,9-(COLUMN(P20)-14),1) -> 0 | Q21: =MID($N21,9-(COLUMN(Q20)-14),1) -> 1 | R21: =MID($N21,9-(COLUMN(R20)-14),1) -> 0 | S21: =MID($N21,9-(COLUMN(S20)-14),1) -> 1 | T21: =MID($N21,9-(COLUMN(T20)-14),1) -> 0 | U21: =MID($N21,9-(COLUMN(U20)-14),1) -> 0 | V21: =MID($N21,9-(COLUMN(V20)-14),1) -> 0 | W21: =_xlfn.CONCAT(O21:V21) -> 00101000
A22: =DEC2HEX(1+HEX2DEC(A21)) -> 14 | B22: =LEFT(RIGHT(G$1,H$1-2*(ROW(B22)-2)),2) -> 46 | C22: =HEX2DEC(B22) -> 70 | D22: BaseFriendship | M22: =DEC2HEX(1+HEX2DEC(M21),2) -> 14 | N22: =HEX2BIN(B22,8) -> 01000110 | O22: =MID($N22,9-(COLUMN(O21)-14),1) -> 0 | P22: =MID($N22,9-(COLUMN(P21)-14),1) -> 1 | Q22: =MID($N22,9-(COLUMN(Q21)-14),1) -> 1 | R22: =MID($N22,9-(COLUMN(R21)-14),1) -> 0 | S22: =MID($N22,9-(COLUMN(S21)-14),1) -> 0 | T22: =MID($N22,9-(COLUMN(T21)-14),1) -> 0 | U22: =MID($N22,9-(COLUMN(U21)-14),1) -> 1 | V22: =MID($N22,9-(COLUMN(V21)-14),1) -> 0 | W22: =_xlfn.CONCAT(O22:V22) -> 01100010
A23: =DEC2HEX(1+HEX2DEC(A22)) -> 15 | B23: =LEFT(RIGHT(G$1,H$1-2*(ROW(B23)-2)),2) -> 03 | C23: =HEX2DEC(B23) -> 3 | D23: EXPGrowth | M23: =DEC2HEX(1+HEX2DEC(M22),2) -> 15 | N23: =HEX2BIN(B23,8) -> 00000011 | O23: =MID($N23,9-(COLUMN(O22)-14),1) -> 1 | P23: =MID($N23,9-(COLUMN(P22)-14),1) -> 1 | Q23: =MID($N23,9-(COLUMN(Q22)-14),1) -> 0 | R23: =MID($N23,9-(COLUMN(R22)-14),1) -> 0 | S23: =MID($N23,9-(COLUMN(S22)-14),1) -> 0 | T23: =MID($N23,9-(COLUMN(T22)-14),1) -> 0 | U23: =MID($N23,9-(COLUMN(U22)-14),1) -> 0 | V23: =MID($N23,9-(COLUMN(V22)-14),1) -> 0 | W23: =_xlfn.CONCAT(O23:V23) -> 11000000
A24: =DEC2HEX(1+HEX2DEC(A23)) -> 16 | B24: =LEFT(RIGHT(G$1,H$1-2*(ROW(B24)-2)),2) -> 01 | C24: =HEX2DEC(B24) -> 1 | D24: EggGroup1 | M24: =DEC2HEX(1+HEX2DEC(M23),2) -> 16 | N24: =HEX2BIN(B24,8) -> 00000001 | O24: =MID($N24,9-(COLUMN(O23)-14),1) -> 1 | P24: =MID($N24,9-(COLUMN(P23)-14),1) -> 0 | Q24: =MID($N24,9-(COLUMN(Q23)-14),1) -> 0 | R24: =MID($N24,9-(COLUMN(R23)-14),1) -> 0 | S24: =MID($N24,9-(COLUMN(S23)-14),1) -> 0 | T24: =MID($N24,9-(COLUMN(T23)-14),1) -> 0 | U24: =MID($N24,9-(COLUMN(U23)-14),1) -> 0 | V24: =MID($N24,9-(COLUMN(V23)-14),1) -> 0 | W24: =_xlfn.CONCAT(O24:V24) -> 10000000
A25: =DEC2HEX(1+HEX2DEC(A24)) -> 17 | B25: =LEFT(RIGHT(G$1,H$1-2*(ROW(B25)-2)),2) -> 07 | C25: =HEX2DEC(B25) -> 7 | D25: EggGroup2 | M25: =DEC2HEX(1+HEX2DEC(M24),2) -> 17 | N25: =HEX2BIN(B25,8) -> 00000111 | O25: =MID($N25,9-(COLUMN(O24)-14),1) -> 1 | P25: =MID($N25,9-(COLUMN(P24)-14),1) -> 1 | Q25: =MID($N25,9-(COLUMN(Q24)-14),1) -> 1 | R25: =MID($N25,9-(COLUMN(R24)-14),1) -> 0 | S25: =MID($N25,9-(COLUMN(S24)-14),1) -> 0 | T25: =MID($N25,9-(COLUMN(T24)-14),1) -> 0 | U25: =MID($N25,9-(COLUMN(U24)-14),1) -> 0 | V25: =MID($N25,9-(COLUMN(V24)-14),1) -> 0 | W25: =_xlfn.CONCAT(O25:V25) -> 11100000
A26: =DEC2HEX(1+HEX2DEC(A25)) -> 18 | B26: =LEFT(RIGHT(G$1,H$1-2*(ROW(B26)-2)),2) -> 41 | C26: =HEX2DEC(B26) -> 65 | D26: Ability1 | M26: =DEC2HEX(1+HEX2DEC(M25),2) -> 18 | N26: =HEX2BIN(B26,8) -> 01000001 | O26: =MID($N26,9-(COLUMN(O25)-14),1) -> 1 | P26: =MID($N26,9-(COLUMN(P25)-14),1) -> 0 | Q26: =MID($N26,9-(COLUMN(Q25)-14),1) -> 0 | R26: =MID($N26,9-(COLUMN(R25)-14),1) -> 0 | S26: =MID($N26,9-(COLUMN(S25)-14),1) -> 0 | T26: =MID($N26,9-(COLUMN(T25)-14),1) -> 0 | U26: =MID($N26,9-(COLUMN(U25)-14),1) -> 1 | V26: =MID($N26,9-(COLUMN(V25)-14),1) -> 0 | W26: =_xlfn.CONCAT(O26:V26) -> 10000010
A27: =DEC2HEX(1+HEX2DEC(A26)) -> 19 | B27: =LEFT(RIGHT(G$1,H$1-2*(ROW(B27)-2)),2) -> A6 | C27: =HEX2DEC(B27) -> 166 | D27: Ability2 | M27: =DEC2HEX(1+HEX2DEC(M26),2) -> 19 | N27: =HEX2BIN(B27,8) -> 10100110 | O27: =MID($N27,9-(COLUMN(O26)-14),1) -> 0 | P27: =MID($N27,9-(COLUMN(P26)-14),1) -> 1 | Q27: =MID($N27,9-(COLUMN(Q26)-14),1) -> 1 | R27: =MID($N27,9-(COLUMN(R26)-14),1) -> 0 | S27: =MID($N27,9-(COLUMN(S26)-14),1) -> 0 | T27: =MID($N27,9-(COLUMN(T26)-14),1) -> 1 | U27: =MID($N27,9-(COLUMN(U26)-14),1) -> 0 | V27: =MID($N27,9-(COLUMN(V26)-14),1) -> 1 | W27: =_xlfn.CONCAT(O27:V27) -> 01100101
A28: =DEC2HEX(1+HEX2DEC(A27)) -> 1A | B28: =LEFT(RIGHT(G$1,H$1-2*(ROW(B28)-2)),2) -> 22 | C28: =HEX2DEC(B28) -> 34 | D28: Ability3 | M28: =DEC2HEX(1+HEX2DEC(M27),2) -> 1A | N28: =HEX2BIN(B28,8) -> 00100010 | O28: =MID($N28,9-(COLUMN(O27)-14),1) -> 0 | P28: =MID($N28,9-(COLUMN(P27)-14),1) -> 1 | Q28: =MID($N28,9-(COLUMN(Q27)-14),1) -> 0 | R28: =MID($N28,9-(COLUMN(R27)-14),1) -> 0 | S28: =MID($N28,9-(COLUMN(S27)-14),1) -> 0 | T28: =MID($N28,9-(COLUMN(T27)-14),1) -> 1 | U28: =MID($N28,9-(COLUMN(U27)-14),1) -> 0 | V28: =MID($N28,9-(COLUMN(V27)-14),1) -> 0 | W28: =_xlfn.CONCAT(O28:V28) -> 01000100
A29: =DEC2HEX(1+HEX2DEC(A28)) -> 1B | B29: =LEFT(RIGHT(G$1,H$1-2*(ROW(B29)-2)),2) -> 00 | C29: =HEX2DEC(B29) -> 0 | D29: EscapeRate | M29: =DEC2HEX(1+HEX2DEC(M28),2) -> 1B | N29: =HEX2BIN(B29,8) -> 00000000 | O29: =MID($N29,9-(COLUMN(O28)-14),1) -> 0 | P29: =MID($N29,9-(COLUMN(P28)-14),1) -> 0 | Q29: =MID($N29,9-(COLUMN(Q28)-14),1) -> 0 | R29: =MID($N29,9-(COLUMN(R28)-14),1) -> 0 | S29: =MID($N29,9-(COLUMN(S28)-14),1) -> 0 | T29: =MID($N29,9-(COLUMN(T28)-14),1) -> 0 | U29: =MID($N29,9-(COLUMN(U28)-14),1) -> 0 | V29: =MID($N29,9-(COLUMN(V28)-14),1) -> 0 | W29: =_xlfn.CONCAT(O29:V29) -> 00000000
A30: =DEC2HEX(1+HEX2DEC(A29)) -> 1C | B30: =LEFT(RIGHT(G$1,H$1-2*(ROW(B30)-2)),2) -> 28 | C30: =HEX2DEC(B30) -> 40 | D30: FormeStatsIndex1 | E30: =C30+256*C31 -> 808 | M30: =DEC2HEX(1+HEX2DEC(M29),2) -> 1C | N30: =HEX2BIN(B30,8) -> 00101000 | O30: =MID($N30,9-(COLUMN(O29)-14),1) -> 0 | P30: =MID($N30,9-(COLUMN(P29)-14),1) -> 0 | Q30: =MID($N30,9-(COLUMN(Q29)-14),1) -> 0 | R30: =MID($N30,9-(COLUMN(R29)-14),1) -> 1 | S30: =MID($N30,9-(COLUMN(S29)-14),1) -> 0 | T30: =MID($N30,9-(COLUMN(T29)-14),1) -> 1 | U30: =MID($N30,9-(COLUMN(U29)-14),1) -> 0 | V30: =MID($N30,9-(COLUMN(V29)-14),1) -> 0 | W30: =_xlfn.CONCAT(O30:V30) -> 00010100
A31: =DEC2HEX(1+HEX2DEC(A30)) -> 1D | B31: =LEFT(RIGHT(G$1,H$1-2*(ROW(B31)-2)),2) -> 03 | C31: =HEX2DEC(B31) -> 3 | D31: FormeStatsIndex2 | M31: =DEC2HEX(1+HEX2DEC(M30),2) -> 1D | N31: =HEX2BIN(B31,8) -> 00000011 | O31: =MID($N31,9-(COLUMN(O30)-14),1) -> 1 | P31: =MID($N31,9-(COLUMN(P30)-14),1) -> 1 | Q31: =MID($N31,9-(COLUMN(Q30)-14),1) -> 0 | R31: =MID($N31,9-(COLUMN(R30)-14),1) -> 0 | S31: =MID($N31,9-(COLUMN(S30)-14),1) -> 0 | T31: =MID($N31,9-(COLUMN(T30)-14),1) -> 0 | U31: =MID($N31,9-(COLUMN(U30)-14),1) -> 0 | V31: =MID($N31,9-(COLUMN(V30)-14),1) -> 0 | W31: =_xlfn.CONCAT(O31:V31) -> 11000000
A32: =DEC2HEX(1+HEX2DEC(A31)) -> 1E | B32: =LEFT(RIGHT(G$1,H$1-2*(ROW(B32)-2)),2) -> 00 | C32: =HEX2DEC(B32) -> 0 | D32: FormeSprite1 | M32: =DEC2HEX(1+HEX2DEC(M31),2) -> 1E | N32: =HEX2BIN(B32,8) -> 00000000 | O32: =MID($N32,9-(COLUMN(O31)-14),1) -> 0 | P32: =MID($N32,9-(COLUMN(P31)-14),1) -> 0 | Q32: =MID($N32,9-(COLUMN(Q31)-14),1) -> 0 | R32: =MID($N32,9-(COLUMN(R31)-14),1) -> 0 | S32: =MID($N32,9-(COLUMN(S31)-14),1) -> 0 | T32: =MID($N32,9-(COLUMN(T31)-14),1) -> 0 | U32: =MID($N32,9-(COLUMN(U31)-14),1) -> 0 | V32: =MID($N32,9-(COLUMN(V31)-14),1) -> 0 | W32: =_xlfn.CONCAT(O32:V32) -> 00000000
A33: =DEC2HEX(1+HEX2DEC(A32)) -> 1F | B33: =LEFT(RIGHT(G$1,H$1-2*(ROW(B33)-2)),2) -> 00 | C33: =HEX2DEC(B33) -> 0 | D33: FormeSprite2 | M33: =DEC2HEX(1+HEX2DEC(M32),2) -> 1F | N33: =HEX2BIN(B33,8) -> 00000000 | O33: =MID($N33,9-(COLUMN(O32)-14),1) -> 0 | P33: =MID($N33,9-(COLUMN(P32)-14),1) -> 0 | Q33: =MID($N33,9-(COLUMN(Q32)-14),1) -> 0 | R33: =MID($N33,9-(COLUMN(R32)-14),1) -> 0 | S33: =MID($N33,9-(COLUMN(S32)-14),1) -> 0 | T33: =MID($N33,9-(COLUMN(T32)-14),1) -> 0 | U33: =MID($N33,9-(COLUMN(U32)-14),1) -> 0 | V33: =MID($N33,9-(COLUMN(V32)-14),1) -> 0 | W33: =_xlfn.CONCAT(O33:V33) -> 00000000
A34: =DEC2HEX(1+HEX2DEC(A33)) -> 20 | B34: =LEFT(RIGHT(G$1,H$1-2*(ROW(B34)-2)),2) -> 03 | C34: =HEX2DEC(B34) -> 3 | D34: FormeCount | M34: =DEC2HEX(1+HEX2DEC(M33),2) -> 20 | N34: =HEX2BIN(B34,8) -> 00000011 | O34: =MID($N34,9-(COLUMN(O33)-14),1) -> 1 | P34: =MID($N34,9-(COLUMN(P33)-14),1) -> 1 | Q34: =MID($N34,9-(COLUMN(Q33)-14),1) -> 0 | R34: =MID($N34,9-(COLUMN(R33)-14),1) -> 0 | S34: =MID($N34,9-(COLUMN(S33)-14),1) -> 0 | T34: =MID($N34,9-(COLUMN(T33)-14),1) -> 0 | U34: =MID($N34,9-(COLUMN(U33)-14),1) -> 0 | V34: =MID($N34,9-(COLUMN(V33)-14),1) -> 0 | W34: =_xlfn.CONCAT(O34:V34) -> 11000000
A35: =DEC2HEX(1+HEX2DEC(A34)) -> 21 | B35: =LEFT(RIGHT(G$1,H$1-2*(ROW(B35)-2)),2) -> 03 | C35: =HEX2DEC(B35) -> 3 | D35: Color | M35: =DEC2HEX(1+HEX2DEC(M34),2) -> 21 | N35: =HEX2BIN(B35,8) -> 00000011 | O35: =MID($N35,9-(COLUMN(O34)-14),1) -> 1 | P35: =MID($N35,9-(COLUMN(P34)-14),1) -> 1 | Q35: =MID($N35,9-(COLUMN(Q34)-14),1) -> 0 | R35: =MID($N35,9-(COLUMN(R34)-14),1) -> 0 | S35: =MID($N35,9-(COLUMN(S34)-14),1) -> 0 | T35: =MID($N35,9-(COLUMN(T34)-14),1) -> 0 | U35: =MID($N35,9-(COLUMN(U34)-14),1) -> 0 | V35: =MID($N35,9-(COLUMN(V34)-14),1) -> 0 | W35: =_xlfn.CONCAT(O35:V35) -> 11000000
A36: =DEC2HEX(1+HEX2DEC(A35)) -> 22 | B36: =LEFT(RIGHT(G$1,H$1-2*(ROW(B36)-2)),2) -> 2B | C36: =HEX2DEC(B36) -> 43 | D36: BaseEXP | M36: =DEC2HEX(1+HEX2DEC(M35),2) -> 22 | N36: =HEX2BIN(B36,8) -> 00101011 | O36: =MID($N36,9-(COLUMN(O35)-14),1) -> 1 | P36: =MID($N36,9-(COLUMN(P35)-14),1) -> 1 | Q36: =MID($N36,9-(COLUMN(Q35)-14),1) -> 0 | R36: =MID($N36,9-(COLUMN(R35)-14),1) -> 1 | S36: =MID($N36,9-(COLUMN(S35)-14),1) -> 0 | T36: =MID($N36,9-(COLUMN(T35)-14),1) -> 1 | U36: =MID($N36,9-(COLUMN(U35)-14),1) -> 0 | V36: =MID($N36,9-(COLUMN(V35)-14),1) -> 0 | W36: =_xlfn.CONCAT(O36:V36) -> 11010100
A37: =DEC2HEX(1+HEX2DEC(A36)) -> 23 | B37: =LEFT(RIGHT(G$1,H$1-2*(ROW(B37)-2)),2) -> 00 | C37: =HEX2DEC(B37) -> 0 | M37: =DEC2HEX(1+HEX2DEC(M36),2) -> 23 | N37: =HEX2BIN(B37,8) -> 00000000 | O37: =MID($N37,9-(COLUMN(O36)-14),1) -> 0 | P37: =MID($N37,9-(COLUMN(P36)-14),1) -> 0 | Q37: =MID($N37,9-(COLUMN(Q36)-14),1) -> 0 | R37: =MID($N37,9-(COLUMN(R36)-14),1) -> 0 | S37: =MID($N37,9-(COLUMN(S36)-14),1) -> 0 | T37: =MID($N37,9-(COLUMN(T36)-14),1) -> 0 | U37: =MID($N37,9-(COLUMN(U36)-14),1) -> 0 | V37: =MID($N37,9-(COLUMN(V36)-14),1) -> 0 | W37: =_xlfn.CONCAT(O37:V37) -> 00000000
A38: =DEC2HEX(1+HEX2DEC(A37)) -> 24 | B38: =LEFT(RIGHT(G$1,H$1-2*(ROW(B38)-2)),2) -> 46 | C38: =HEX2DEC(B38) -> 70 | M38: =DEC2HEX(1+HEX2DEC(M37),2) -> 24 | N38: =HEX2BIN(B38,8) -> 01000110 | O38: =MID($N38,9-(COLUMN(O37)-14),1) -> 0 | P38: =MID($N38,9-(COLUMN(P37)-14),1) -> 1 | Q38: =MID($N38,9-(COLUMN(Q37)-14),1) -> 1 | R38: =MID($N38,9-(COLUMN(R37)-14),1) -> 0 | S38: =MID($N38,9-(COLUMN(S37)-14),1) -> 0 | T38: =MID($N38,9-(COLUMN(T37)-14),1) -> 0 | U38: =MID($N38,9-(COLUMN(U37)-14),1) -> 1 | V38: =MID($N38,9-(COLUMN(V37)-14),1) -> 0 | W38: =_xlfn.CONCAT(O38:V38) -> 01100010
A39: =DEC2HEX(1+HEX2DEC(A38)) -> 25 | B39: =LEFT(RIGHT(G$1,H$1-2*(ROW(B39)-2)),2) -> 00 | C39: =HEX2DEC(B39) -> 0 | M39: =DEC2HEX(1+HEX2DEC(M38),2) -> 25 | N39: =HEX2BIN(B39,8) -> 00000000 | O39: =MID($N39,9-(COLUMN(O38)-14),1) -> 0 | P39: =MID($N39,9-(COLUMN(P38)-14),1) -> 0 | Q39: =MID($N39,9-(COLUMN(Q38)-14),1) -> 0 | R39: =MID($N39,9-(COLUMN(R38)-14),1) -> 0 | S39: =MID($N39,9-(COLUMN(S38)-14),1) -> 0 | T39: =MID($N39,9-(COLUMN(T38)-14),1) -> 0 | U39: =MID($N39,9-(COLUMN(U38)-14),1) -> 0 | V39: =MID($N39,9-(COLUMN(V38)-14),1) -> 0 | W39: =_xlfn.CONCAT(O39:V39) -> 00000000
A40: =DEC2HEX(1+HEX2DEC(A39)) -> 26 | B40: =LEFT(RIGHT(G$1,H$1-2*(ROW(B40)-2)),2) -> 45 | C40: =HEX2DEC(B40) -> 69 | M40: =DEC2HEX(1+HEX2DEC(M39),2) -> 26 | N40: =HEX2BIN(B40,8) -> 01000101 | O40: =MID($N40,9-(COLUMN(O39)-14),1) -> 1 | P40: =MID($N40,9-(COLUMN(P39)-14),1) -> 0 | Q40: =MID($N40,9-(COLUMN(Q39)-14),1) -> 1 | R40: =MID($N40,9-(COLUMN(R39)-14),1) -> 0 | S40: =MID($N40,9-(COLUMN(S39)-14),1) -> 0 | T40: =MID($N40,9-(COLUMN(T39)-14),1) -> 0 | U40: =MID($N40,9-(COLUMN(U39)-14),1) -> 1 | V40: =MID($N40,9-(COLUMN(V39)-14),1) -> 0 | W40: =_xlfn.CONCAT(O40:V40) -> 10100010
A41: =DEC2HEX(1+HEX2DEC(A40)) -> 27 | B41: =LEFT(RIGHT(G$1,H$1-2*(ROW(B41)-2)),2) -> 00 | C41: =HEX2DEC(B41) -> 0 | M41: =DEC2HEX(1+HEX2DEC(M40),2) -> 27 | N41: =HEX2BIN(B41,8) -> 00000000 | O41: =MID($N41,9-(COLUMN(O40)-14),1) -> 0 | P41: =MID($N41,9-(COLUMN(P40)-14),1) -> 0 | Q41: =MID($N41,9-(COLUMN(Q40)-14),1) -> 0 | R41: =MID($N41,9-(COLUMN(R40)-14),1) -> 0 | S41: =MID($N41,9-(COLUMN(S40)-14),1) -> 0 | T41: =MID($N41,9-(COLUMN(T40)-14),1) -> 0 | U41: =MID($N41,9-(COLUMN(U40)-14),1) -> 0 | V41: =MID($N41,9-(COLUMN(V40)-14),1) -> 0 | W41: =_xlfn.CONCAT(O41:V41) -> 00000000
A42: =DEC2HEX(1+HEX2DEC(A41)) -> 28 | B42: =LEFT(RIGHT(G$1,H$1-2*(ROW(B42)-2)),2) -> F8 | C42: =HEX2DEC(B42) -> 248 | M42: =DEC2HEX(1+HEX2DEC(M41),2) -> 28 | N42: =HEX2BIN(B42,8) -> 11111000 | O42: =MID($N42,9-(COLUMN(O41)-14),1) -> 0 | P42: =MID($N42,9-(COLUMN(P41)-14),1) -> 0 | Q42: =MID($N42,9-(COLUMN(Q41)-14),1) -> 0 | R42: =MID($N42,9-(COLUMN(R41)-14),1) -> 1 | S42: =MID($N42,9-(COLUMN(S41)-14),1) -> 1 | T42: =MID($N42,9-(COLUMN(T41)-14),1) -> 1 | U42: =MID($N42,9-(COLUMN(U41)-14),1) -> 1 | V42: =MID($N42,9-(COLUMN(V41)-14),1) -> 1 | W42: =_xlfn.CONCAT(O42:V42) -> 00011111
A43: =DEC2HEX(1+HEX2DEC(A42)) -> 29 | B43: =LEFT(RIGHT(G$1,H$1-2*(ROW(B43)-2)),2) -> 87 | C43: =HEX2DEC(B43) -> 135 | M43: =DEC2HEX(1+HEX2DEC(M42),2) -> 29 | N43: =HEX2BIN(B43,8) -> 10000111 | O43: =MID($N43,9-(COLUMN(O42)-14),1) -> 1 | P43: =MID($N43,9-(COLUMN(P42)-14),1) -> 1 | Q43: =MID($N43,9-(COLUMN(Q42)-14),1) -> 1 | R43: =MID($N43,9-(COLUMN(R42)-14),1) -> 0 | S43: =MID($N43,9-(COLUMN(S42)-14),1) -> 0 | T43: =MID($N43,9-(COLUMN(T42)-14),1) -> 0 | U43: =MID($N43,9-(COLUMN(U42)-14),1) -> 0 | V43: =MID($N43,9-(COLUMN(V42)-14),1) -> 1 | W43: =_xlfn.CONCAT(O43:V43) -> 11100001
...

Sheet Sheet1
A1: Offset | C1: Field | D1: Galarian Slowking | H1: Bulbasaur | U1: 95 | AA1: 106 | AB1: 88 | AC1: 100
D2: Hex | E2: Dec | F2: Inter. | H2: Hex | I2: Dec | J2: Inter. | L2: Hex | M2: Dec | N2: Inter. | P2: Hex | Q2: Dec | R2: Inter. | U2: =DEC2HEX(U1) -> 5F | W2: 6A586441876A0C0C2D0300030000000000007F1446030105090939004F0300000202E6008C00670220C29BC5009A89058821C0120800000000000000103010512118820004000000000000000000000000000000 | X2: =LEN(W2) -> 168 | AA2: =DEC2HEX(AA1) -> 6A | AB2: =DEC2HEX(AB1) -> 58 | AC2: =DEC2HEX(AC1) -> 64
A3: 0 | B3: =DEC2HEX(A3) -> 0 | C3: HP | D3: AB | E3: =HEX2DEC(D3) -> 171 | H3: 2A | I3: =HEX2DEC(H3) -> 42 | L3: 6A | M3: =HEX2DEC(L3) -> 106 | P3: 6A | Q3: =HEX2DEC(P3) -> 106 | V3: =LEFT(RIGHT($W$2,$X$2-2*(ROW(V3)-3)),2) -> 6A
A4: 1 | B4: =DEC2HEX(A4) -> 1 | C4: Attack | D4: 7C | E4: =HEX2DEC(D4) -> 124 | H4: 2E | I4: =HEX2DEC(H4) -> 46 | L4: 58 | M4: =HEX2DEC(L4) -> 88 | P4: 6D | Q4: =HEX2DEC(P4) -> 109 | V4: =LEFT(RIGHT($W$2,$X$2-2*(ROW(V4)-3)),2) -> 58
A5: 2 | B5: =DEC2HEX(A5) -> 2 | C5: Defense | D5: 7C | E5: =HEX2DEC(D5) -> 124 | H5: 2E | I5: =HEX2DEC(H5) -> 46 | L5: 64 | M5: =HEX2DEC(L5) -> 100 | P5: 78 | Q5: =HEX2DEC(P5) -> 120 | V5: =LEFT(RIGHT($W$2,$X$2-2*(ROW(V5)-3)),2) -> 64
A6: 3 | B6: =DEC2HEX(A6) -> 3 | C6: Speed | D6: 1D | E6: =HEX2DEC(D6) -> 29 | H6: 2A | I6: =HEX2DEC(H6) -> 42 | L6: 41 | M6: =HEX2DEC(L6) -> 65 | P6: 58 | Q6: =HEX2DEC(P6) -> 88 | V6: =LEFT(RIGHT($W$2,$X$2-2*(ROW(V6)-3)),2) -> 41
A7: 4 | B7: =DEC2HEX(A7) -> 4 | C7: Special Attack | D7: 7C | E7: =HEX2DEC(D7) -> 124 | H7: 3D | I7: =HEX2DEC(H7) -> 61 | L7: 87 | M7: =HEX2DEC(L7) -> 135 | P7: BD | Q7: =HEX2DEC(P7) -> 189 | V7: =LEFT(RIGHT($W$2,$X$2-2*(ROW(V7)-3)),2) -> 87
A8: 5 | B8: =DEC2HEX(A8) -> 5 | C8: Special Defense | D8: 5A | E8: =HEX2DEC(D8) -> 90 | H8: 3D | I8: =HEX2DEC(H8) -> 61 | L8: 6A | M8: =HEX2DEC(L8) -> 106 | P8: 7E | Q8: =HEX2DEC(P8) -> 126 | V8: =LEFT(RIGHT($W$2,$X$2-2*(ROW(V8)-3)),2) -> 6A
A9: 6 | B9: =DEC2HEX(A9) -> 6 | C9: Type 1 | D9: 03 | E9: =HEX2DEC(D9) -> 3 | F9: =_xlfn.XLOOKUP(E9,Sheet2!$A:$A,Sheet2!$B:$B) -> Poison | H9: 0B | I9: =HEX2DEC(H9) -> 11 | J9: =_xlfn.XLOOKUP(I9,Sheet2!$A:$A,Sheet2!$B:$B) -> Grass | L9: 0C | M9: =HEX2DEC(L9) -> 12 | N9: =_xlfn.XLOOKUP(M9,Sheet2!$A:$A,Sheet2!$B:$B) -> Electric | P9: 0C | Q9: =HEX2DEC(P9) -> 12 | R9: =_xlfn.XLOOKUP(Q9,Sheet2!$A:$A,Sheet2!$B:$B) -> Electric | V9: =LEFT(RIGHT($W$2,$X$2-2*(ROW(V9)-3)),2) -> 0C
A10: 7 | B10: =DEC2HEX(A10) -> 7 | C10: Type 2 | D10: 0D | E10: =HEX2DEC(D10) -> 13 | F10: =_xlfn.XLOOKUP(E10,Sheet2!$A:$A,Sheet2!$B:$B) -> Psychic | H10: 03 | I10: =HEX2DEC(H10) -> 3 | J10: =_xlfn.XLOOKUP(I10,Sheet2!$A:$A,Sheet2!$B:$B) -> Poison | L10: 0C | M10: =HEX2DEC(L10) -> 12 | N10: =_xlfn.XLOOKUP(M10,Sheet2!$A:$A,Sheet2!$B:$B) -> Electric | P10: 0F | Q10: =HEX2DEC(P10) -> 15 | R10: =_xlfn.XLOOKUP(Q10,Sheet2!$A:$A,Sheet2!$B:$B) -> Dragon | V10: =LEFT(RIGHT($W$2,$X$2-2*(ROW(V10)-3)),2) -> 0C
A11: 8 | B11: =DEC2HEX(A11) -> 8 | C11: Catch Rate | D11: 46 | E11: =HEX2DEC(D11) -> 70 | H11: 2D | I11: =HEX2DEC(H11) -> 45 | L11: 2D | M11: =HEX2DEC(L11) -> 45 | P11: 2D | Q11: =HEX2DEC(P11) -> 45 | V11: =LEFT(RIGHT($W$2,$X$2-2*(ROW(V11)-3)),2) -> 2D
A12: 9 | B12: =DEC2HEX(A12) -> 9 | C12: Evolution Stage | D12: 02 | E12: =HEX2DEC(D12) -> 2 | H12: 01 | I12: =HEX2DEC(H12) -> 1 | L12: 03 | M12: =HEX2DEC(L12) -> 3 | P12: 03 | Q12: =HEX2DEC(P12) -> 3 | V12: =LEFT(RIGHT($W$2,$X$2-2*(ROW(V12)-3)),2) -> 03
A13: 10 | B13: =DEC2HEX(A13) -> A | C13: Effort Values | D13: 00 | E13: =HEX2DEC(D13) -> 0 | H13: 00 | I13: =HEX2DEC(H13) -> 0 | L13: 00 | M13: =HEX2DEC(L13) -> 0 | P13: 00 | Q13: =HEX2DEC(P13) -> 0 | V13: =LEFT(RIGHT($W$2,$X$2-2*(ROW(V13)-3)),2) -> 00
A14: 11 | B14: =DEC2HEX(A14) -> B | C14: Effort Values | D14: 0C | E14: =HEX2DEC(D14) -> 12 | H14: 01 | I14: =HEX2DEC(H14) -> 1 | L14: 03 | M14: =HEX2DEC(L14) -> 3 | P14: 03 | Q14: =HEX2DEC(P14) -> 3 | V14: =LEFT(RIGHT($W$2,$X$2-2*(ROW(V14)-3)),2) -> 03
A15: 12 | B15: =DEC2HEX(A15) -> C | C15: Item 1 | D15: 00 | E15: =HEX2DEC(D15) -> 0 | H15: 00 | I15: =HEX2DEC(H15) -> 0 | L15: 00 | M15: =HEX2DEC(L15) -> 0 | P15: 00 | Q15: =HEX2DEC(P15) -> 0 | V15: =LEFT(RIGHT($W$2,$X$2-2*(ROW(V15)-3)),2) -> 00
A16: 13 | B16: =DEC2HEX(A16) -> D | C16: Item 1 | D16: 00 | E16: =HEX2DEC(D16) -> 0 | H16: 00 | I16: =HEX2DEC(H16) -> 0 | L16: 00 | M16: =HEX2DEC(L16) -> 0 | P16: 00 | Q16: =HEX2DEC(P16) -> 0 | V16: =LEFT(RIGHT($W$2,$X$2-2*(ROW(V16)-3)),2) -> 00
A17: 14 | B17: =DEC2HEX(A17) -> E | C17: Item 2 | D17: DD | E17: =HEX2DEC(D17) -> 221 | H17: 00 | I17: =HEX2DEC(H17) -> 0 | L17: 00 | M17: =HEX2DEC(L17) -> 0 | P17: 00 | Q17: =HEX2DEC(P17) -> 0 | V17: =LEFT(RIGHT($W$2,$X$2-2*(ROW(V17)-3)),2) -> 00
A18: 15 | B18: =DEC2HEX(A18) -> F | C18: Item 2 | D18: 00 | E18: =HEX2DEC(D18) -> 0 | H18: 00 | I18: =HEX2DEC(H18) -> 0 | L18: 00 | M18: =HEX2DEC(L18) -> 0 | P18: 00 | Q18: =HEX2DEC(P18) -> 0 | V18: =LEFT(RIGHT($W$2,$X$2-2*(ROW(V18)-3)),2) -> 00
A19: 16 | B19: =DEC2HEX(A19) -> 10 | C19: Item 3 | D19: 00 | E19: =HEX2DEC(D19) -> 0 | H19: 00 | I19: =HEX2DEC(H19) -> 0 | L19: 00 | M19: =HEX2DEC(L19) -> 0 | P19: 00 | Q19: =HEX2DEC(P19) -> 0 | V19: =LEFT(RIGHT($W$2,$X$2-2*(ROW(V19)-3)),2) -> 00
A20: 17 | B20: =DEC2HEX(A20) -> 11 | C20: Item 3 | D20: 00 | E20: =HEX2DEC(D20) -> 0 | H20: 00 | I20: =HEX2DEC(H20) -> 0 | L20: 00 | M20: =HEX2DEC(L20) -> 0 | P20: 00 | Q20: =HEX2DEC(P20) -> 0 | V20: =LEFT(RIGHT($W$2,$X$2-2*(ROW(V20)-3)),2) -> 00
A21: 18 | B21: =DEC2HEX(A21) -> 12 | C21: Gender | D21: 7F | E21: =HEX2DEC(D21) -> 127 | H21: 1F | I21: =HEX2DEC(H21) -> 31 | L21: 7F | M21: =HEX2DEC(L21) -> 127 | P21: 7F | Q21: =HEX2DEC(P21) -> 127 | V21: =LEFT(RIGHT($W$2,$X$2-2*(ROW(V21)-3)),2) -> 7F
A22: 19 | B22: =DEC2HEX(A22) -> 13 | C22: Hatch Cycles | D22: 14 | E22: =HEX2DEC(D22) -> 20 | H22: 14 | I22: =HEX2DEC(H22) -> 20 | L22: 14 | M22: =HEX2DEC(L22) -> 20 | P22: 14 | Q22: =HEX2DEC(P22) -> 20 | V22: =LEFT(RIGHT($W$2,$X$2-2*(ROW(V22)-3)),2) -> 14
... A24: 21 | B24: =DEC2HEX(A24) -> 15 | C24: Level curve | D24: 02 | E24: =HEX2DEC(D24) -> 2 | H24: 03 | I24: =HEX2DEC(H24) -> 3 | L24: 03 | M24: =HEX2DEC(L24) -> 3 | P24: 03 | Q24: =HEX2DEC(P24) -> 3 | V24: =LEFT(RIGHT($W$2,$X$2-2*(ROW(V24)-3)),2) -> 03
A25: 22 | B25: =DEC2HEX(A25) -> 16 | C25: Egg Group 1 | D25: 01 | E25: =HEX2DEC(D25) -> 1 | F25: =_xlfn.XLOOKUP(E25,Sheet2!$A:$A,Sheet2!$C:$C) -> Monster | H25: 01 | I25: =HEX2DEC(H25) -> 1 | J25: =_xlfn.XLOOKUP(I25,Sheet2!$A:$A,Sheet2!$C:$C) -> Monster | L25: 01 | M25: =HEX2DEC(L25) -> 1 | N25: =_xlfn.XLOOKUP(M25,Sheet2!$A:$A,Sheet2!$C:$C) -> Monster | P25: 01 | Q25: =HEX2DEC(P25) -> 1 | R25: =_xlfn.XLOOKUP(Q25,Sheet2!$A:$A,Sheet2!$C:$C) -> Monster | V25: =LEFT(RIGHT($W$2,$X$2-2*(ROW(V25)-3)),2) -> 01
A26: 23 | B26: =DEC2HEX(A26) -> 17 | C26: Egg Group 2 | D26: 02 | E26: =HEX2DEC(D26) -> 2 | F26: =_xlfn.XLOOKUP(E26,Sheet2!$A:$A,Sheet2!$C:$C) -> Water 1 (Amphibious) | H26: 07 | I26: =HEX2DEC(H26) -> 7 | J26: =_xlfn.XLOOKUP(I26,Sheet2!$A:$A,Sheet2!$C:$C) -> Grass | L26: 05 | M26: =HEX2DEC(L26) -> 5 | N26: =_xlfn.XLOOKUP(M26,Sheet2!$A:$A,Sheet2!$C:$C) -> Field | P26: 05 | Q26: =HEX2DEC(P26) -> 5 | R26: =_xlfn.XLOOKUP(Q26,Sheet2!$A:$A,Sheet2!$C:$C) -> Field | V26: =LEFT(RIGHT($W$2,$X$2-2*(ROW(V26)-3)),2) -> 05
A27: 24 | B27: =DEC2HEX(A27) -> 18 | C27: Ability 1 | D27: D5 | E27: =HEX2DEC(D27) -> 213 | F27: =_xlfn.XLOOKUP(E27,Sheet2!$A:$A,Sheet2!$D:$D) -> Comatose | H27: 41 | I27: =HEX2DEC(H27) -> 65 | J27: =_xlfn.XLOOKUP(I27,Sheet2!$A:$A,Sheet2!$D:$D) -> Overgrow | L27: 09 | M27: =HEX2DEC(L27) -> 9 | N27: =_xlfn.XLOOKUP(M27,Sheet2!$A:$A,Sheet2!$D:$D) -> Static | P27: 68 | Q27: =HEX2DEC(P27) -> 104 | R27: =_xlfn.XLOOKUP(Q27,Sheet2!$A:$A,Sheet2!$D:$D) -> Mold Breaker | V27: =LEFT(RIGHT($W$2,$X$2-2*(ROW(V27)-3)),2) -> 09
A28: 25 | B28: =DEC2HEX(A28) -> 19 | C28: Ability 2 | D28: 14 | E28: =HEX2DEC(D28) -> 20 | F28: =_xlfn.XLOOKUP(E28,Sheet2!$A:$A,Sheet2!$D:$D) -> Own Tempo | H28: A6 | I28: =HEX2DEC(H28) -> 166 | J28: =_xlfn.XLOOKUP(I28,Sheet2!$A:$A,Sheet2!$D:$D) -> Flower Veil | L28: 09 | M28: =HEX2DEC(L28) -> 9 | N28: =_xlfn.XLOOKUP(M28,Sheet2!$A:$A,Sheet2!$D:$D) -> Static | P28: 68 | Q28: =HEX2DEC(P28) -> 104 | R28: =_xlfn.XLOOKUP(Q28,Sheet2!$A:$A,Sheet2!$D:$D) -> Mold Breaker | V28: =LEFT(RIGHT($W$2,$X$2-2*(ROW(V28)-3)),2) -> 09
A29: 26 | B29: =DEC2HEX(A29) -> 1A | C29: Ability 3 | D29: 90 | E29: =HEX2DEC(D29) -> 144 | F29: =_xlfn.XLOOKUP(E29,Sheet2!$A:$A,Sheet2!$D:$D) -> Regenerator | H29: 22 | I29: =HEX2DEC(H29) -> 34 | J29: =_xlfn.XLOOKUP(I29,Sheet2!$A:$A,Sheet2!$D:$D) -> Chlorophyll | L29: 39 | M29: =HEX2DEC(L29) -> 57 | N29: =_xlfn.XLOOKUP(M29,Sheet2!$A:$A,Sheet2!$D:$D) -> Plus | P29: 68 | Q29: =HEX2DEC(P29) -> 104 | R29: =_xlfn.XLOOKUP(Q29,Sheet2!$A:$A,Sheet2!$D:$D) -> Mold Breaker | V29: =LEFT(RIGHT($W$2,$X$2-2*(ROW(V29)-3)),2) -> 39
A30: 27 | B30: =DEC2HEX(A30) -> 1B | C30: Flee Rate | D30: 00 | E30: =HEX2DEC(D30) -> 0 | H30: 00 | I30: =HEX2DEC(H30) -> 0 | L30: 00 | M30: =HEX2DEC(L30) -> 0 | P30: 00 | Q30: =HEX2DEC(P30) -> 0 | V30: =LEFT(RIGHT($W$2,$X$2-2*(ROW(V30)-3)),2) -> 00
A31: 28 | B31: =DEC2HEX(A31) -> 1C | C31: Forme pointer | D31: 79 | E31: =HEX2DEC(D31) -> 121 | F31: =E32*256+E31 -> 889 | H31: 00 | I31: =HEX2DEC(H31) -> 0 | J31: =I32*256+I31 -> 0 | L31: 4F | M31: =HEX2DEC(L31) -> 79 | N31: =M32*256+M31 -> 847 | P31: 4F | Q31: =HEX2DEC(P31) -> 79 | R31: =Q32*256+Q31 -> 847 | V31: =LEFT(RIGHT($W$2,$X$2-2*(ROW(V31)-3)),2) -> 4F
A32: 29 | B32: =DEC2HEX(A32) -> 1D | D32: 03 | E32: =HEX2DEC(D32) -> 3 | H32: 00 | I32: =HEX2DEC(H32) -> 0 | L32: 03 | M32: =HEX2DEC(L32) -> 3 | P32: 03 | Q32: =HEX2DEC(P32) -> 3 | V32: =LEFT(RIGHT($W$2,$X$2-2*(ROW(V32)-3)),2) -> 03
A33: 30 | B33: =DEC2HEX(A33) -> 1E | C33: Forme Sprite | D33: 00 | E33: =HEX2DEC(D33) -> 0 | F33: =E34*256+E33 -> 0 | H33: 00 | I33: =HEX2DEC(H33) -> 0 | J33: =I34*256+I33 -> 0 | L33: 00 | M33: =HEX2DEC(L33) -> 0 | N33: =M34*256+M33 -> 0 | P33: 00 | Q33: =HEX2DEC(P33) -> 0 | R33: =Q34*256+Q33 -> 0 | V33: =LEFT(RIGHT($W$2,$X$2-2*(ROW(V33)-3)),2) -> 00
A34: 31 | B34: =DEC2HEX(A34) -> 1F | D34: 00 | E34: =HEX2DEC(D34) -> 0 | H34: 00 | I34: =HEX2DEC(H34) -> 0 | L34: 00 | M34: =HEX2DEC(L34) -> 0 | P34: 00 | Q34: =HEX2DEC(P34) -> 0 | V34: =LEFT(RIGHT($W$2,$X$2-2*(ROW(V34)-3)),2) -> 00
A35: 32 | B35: =DEC2HEX(A35) -> 20 | C35: Forme Count | D35: 02 | E35: =HEX2DEC(D35) -> 2 | H35: 01 | I35: =HEX2DEC(H35) -> 1 | L35: 02 | M35: =HEX2DEC(L35) -> 2 | P35: 02 | Q35: =HEX2DEC(P35) -> 2 | V35: =LEFT(RIGHT($W$2,$X$2-2*(ROW(V35)-3)),2) -> 02
A36: 33 | B36: =DEC2HEX(A36) -> 21 | C36: Color | D36: 09 | E36: =HEX2DEC(D36) -> 9 | F36: =_xlfn.XLOOKUP(E36,Sheet2!$A:$A,Sheet2!$E:$E) -> Pink | H36: 03 | I36: =HEX2DEC(H36) -> 3 | J36: =_xlfn.XLOOKUP(I36,Sheet2!$A:$A,Sheet2!$E:$E) -> Green | L36: 02 | M36: =HEX2DEC(L36) -> 2 | N36: =_xlfn.XLOOKUP(M36,Sheet2!$A:$A,Sheet2!$E:$E) -> Yellow | P36: 02 | Q36: =HEX2DEC(P36) -> 2 | R36: =_xlfn.XLOOKUP(Q36,Sheet2!$A:$A,Sheet2!$E:$E) -> Yellow | V36: =LEFT(RIGHT($W$2,$X$2-2*(ROW(V36)-3)),2) -> 02
A37: 34 | B37: =DEC2HEX(A37) -> 22 | C37: Base Exp. | D37: 8A | E37: =HEX2DEC(D37) -> 138 | F37: =E38*256+E37 -> 138 | H37: 33 | I37: =HEX2DEC(H37) -> 51 | J37: =I38*256+I37 -> 51 | L37: E6 | M37: =HEX2DEC(L37) -> 230 | N37: =M38*256+M37 -> 230 | P37: 13 | Q37: =HEX2DEC(P37) -> 19 | R37: =Q38*256+Q37 -> 275 | V37: =LEFT(RIGHT($W$2,$X$2-2*(ROW(V37)-3)),2) -> E6
A38: 35 | B38: =DEC2HEX(A38) -> 23 | D38: 00 | E38: =HEX2DEC(D38) -> 0 | H38: 00 | I38: =HEX2DEC(H38) -> 0 | L38: 00 | M38: =HEX2DEC(L38) -> 0 | P38: 01 | Q38: =HEX2DEC(P38) -> 1 | V38: =LEFT(RIGHT($W$2,$X$2-2*(ROW(V38)-3)),2) -> 00
A39: 36 | B39: =DEC2HEX(A39) -> 24 | C39: Height in decimeters | D39: B4 | E39: =HEX2DEC(D39) -> 180 | F39: =E40*256+E39 -> 180 | H39: 46 | I39: =HEX2DEC(H39) -> 70 | J39: =I40*256+I39 -> 70 | L39: 8C | M39: =HEX2DEC(L39) -> 140 | N39: =M40*256+M39 -> 140 | P39: 8C | Q39: =HEX2DEC(P39) -> 140 | R39: =Q40*256+Q39 -> 140 | V39: =LEFT(RIGHT($W$2,$X$2-2*(ROW(V39)-3)),2) -> 8C
A40: 37 | B40: =DEC2HEX(A40) -> 25 | D40: 00 | E40: =HEX2DEC(D40) -> 0 | H40: 00 | I40: =HEX2DEC(H40) -> 0 | L40: 00 | M40: =HEX2DEC(L40) -> 0 | P40: 00 | Q40: =HEX2DEC(P40) -> 0 | V40: =LEFT(RIGHT($W$2,$X$2-2*(ROW(V40)-3)),2) -> 00
A41: 38 | B41: =DEC2HEX(A41) -> 26 | C41: Mass in decigrams | D41: 1B | E41: =HEX2DEC(D41) -> 27 | F41: =E42*256+E41 -> 795 | H41: 45 | I41: =HEX2DEC(H41) -> 69 | J41: =I42*256+I41 -> 69 | L41: 67 | M41: =HEX2DEC(L41) -> 103 | N41: =M42*256+M41 -> 615 | P41: 67 | Q41: =HEX2DEC(P41) -> 103 | R41: =Q42*256+Q41 -> 615 | V41: =LEFT(RIGHT($W$2,$X$2-2*(ROW(V41)-3)),2) -> 67
...

Sheet Sheet2
A1: 0 | B1: Normal | E1: Red | G1: =_xlfn.CONCAT("'",B1,"'") -> 'Normal' | H1: =_xlfn.CONCAT("'",C1,"'") -> '' | J1: =_xlfn.CONCAT("'",E1,"'") -> 'Red'
A2: 1 | B2: Fighting | C2: Monster | D2: Stench | E2: Blue | G2: =_xlfn.CONCAT("'",B2,"'") -> 'Fighting' | H2: =_xlfn.CONCAT("'",C2,"'") -> 'Monster' | J2: =_xlfn.CONCAT("'",E2,"'") -> 'Blue'
A3: 2 | B3: Flying | C3: Water 1 (Amphibious) | D3: Drizzle | E3: Yellow | G3: =_xlfn.CONCAT("'",B3,"'") -> 'Flying' | H3: =_xlfn.CONCAT("'",C3,"'") -> 'Water 1 (Amphibious)' | J3: =_xlfn.CONCAT("'",E3,"'") -> 'Yellow'
A4: 3 | B4: Poison | C4: Bug | D4: Speed Boost | E4: Green | G4: =_xlfn.CONCAT("'",B4,"'") -> 'Poison' | H4: =_xlfn.CONCAT("'",C4,"'") -> 'Bug' | J4: =_xlfn.CONCAT("'",E4,"'") -> 'Green'
A5: 4 | B5: Ground | C5: Flying | D5: Battle Armor | E5: Black | G5: =_xlfn.CONCAT("'",B5,"'") -> 'Ground' | H5: =_xlfn.CONCAT("'",C5,"'") -> 'Flying' | J5: =_xlfn.CONCAT("'",E5,"'") -> 'Black'
A6: 5 | B6: Rock | C6: Field | D6: Sturdy | E6: Brown | G6: =_xlfn.CONCAT("'",B6,"'") -> 'Rock' | H6: =_xlfn.CONCAT("'",C6,"'") -> 'Field' | J6: =_xlfn.CONCAT("'",E6,"'") -> 'Brown'
A7: 6 | B7: Bug | C7: Fairy | D7: Damp | E7: Purple | G7: =_xlfn.CONCAT("'",B7,"'") -> 'Bug' | H7: =_xlfn.CONCAT("'",C7,"'") -> 'Fairy' | J7: =_xlfn.CONCAT("'",E7,"'") -> 'Purple'
A8: 7 | B8: Ghost | C8: Grass | D8: Limber | E8: Gray | G8: =_xlfn.CONCAT("'",B8,"'") -> 'Ghost' | H8: =_xlfn.CONCAT("'",C8,"'") -> 'Grass' | J8: =_xlfn.CONCAT("'",E8,"'") -> 'Gray'
A9: 8 | B9: Steel | C9: Humanoid | D9: Sand Veil | E9: White | G9: =_xlfn.CONCAT("'",B9,"'") -> 'Steel' | H9: =_xlfn.CONCAT("'",C9,"'") -> 'Humanoid' | J9: =_xlfn.CONCAT("'",E9,"'") -> 'White'
A10: 9 | B10: Fire | C10: Water 3 (Aquatic Invertebrate) | D10: Static | E10: Pink | G10: =_xlfn.CONCAT("'",B10,"'") -> 'Fire' | H10: =_xlfn.CONCAT("'",C10,"'") -> 'Water 3 (Aquatic Invertebrate)' | J10: =_xlfn.CONCAT("'",E10,"'") -> 'Pink'
A11: 10 | B11: Water | C11: Mineral | D11: Volt Absorb | G11: =_xlfn.CONCAT("'",B11,"'") -> 'Water' | H11: =_xlfn.CONCAT("'",C11,"'") -> 'Mineral' | J11: =_xlfn.CONCAT("'",E11,"'") -> ''
A12: 11 | B12: Grass | C12: Amorphous | D12: Water Absorb | G12: =_xlfn.CONCAT("'",B12,"'") -> 'Grass' | H12: =_xlfn.CONCAT("'",C12,"'") -> 'Amorphous' | J12: =_xlfn.CONCAT("'",E12,"'") -> ''
A13: 12 | B13: Electric | C13: Water 2 (Piscine) | D13: Oblivious | G13: =_xlfn.CONCAT("'",B13,"'") -> 'Electric' | H13: =_xlfn.CONCAT("'",C13,"'") -> 'Water 2 (Piscine)' | J13: =_xlfn.CONCAT("'",E13,"'") -> ''
A14: 13 | B14: Psychic | C14: Ditto | D14: Cloud Nine | G14: =_xlfn.CONCAT("'",B14,"'") -> 'Psychic' | H14: =_xlfn.CONCAT("'",C14,"'") -> 'Ditto' | J14: =_xlfn.CONCAT("'",E14,"'") -> ''
A15: 14 | B15: Ice | C15: Dragon | D15: Compound Eyes | G15: =_xlfn.CONCAT("'",B15,"'") -> 'Ice' | H15: =_xlfn.CONCAT("'",C15,"'") -> 'Dragon' | J15: =_xlfn.CONCAT("'",E15,"'") -> ''
A16: 15 | B16: Dragon | C16: Undiscovered | D16: Insomnia | G16: =_xlfn.CONCAT("'",B16,"'") -> 'Dragon' | H16: =_xlfn.CONCAT("'",C16,"'") -> 'Undiscovered' | J16: =_xlfn.CONCAT("'",E16,"'") -> ''
A17: 16 | B17: Dark | D17: Color Change | G17: =_xlfn.CONCAT("'",B17,"'") -> 'Dark' | H17: =_xlfn.CONCAT("'",C17,"'") -> '' | J17: =_xlfn.CONCAT("'",E17,"'") -> ''
A18: 17 | B18: Fairy | D18: Immunity | G18: =_xlfn.CONCAT("'",B18,"'") -> 'Fairy' | H18: =_xlfn.CONCAT("'",C18,"'") -> '' | J18: =_xlfn.CONCAT("'",E18,"'") -> ''
A19: 18 | D19: Flash Fire | G19: =_xlfn.TEXTJOIN(",",TRUE,G1:G18) -> 'Normal','Fighting','Flying','Poison','Ground','Rock','Bug','Ghost','Steel','Fire','Water','Grass','Electric','Psychic','Ice','Dragon','Dark','Fairy' | H19: =_xlfn.TEXTJOIN(",",TRUE,H1:H18) -> '','Monster','Water 1 (Amphibious)','Bug','Flying','Field','Fairy','Grass','Humanoid','Water 3 (Aquatic Invertebrate)','Mineral','Amorphous','Water 2 (Piscine)','Ditto','Dragon','Undiscovered','','' | I19: =_xlfn.TEXTJOIN(",",TRUE,I1:I18) | J19: =_xlfn.TEXTJOIN(",",TRUE,J1:J18) -> 'Red','Blue','Yellow','Green','Black','Brown','Purple','Gray','White','Pink','','','','','','','',''
A20: 19 | D20: Shield Dust
A21: 20 | D21: Own Tempo
A22: 21 | D22: Suction Cups
A23: 22 | D23: Intimidate
A24: 23 | D24: Shadow Tag
A25: 24 | D25: Rough Skin
A26: 25 | D26: Wonder Guard
A27: 26 | D27: Levitate
A28: 27 | D28: Effect Spore
A29: 28 | D29: Synchronize
A30: 29 | D30: Clear Body
A31: 30 | D31: Natural Cure
... A35: 34 | D35: Chlorophyll
A36: 35 | D36: Illuminate | H36: 520
A37: 36 | D37: Trace | H37: 519
A38: 37 | D38: Huge Power | H38: 518
A39: 38 | D39: Poison Point | H39: 338
A40: 39 | D40: Inner Focus | H40: 307
A41: 40 | D41: Magma Armor | H41: 308
A42: 41 | D42: Water Veil | H42: 434
A43: 42 | D43: Magnet Pull | H43: 620 | I43: =_xlfn.TEXTJOIN(", ",TRUE,H36:H43) -> 520, 519, 518, 338, 307, 308, 434, 620
...
