Workbook

Sheet Edited code.bin and bag.cro
A1: Address | B1: Hex | C1: instruction | D1: notes
A2: code.bin
A3: 00325ACC | B3: 1E350FEB | C3: =_xlfn.CONCAT("bl 0x",DEC2HEX(HEX2DEC(A9)+HEX2DEC("6DD000"),8)) -> bl 0x006F2F4C | D3: returns 0 if new level == old level or new level >100
A4: =DEC2HEX(HEX2DEC(A3)+4,8) -> 00325AD0 | B4: 000050E3 | C4: cmp r0, 0x0
A5: =DEC2HEX(HEX2DEC(A4)+4,8) -> 00325AD4 | B5: 1F00000A | C5: beq 0x325B58
A6: =DEC2HEX(HEX2DEC(A5)+4,8) -> 00325AD8 | B6: 00F020E3 | C6: nop
A8: Level cap function
A9: 00015F4C | B9: 640055E3 | C9: cmp r5, 0x64 | D9: check if new level is >100
A10: =DEC2HEX(HEX2DEC(A9)+4,8) -> 00015F50 | B10: 6450A083 | C10: movhi r5, 0x64 | D10: if so set 100 instead
A11: =DEC2HEX(HEX2DEC(A10)+4,8) -> 00015F54 | B11: 000055E1 | C11: cmp r5, r0 | D11: if new level == old level
A12: =DEC2HEX(HEX2DEC(A11)+4,8) -> 00015F58 | B12: 70402DE9 | C12: push {r4, r5, r6, lr}
A13: =DEC2HEX(HEX2DEC(A12)+4,8) -> 00015F5C | B13: 1900000A | C13: =_xlfn.CONCAT("beq 0x",A40) -> beq 0x00015FC8 | D13: return false
A14: =DEC2HEX(HEX2DEC(A13)+4,8) -> 00015F60 | B14: 0500A0E1 | C14: mov r0, r5 | D14: set r0 to new level
A15: =DEC2HEX(HEX2DEC(A14)+4,8) -> 00015F64 | B15: 64409FE5 | C15: =_xlfn.CONCAT("ldr r4, [pc, #",HEX2DEC(A$42)-HEX2DEC(A15)-8,"]") -> ldr r4, [pc, #100] | D15: Load pointer to flag
A16: =DEC2HEX(HEX2DEC(A15)+4,8) -> 00015F68 | B16: B210D4E1 | C16: ldrh r1, [r4, 0x2]
A17: =DEC2HEX(HEX2DEC(A16)+4,8) -> 00015F6C | B17: DE0051E3 | C17: =_xlfn.CONCAT("cmp r1, 0x",DEC2HEX(MAX(Data!E:E))) -> cmp r1, 0xDE | D17: this pulls the max flag from the table
A18: =DEC2HEX(HEX2DEC(A17)+4,8) -> 00015F70 | B18: 0700002A | C18: =_xlfn.CONCAT("bhs 0x",A$27) -> bhs 0x00015F94 | D18: if we are >= that, level cap is max, don't bother checking
A19: =DEC2HEX(HEX2DEC(A18)+4,8) -> 00015F74 | B19: 5C408FE2 | C19: =_xlfn.CONCAT("add r4, pc, 0x",DEC2HEX(HEX2DEC(A44)-HEX2DEC(A19)-8)) -> add r4, pc, 0x5C | D19: r4 points to table
A20: =DEC2HEX(HEX2DEC(A19)+4,8) -> 00015F78 | B20: B060D4E1 | C20: ldrh r6, [r4] | D20: load next important NPC battle count entry
A21: =DEC2HEX(HEX2DEC(A20)+4,8) -> 00015F7C | B21: 060051E1 | C21: cmp r1, r6 | D21: compare current value to value in table
A22: =DEC2HEX(HEX2DEC(A21)+4,8) -> 00015F80 | B22: 03408422 | C22: addhs r4, r4, 0x3 | D22: add 3 to iterator
A23: =DEC2HEX(HEX2DEC(A22)+4,8) -> 00015F84 | B23: FBFFFF2A | C23: =_xlfn.CONCAT("bhs 0x",A20) -> bhs 0x00015F78 | D23: next loop
A24: =DEC2HEX(HEX2DEC(A23)+4,8) -> 00015F88 | B24: 0250D4E5 | C24: ldrb r5, [r4, 0x2] | D24: load level
A25: =DEC2HEX(HEX2DEC(A24)+4,8) -> 00015F8C | B25: 050050E1 | C25: cmp r0, r5 | D25: compare current level to level cap
A26: =DEC2HEX(HEX2DEC(A25)+4,8) -> 00015F90 | B26: 0100008A | C26: =_xlfn.CONCAT("bhi 0x",A$29) -> bhi 0x00015F9C | D26: if level > level cap, return false
A27: =DEC2HEX(HEX2DEC(A26)+4,8) -> 00015F94 | B27: 0100A0E3 | C27: mov r0, 0x1 | D27: otherwise return true
A28: =DEC2HEX(HEX2DEC(A27)+4,8) -> 00015F98 | B28: 7080BDE8 | C28: =SUBSTITUTE(SUBSTITUTE(C12,"push","pop"),"lr","pc") -> pop {r4, r5, r6, pc}
A29: =DEC2HEX(HEX2DEC(A28)+4,8) -> 00015F9C | B29: 30409FE5 | C29: =_xlfn.CONCAT("ldr r4, [pc, #",HEX2DEC(A$43)-HEX2DEC(A29)-8,"]") -> ldr r4, [pc, #48] | D29: get pointer to game storage of fly and other flags
A30: =DEC2HEX(HEX2DEC(A29)+4,8) -> 00015FA0 | B30: 72508FE2 | C30: =_xlfn.CONCAT("add r5, pc, 0x",DEC2HEX(HEX2DEC(A66)-HEX2DEC(A30)-8)) -> add r5, pc, 0x72 | D30: get pointer to cap table
A31: =DEC2HEX(HEX2DEC(A30)+4,8) -> 00015FA4 | B31: 0010D5E5 | C31: ldrb r1, [r5, 0x0] | D31: offset from base
A32: =DEC2HEX(HEX2DEC(A31)+4,8) -> 00015FA8 | B32: 0110D4E7 | C32: ldrb r1, [r4, r1] | D32: get byte with bitflags
A33: =DEC2HEX(HEX2DEC(A32)+4,8) -> 00015FAC | B33: 0160D5E5 | C33: ldrb r6, [r5, 0x1] | D33: get the bit for this flag
A34: =DEC2HEX(HEX2DEC(A33)+4,8) -> 00015FB0 | B34: 061011E0 | C34: ands r1, r1, r6 | D34: bitand the bitflag's bit and the loaded byte, and set CPSR
A35: =DEC2HEX(HEX2DEC(A34)+4,8) -> 00015FB4 | B35: 03508512 | C35: addne r5, r5, 0x3 | D35: NE, passed this, add 3 and do next
A36: =DEC2HEX(HEX2DEC(A35)+4,8) -> 00015FB8 | B36: F9FFFF1A | C36: =_xlfn.CONCAT("bne 0x",A31) -> bne 0x00015FA4
A37: =DEC2HEX(HEX2DEC(A36)+4,8) -> 00015FBC | B37: 0260D5E5 | C37: ldrb r6, [r5, 0x2] | D37: if equal (0, not set), use this entry as cap (first not arrived)
A38: =DEC2HEX(HEX2DEC(A37)+4,8) -> 00015FC0 | B38: 060050E1 | C38: cmp r0, r6 | D38: compare current level to level cap
A39: =DEC2HEX(HEX2DEC(A38)+4,8) -> 00015FC4 | B39: F2FFFF9A | C39: =_xlfn.CONCAT("bls 0x",A27) -> bls 0x00015F94 | D39: level <= level cap, return true
A40: =DEC2HEX(HEX2DEC(A39)+4,8) -> 00015FC8 | B40: 0000A0E3 | C40: mov r0, 0x0
A41: =DEC2HEX(HEX2DEC(A40)+4,8) -> 00015FCC | B41: 7080BDE8 | C41: =C28 -> pop {r4, r5, r6, pc}
...

Sheet Edited battle.cro
A1: Address | B1: Hex | C1: instruction | D1: notes
A2: Section in exp calc function
A3: 00015AD4 | B3: EDB703EB | C3: =_xlfn.CONCAT("bl 0x",A8) -> bl 0x00103A90 | D3: branch to level cap check function
A4: =DEC2HEX(HEX2DEC(A3)+4,8) -> 00015AD8 | B4: 010050E3 | C4: cmp r0, 0x1 | D4: will be 0 if at level cap or level >= 100
A5: =DEC2HEX(HEX2DEC(A4)+4,8) -> 00015ADC | B5: 0400001A | C5: bne 0x00015AF4
A7: Level cap function
A8: 00103A90 | B8: 70402DE9 | C8: push {r4, r5, r6, lr}
A9: =DEC2HEX(HEX2DEC(A8)+4,8) -> 00103A94 | B9: 640050E3 | C9: cmp r0, 0x64 | D9: check if Pokemon is level 100, if it is, just return false
A10: =DEC2HEX(HEX2DEC(A9)+4,8) -> 00103A98 | B10: 1A0000AA | C10: =_xlfn.CONCAT("bge 0x",A38) -> bge 0x00103B08
A11: =DEC2HEX(HEX2DEC(A10)+4,8) -> 00103A9C | B11: 68409FE5 | C11: =_xlfn.CONCAT("ldr r4, [pc, #",HEX2DEC(A$39)-HEX2DEC(A11)-8,"]") -> ldr r4, [pc, #104] | D11: Load pointer to flag
A12: =DEC2HEX(HEX2DEC(A11)+4,8) -> 00103AA0 | B12: B210D4E1 | C12: ldrh r1, [r4, 0x2] | D12: A8
A13: =DEC2HEX(HEX2DEC(A12)+4,8) -> 00103AA4 | B13: DE0051E3 | C13: =_xlfn.CONCAT("cmp r1, 0x",DEC2HEX(MAX(Data!E:E))) -> cmp r1, 0xDE | D13: this pulls the max flag from the table
A14: =DEC2HEX(HEX2DEC(A13)+4,8) -> 00103AA8 | B14: 0800002A | C14: =_xlfn.CONCAT("bhs 0x",A$24) -> bhs 0x00103AD0 | D14: if we are >= that, level cap is max, don't bother checking
A15: =DEC2HEX(HEX2DEC(A14)+4,8) -> 00103AAC | B15: 60409FE5 | C15: =_xlfn.CONCAT("ldr r4, [pc, #",HEX2DEC(A$41)-HEX2DEC(A15)-8,"]") -> ldr r4, [pc, #96] | D15: get pointer to table of level caps and flags
A16: =DEC2HEX(HEX2DEC(A15)+4,8) -> 00103AB0 | B16: B060D4E1 | C16: ldrh r6, [r4] | D16: load next important NPC battle count entry
A17: =DEC2HEX(HEX2DEC(A16)+4,8) -> 00103AB4 | B17: 060051E1 | C17: cmp r1, r6 | D17: compare current value to value in table
A18: =DEC2HEX(HEX2DEC(A17)+4,8) -> 00103AB8 | B18: 0100003A | C18: =_xlfn.CONCAT("blo 0x",A$21) -> blo 0x00103AC4 | D18: if current value is smaller, then that is our level cap
A19: =DEC2HEX(HEX2DEC(A18)+4,8) -> 00103ABC | B19: 034084E2 | C19: add r4, r4, 0x3 | D19: add 3 to iterator
A20: =DEC2HEX(HEX2DEC(A19)+4,8) -> 00103AC0 | B20: FAFFFFEA | C20: =_xlfn.CONCAT("b 0x",A16) -> b 0x00103AB0 | D20: next loop
A21: =DEC2HEX(HEX2DEC(A20)+4,8) -> 00103AC4 | B21: 0250D4E5 | C21: ldrb r5, [r4, 0x2]
A22: =DEC2HEX(HEX2DEC(A21)+4,8) -> 00103AC8 | B22: 050050E1 | C22: cmp r0, r5 | D22: compare current level to level cap
A23: =DEC2HEX(HEX2DEC(A22)+4,8) -> 00103ACC | B23: 0100002A | C23: =_xlfn.CONCAT("bhs 0x",A$26) -> bhs 0x00103AD8 | D23: if level >= level cap, double check using other flags
A24: =DEC2HEX(HEX2DEC(A23)+4,8) -> 00103AD0 | B24: 0100A0E3 | C24: mov r0, 0x1 | D24: otherwise return true
A25: =DEC2HEX(HEX2DEC(A24)+4,8) -> 00103AD4 | B25: 7080BDE8 | C25: =SUBSTITUTE(SUBSTITUTE(C8,"push","pop"),"lr","pc") -> pop {r4, r5, r6, pc}
A26: =DEC2HEX(HEX2DEC(A25)+4,8) -> 00103AD8 | B26: 30409FE5 | C26: =_xlfn.CONCAT("ldr r4, [pc, #",HEX2DEC(A$40)-HEX2DEC(A26)-8,"]") -> ldr r4, [pc, #48] | D26: get pointer to game storage of fly and other flags
A27: =DEC2HEX(HEX2DEC(A26)+4,8) -> 00103ADC | B27: 34509FE5 | C27: =_xlfn.CONCAT("ldr r5, [pc, #",HEX2DEC(A$42)-HEX2DEC(A27)-8,"]") -> ldr r5, [pc, #52] | D27: get pointer to cap table
A28: =DEC2HEX(HEX2DEC(A27)+4,8) -> 00103AE0 | B28: 0010D5E5 | C28: ldrb r1, [r5, 0x0] | D28: offset from base
A29: =DEC2HEX(HEX2DEC(A28)+4,8) -> 00103AE4 | B29: 0110D4E7 | C29: ldrb r1, [r4, r1] | D29: get byte with bitflags
A30: =DEC2HEX(HEX2DEC(A29)+4,8) -> 00103AE8 | B30: 0160D5E5 | C30: ldrb r6, [r5, 0x1] | D30: get the bit for this flag
A31: =DEC2HEX(HEX2DEC(A30)+4,8) -> 00103AEC | B31: 061011E0 | C31: ands r1, r1, r6 | D31: bitand the bitflag's bit and the loaded byte, and set CPSR
A32: =DEC2HEX(HEX2DEC(A31)+4,8) -> 00103AF0 | B32: 03508512 | C32: addne r5, r5, 0x3 | D32: NE, passed this, add 3 and do next
A33: =DEC2HEX(HEX2DEC(A32)+4,8) -> 00103AF4 | B33: F9FFFF1A | C33: =_xlfn.CONCAT("bne 0x",A28) -> bne 0x00103AE0 | I33: addne r5, r5, 0x3 | J33: if NE, then the bitflag is set, and this level cap is surpassed
A34: =DEC2HEX(HEX2DEC(A33)+4,8) -> 00103AF8 | B34: 0260D5E5 | C34: ldrb r6, [r5, 0x2] | D34: if equal (0, not set), use this entry as cap (first not arrived)
A35: =DEC2HEX(HEX2DEC(A34)+4,8) -> 00103AFC | B35: 060050E1 | C35: cmp r0, r6 | D35: compare current level to level cap
A36: =DEC2HEX(HEX2DEC(A35)+4,8) -> 00103B00 | B36: F2FFFF3A | C36: =_xlfn.CONCAT("blo 0x",A24) -> blo 0x00103AD0 | D36: level < level cap, return true
A37: =DEC2HEX(HEX2DEC(A36)+4,8) -> 00103B04 | B37: 0000A0E3 | C37: mov r0, 0x0 | D37: return false | I37: if equal (0, not set), we're not up to this part of the game
A38: =DEC2HEX(HEX2DEC(A37)+4,8) -> 00103B08 | B38: 7080BDE8 | C38: =C25 -> pop {r4, r5, r6, pc} | I38: And the last one passed, so the cap here is the cap
A39: =DEC2HEX(HEX2DEC(A38)+4,8) -> 00103B0C | B39: A82F0133 | D39: Pointer to flag
A40: =DEC2HEX(HEX2DEC(A39)+4,8) -> 00103B10 | B40: D0380133
A41: =DEC2HEX(HEX2DEC(A40)+4,8) -> 00103B14 | B41: 00000000 | D41: Table of battle count caps
...

Sheet Table Builder
A1: Trainer/Event | B1: Level Cap | D1: Flag | E1: Level Cap | F1: Offset | G1: Bit
A2: Trainer School | B2: 15 | D2: Fly - Route 1 | E2: 15 | F2: =IF(D2<>"",DEC2HEX(_xlfn.XLOOKUP(D2,Data!M:M,Data!P:P),2),"") -> 11 | G2: =IF(D2<>"",DEC2HEX(_xlfn.XLOOKUP(D2,Data!M:M,Data!O:O),2),"") -> 01 | I2: =IF(D2<>"",_xlfn.CONCAT(F2,G2,DEC2HEX(E2,2)),"") -> 11010F
A3: Captain Ilima | B3: 17 | D3: Fly - Hau'oli City | E3: 17 | F3: =IF(D3<>"",DEC2HEX(_xlfn.XLOOKUP(D3,Data!M:M,Data!P:P),2),"") -> 11 | G3: =IF(D3<>"",DEC2HEX(_xlfn.XLOOKUP(D3,Data!M:M,Data!O:O),2),"") -> 02 | I3: =IF(D3<>"",_xlfn.CONCAT(F3,G3,DEC2HEX(E3,2)),"") -> 110211
A4: Totem Gumshoos | B4: 20 | D4: Fly - Verdant Cave | E4: 20 | F4: =IF(D4<>"",DEC2HEX(_xlfn.XLOOKUP(D4,Data!M:M,Data!P:P),2),"") -> 11 | G4: =IF(D4<>"",DEC2HEX(_xlfn.XLOOKUP(D4,Data!M:M,Data!O:O),2),"") -> 80 | I4: =IF(D4<>"",_xlfn.CONCAT(F4,G4,DEC2HEX(E4,2)),"") -> 118014
A5: Kahuna Hala | B5: 27 | D5: Fly - Melemele Meadow | E5: 27 | F5: =IF(D5<>"",DEC2HEX(_xlfn.XLOOKUP(D5,Data!M:M,Data!P:P),2),"") -> 11 | G5: =IF(D5<>"",DEC2HEX(_xlfn.XLOOKUP(D5,Data!M:M,Data!O:O),2),"") -> 40 | I5: =IF(D5<>"",_xlfn.CONCAT(F5,G5,DEC2HEX(E5,2)),"") -> 11401B
A6: Dexio/Sina Battle | B6: 29 | D6: Fly - Heahea City | E6: 29 | F6: =IF(D6<>"",DEC2HEX(_xlfn.XLOOKUP(D6,Data!M:M,Data!P:P),2),"") -> 12 | G6: =IF(D6<>"",DEC2HEX(_xlfn.XLOOKUP(D6,Data!M:M,Data!O:O),2),"") -> 04 | I6: =IF(D6<>"",_xlfn.CONCAT(F6,G6,DEC2HEX(E6,2)),"") -> 12041D
A7: Hau, Paniola Town | B7: 32 | D7: Fly - Paniola Town | E7: 32 | F7: =IF(D7<>"",DEC2HEX(_xlfn.XLOOKUP(D7,Data!M:M,Data!P:P),2),"") -> 12 | G7: =IF(D7<>"",DEC2HEX(_xlfn.XLOOKUP(D7,Data!M:M,Data!O:O),2),"") -> 40 | I7: =IF(D7<>"",_xlfn.CONCAT(F7,G7,DEC2HEX(E7,2)),"") -> 124020
A8: Gladion | B8: 37 | D8: Fly - Route 5/Brooklet Hill | E8: 37 | F8: =IF(D8<>"",DEC2HEX(_xlfn.XLOOKUP(D8,Data!M:M,Data!P:P),2),"") -> 13 | G8: =IF(D8<>"",DEC2HEX(_xlfn.XLOOKUP(D8,Data!M:M,Data!O:O),2),"") -> 02 | I8: =IF(D8<>"",_xlfn.CONCAT(F8,G8,DEC2HEX(E8,2)),"") -> 130225
A9: Totem Araquanid | B9: 40 | D9: Lapras Surf | E9: 40 | F9: =IF(D9<>"",DEC2HEX(_xlfn.XLOOKUP(D9,Data!M:M,Data!P:P),2),"") -> 01 | G9: =IF(D9<>"",DEC2HEX(_xlfn.XLOOKUP(D9,Data!M:M,Data!O:O),2),"") -> 40 | I9: =IF(D9<>"",_xlfn.CONCAT(F9,G9,DEC2HEX(E9,2)),"") -> 014028
A10: Royal Avenue | B10: 45 | D10: Fly - Royal Avenue | E10: 45 | F10: =IF(D10<>"",DEC2HEX(_xlfn.XLOOKUP(D10,Data!M:M,Data!P:P),2),"") -> 12 | G10: =IF(D10<>"",DEC2HEX(_xlfn.XLOOKUP(D10,Data!M:M,Data!O:O),2),"") -> 08 | I10: =IF(D10<>"",_xlfn.CONCAT(F10,G10,DEC2HEX(E10,2)),"") -> 12082D
A11: Totem Marowak | B11: 50 | D11: Fly - Route 7/Wela Volcano Park | E11: 50 | F11: =IF(D11<>"",DEC2HEX(_xlfn.XLOOKUP(D11,Data!M:M,Data!P:P),2),"") -> 13 | G11: =IF(D11<>"",DEC2HEX(_xlfn.XLOOKUP(D11,Data!M:M,Data!O:O),2),"") -> 08 | I11: =IF(D11<>"",_xlfn.CONCAT(F11,G11,DEC2HEX(E11,2)),"") -> 130832
A12: Totem Lurantis | B12: 55 | D12: Fly - Route 8 | E12: 55 | F12: =IF(D12<>"",DEC2HEX(_xlfn.XLOOKUP(D12,Data!M:M,Data!P:P),2),"") -> 12 | G12: =IF(D12<>"",DEC2HEX(_xlfn.XLOOKUP(D12,Data!M:M,Data!O:O),2),"") -> 10 | I12: =IF(D12<>"",_xlfn.CONCAT(F12,G12,DEC2HEX(E12,2)),"") -> 121037
A13: Konikoni City | D13: Fly - Konikoni City | E13: 60 | F13: =IF(D13<>"",DEC2HEX(_xlfn.XLOOKUP(D13,Data!M:M,Data!P:P),2),"") -> 12 | G13: =IF(D13<>"",DEC2HEX(_xlfn.XLOOKUP(D13,Data!M:M,Data!O:O),2),"") -> 20 | I13: =IF(D13<>"",_xlfn.CONCAT(F13,G13,DEC2HEX(E13,2)),"") -> 12203C
A14: Kahuna Olivia | B14: 63 | D14: Fly - Ruins of Life | E14: 63 | F14: =IF(D14<>"",DEC2HEX(_xlfn.XLOOKUP(D14,Data!M:M,Data!P:P),2),"") -> 13 | G14: =IF(D14<>"",DEC2HEX(_xlfn.XLOOKUP(D14,Data!M:M,Data!O:O),2),"") -> 10 | I14: =IF(D14<>"",_xlfn.CONCAT(F14,G14,DEC2HEX(E14,2)),"") -> 13103F
A15: Malie City Hau Battle | B15: 65 | D15: Fly - Malie City | E15: 65 | F15: =IF(D15<>"",DEC2HEX(_xlfn.XLOOKUP(D15,Data!M:M,Data!P:P),2),"") -> 13 | G15: =IF(D15<>"",DEC2HEX(_xlfn.XLOOKUP(D15,Data!M:M,Data!O:O),2),"") -> 40 | I15: =IF(D15<>"",_xlfn.CONCAT(F15,G15,DEC2HEX(E15,2)),"") -> 134041
A16: Totem Togedemaru | B16: 72 | D16: Fly - Mount Hokulani | E16: 72 | F16: =IF(D16<>"",DEC2HEX(_xlfn.XLOOKUP(D16,Data!M:M,Data!P:P),2),"") -> 14 | G16: =IF(D16<>"",DEC2HEX(_xlfn.XLOOKUP(D16,Data!M:M,Data!O:O),2),"") -> 04 | I16: =IF(D16<>"",_xlfn.CONCAT(F16,G16,DEC2HEX(E16,2)),"") -> 140448
A17: Ula'Ula Beach | B17: 75 | D17: Mudsdale Ride | E17: 75 | F17: =IF(D17<>"",DEC2HEX(_xlfn.XLOOKUP(D17,Data!M:M,Data!P:P),2),"") -> 01 | G17: =IF(D17<>"",DEC2HEX(_xlfn.XLOOKUP(D17,Data!M:M,Data!O:O),2),"") -> 20 | I17: =IF(D17<>"",_xlfn.CONCAT(F17,G17,DEC2HEX(E17,2)),"") -> 01204B
A18: Totem Mimikyu | B18: 80 | D18: Fly - Tapu Village | E18: 80 | F18: =IF(D18<>"",DEC2HEX(_xlfn.XLOOKUP(D18,Data!M:M,Data!P:P),2),"") -> 14 | G18: =IF(D18<>"",DEC2HEX(_xlfn.XLOOKUP(D18,Data!M:M,Data!O:O),2),"") -> 01 | I18: =IF(D18<>"",_xlfn.CONCAT(F18,G18,DEC2HEX(E18,2)),"") -> 140150
A19: Po Town | B19: 85 | D19: Fly - Po Town | E19: 85 | F19: =IF(D19<>"",DEC2HEX(_xlfn.XLOOKUP(D19,Data!M:M,Data!P:P),2),"") -> 2D | G19: =IF(D19<>"",DEC2HEX(_xlfn.XLOOKUP(D19,Data!M:M,Data!O:O),2),"") -> 40 | I19: =IF(D19<>"",_xlfn.CONCAT(F19,G19,DEC2HEX(E19,2)),"") -> 2D4055
A20: Aether Branch Chief Faba | B20: 90 | D20: Fly - Aether Paradise | E20: 90 | F20: =IF(D20<>"",DEC2HEX(_xlfn.XLOOKUP(D20,Data!M:M,Data!P:P),2),"") -> 15 | G20: =IF(D20<>"",DEC2HEX(_xlfn.XLOOKUP(D20,Data!M:M,Data!O:O),2),"") -> 08 | I20: =IF(D20<>"",_xlfn.CONCAT(F20,G20,DEC2HEX(E20,2)),"") -> 15085A
A21: Arrive Seafolk Village | B21: 95 | D21: Over the Gyarados | E21: 95 | F21: =IF(D21<>"",DEC2HEX(_xlfn.XLOOKUP(D21,Data!M:M,Data!P:P),2),"") -> 3C | G21: =IF(D21<>"",DEC2HEX(_xlfn.XLOOKUP(D21,Data!M:M,Data!O:O),2),"") -> 10 | I21: =IF(D21<>"",_xlfn.CONCAT(F21,G21,DEC2HEX(E21,2)),"") -> 3C105F
A22: Arrive Ponyi Canyon Altar | B22: 100 | D22: Fly - Altar of the Sunne | E22: 100 | F22: =IF(D22<>"",DEC2HEX(_xlfn.XLOOKUP(D22,Data!M:M,Data!P:P),2),"") -> 2E | G22: =IF(D22<>"",DEC2HEX(_xlfn.XLOOKUP(D22,Data!M:M,Data!O:O),2),"") -> 10 | I22: =IF(D22<>"",_xlfn.CONCAT(F22,G22,DEC2HEX(E22,2)),"") -> 2E1064
F23: =IF(D23<>"",DEC2HEX(_xlfn.XLOOKUP(D23,Data!M:M,Data!P:P),2),"") | G23: =IF(D23<>"",DEC2HEX(_xlfn.XLOOKUP(D23,Data!M:M,Data!O:O),2),"") | I23: =IF(D23<>"",_xlfn.CONCAT(F23,G23,DEC2HEX(E23,2)),"")
I24: =IF(D24<>"",_xlfn.CONCAT(F24,G24,DEC2HEX(E24,2)),"")
I25: =IF(D25<>"",_xlfn.CONCAT(F25,G25,DEC2HEX(E25,2)),"")

Sheet Data
A1: Trainer/Event | B1: Level Cap | C1: Associated Flag | E1: Dec | H1: # Battles approximate (hex) | I1: Where in game | M1: Flag | N1: Offset | O1: Bit | P1: From 330138D0 | R1: Variable | S1: Bytes | T1: Save Location | U1: Loaded Location | V1: 1 | W1: 2 | X1: 4 | Y1: 8 | Z1: 16 | AA1: 32 | AB1: 64 | AC1: 128
A2: Trainer School | B2: 15 | C2: 0900 | E2: =HEX2DEC(RIGHT(C2,2)&LEFT(C2,2)) -> 9 | F2: =C2&DEC2HEX(B2,2) -> 09000F | H2: 0000 | I2: Start | M2: Always 1? | N2: 330138D1 | O2: 1 | P2: =_xlfn.XLOOKUP(N2,U:U,AD:AD) -> 1 | R2: # Battles | S2: 2 | T2: 00001EA6 | U2: 33012FA8 | AD2: =HEX2DEC(U2)-HEX2DEC("330138D0") -> -2344
A3: Captain Ilima | B3: 17 | C3: 0C00 | E3: =HEX2DEC(RIGHT(C3,2)&LEFT(C3,2)) -> 12 | F3: =C3&DEC2HEX(B3,2) -> 0C0011 | H3: 0100 | I3: before first hau | M3: Ride Pager | N3: 330138D1 | O3: 2 | P3: =_xlfn.XLOOKUP(N3,U:U,AD:AD) -> 1 | R3: Ride Pokemon Byte 1 | S3: 1 | T3: 000027CD | U3: =DEC2HEX(855707908+HEX2DEC(T3),8) -> 330138D1 | V3: ? | W3: Ride Pager | X3: Tauros | Y3: Stoutland | Z3: Machamp | AA3: Mudsdale | AB3: Lapras | AC3: Sharpedo | AD3: =HEX2DEC(U3)-HEX2DEC("330138D0") -> 1
A4: Totem Gumshoos | B4: 20 | C4: 1500 | E4: =HEX2DEC(RIGHT(C4,2)&LEFT(C4,2)) -> 21 | F4: =C4&DEC2HEX(B4,2) -> 150014 | H4: 0500 | I4: after first Hau | M4: Tauros Charge | N4: 330138D1 | O4: 4 | P4: =_xlfn.XLOOKUP(N4,U:U,AD:AD) -> 1 | R4: Ride Pokemon Byte 2 | S4: 1 | T4: 000027CE | U4: =DEC2HEX(855707908+HEX2DEC(T4),8) -> 330138D2 | V4: Charizard | W4: ? | AD4: =HEX2DEC(U4)-HEX2DEC("330138D0") -> 2
A5: Kahuna Hala | B5: 27 | C5: 1900 | E5: =HEX2DEC(RIGHT(C5,2)&LEFT(C5,2)) -> 25 | F5: =C5&DEC2HEX(B5,2) -> 19001B | H5: 0900 | I5: partway through Trainer School | M5: Stoutland Search | N5: 330138D1 | O5: 8 | P5: =_xlfn.XLOOKUP(N5,U:U,AD:AD) -> 1 | R5: Flags 1 | S5: 1 | T5: 000027DC | U5: =DEC2HEX(855707908+HEX2DEC(T5),8) -> 330138E0 | AA5: Pokemon League | AB5: Ruins of Abundance | AC5: Paniola Ranch | AD5: =HEX2DEC(U5)-HEX2DEC("330138D0") -> 16
A6: Dexio/Sina Battle | B6: 29 | C6: 1D00 | E6: =HEX2DEC(RIGHT(C6,2)&LEFT(C6,2)) -> 29 | F6: =C6&DEC2HEX(B6,2) -> 1D001D | H6: 0C00 | I6: before ilima | M6: Machamp Shove | N6: 330138D1 | O6: 16 | P6: =_xlfn.XLOOKUP(N6,U:U,AD:AD) -> 1 | R6: Flags 2 | S6: 1 | T6: 000027DD | U6: =DEC2HEX(855707908+HEX2DEC(T6),8) -> 330138E1 | V6: Route 1 | W6: Hau'oli City | X6: Route 2 | Y6: Iki Town | Z6: Your House | AA6: Ten Carat Hill | AB6: Melemele Meadow | AC6: Verdant Cave | AD6: =HEX2DEC(U6)-HEX2DEC("330138D0") -> 17
A7: Hau, Paniola Town | B7: 32 | C7: 1F00 | E7: =HEX2DEC(RIGHT(C7,2)&LEFT(C7,2)) -> 31 | F7: =C7&DEC2HEX(B7,2) -> 1F0020 | H7: 0D00 | I7: After beating ilima | M7: Mudsdale Ride | N7: 330138D1 | O7: 32 | P7: =_xlfn.XLOOKUP(N7,U:U,AD:AD) -> 1 | R7: Flags 3 | S7: 1 | T7: 000027DE | U7: =DEC2HEX(855707908+HEX2DEC(T7),8) -> 330138E2 | V7: Ruins of Conflict | W7: Hau'oli Cemetery | X7: Heahea City | Y7: Royal Avenue | Z7: Route 8 | AA7: Konikoni City | AB7: Paniola Town | AC7: Battle Royale Dome | AD7: =HEX2DEC(U7)-HEX2DEC("330138D0") -> 18
A8: Gladion | B8: 37 | C8: 2400 | E8: =HEX2DEC(RIGHT(C8,2)&LEFT(C8,2)) -> 36 | F8: =C8&DEC2HEX(B8,2) -> 240025 | H8: 1400 | I8: Before Normal Trial | M8: Lapras Surf | N8: 330138D1 | O8: 64 | P8: =_xlfn.XLOOKUP(N8,U:U,AD:AD) -> 1 | R8: Flags 4 | S8: 1 | T8: 000027DF | U8: =DEC2HEX(855707908+HEX2DEC(T8),8) -> 330138E3 | V8: Hano Grand Resort | W8: Route 5/Brooklet Hill | X8: Lush Jungle | Y8: Route 7/Wela Volcano Park | Z8: Ruins of Life | AA8: Route 9/Memorial Hill | AB8: Malie City | AD8: =HEX2DEC(U8)-HEX2DEC("330138D0") -> 19
A9: Totem Araquanid | B9: 40 | C9: 3100 | E9: =HEX2DEC(RIGHT(C9,2)&LEFT(C9,2)) -> 49 | F9: =C9&DEC2HEX(B9,2) -> 310028 | H9: 1500 | I9: During Normal Trial | M9: Sharpedo Jet | N9: 330138D1 | O9: 128 | P9: =_xlfn.XLOOKUP(N9,U:U,AD:AD) -> 1 | R9: Flags 5 | S9: 1 | T9: 000027E0 | U9: =DEC2HEX(855707908+HEX2DEC(T9),8) -> 330138E4 | V9: Tapu Village | W9: Route 16 | X9: Mount Hokulani | Y9: Blush Mountain | AA9: Seafolk Village | AB9: Battle Tree | AC9: Vast Poni Canyon | AD9: =HEX2DEC(U9)-HEX2DEC("330138D0") -> 20
A10: Royal Avenue | B10: 45 | C10: 3C00 | E10: =HEX2DEC(RIGHT(C10,2)&LEFT(C10,2)) -> 60 | F10: =C10&DEC2HEX(B10,2) -> 3C002D | H10: 1600 | I10: Post Normal Trial | M10: Charizard Fly | N10: 330138D2 | O10: 1 | P10: =_xlfn.XLOOKUP(N10,U:U,AD:AD) -> 2 | R10: Flags 6 | S10: 1 | T10: 000027E1 | U10: =DEC2HEX(855707908+HEX2DEC(T10),8) -> 330138E5 | V10: Ruins of Hope | W10: Poni Meadow | X10: Exeggutor Island | Y10: Aether Paradise | AD10: =HEX2DEC(U10)-HEX2DEC("330138D0") -> 21
A11: Totem Marowak | B11: 50 | C11: 4700 | E11: =HEX2DEC(RIGHT(C11,2)&LEFT(C11,2)) -> 71 | F11: =C11&DEC2HEX(B11,2) -> 470032 | H11: 1900 | I11: Before Hala Grand Trial | M11: Always 1? | N11: 330138D2 | O11: 2 | P11: =_xlfn.XLOOKUP(N11,U:U,AD:AD) -> 2 | R11: Flags 7 | S11: 1 | T11: 000027F9 | U11: =DEC2HEX(855707908+HEX2DEC(T11),8) -> 330138FD | AB11: Po Town | AD11: =HEX2DEC(U11)-HEX2DEC("330138D0") -> 45
A12: Totem Lurantis | B12: 55 | C12: 4D00 | E12: =HEX2DEC(RIGHT(C12,2)&LEFT(C12,2)) -> 77 | F12: =C12&DEC2HEX(B12,2) -> 4D0037 | H12: 1B00 | I12: Before Dexio | L12: {=_xlfn.LET(_xlpm.x,INDIRECT(ADDRESS(INT((ROW(#REF!)-12)/8)+5,MOD(ROW(#REF!)-12,8)+22)),IF(_xlpm.x=0,"",_xlpm.x))} -> #REF! | N12: 330138E0 | O12: 1 | P12: =_xlfn.XLOOKUP(N12,U:U,AD:AD) -> 16 | R12: Flags 8 | S12: 1 | T12: 000027FA | U12: =DEC2HEX(855707908+HEX2DEC(T12),8) -> 330138FE | W12: Lake of the Moone | Z12: Altar of the Sunne | AD12: =HEX2DEC(U12)-HEX2DEC("330138D0") -> 46
A13: Kahuna Olivia | B13: 63 | C13: 6400 | E13: =HEX2DEC(RIGHT(C13,2)&LEFT(C13,2)) -> 100 | F13: =C13&DEC2HEX(B13,2) -> 64003F | H13: 1D00 | I13: Before Dexio | L13: {=_xlfn.LET(_xlpm.x,INDIRECT(ADDRESS(INT((ROW(M13)-12)/8)+5,MOD(ROW(M13)-12,8)+22)),IF(_xlpm.x=0,"",_xlpm.x))} | M13: =IF(L13="","","Fly - "&L13) | N13: 330138E0 | O13: 2 | P13: =_xlfn.XLOOKUP(N13,U:U,AD:AD) -> 16 | R13: Flags 9 | S13: 1 | T13: 00002801 | U13: =DEC2HEX(855707908+HEX2DEC(T13),8) -> 33013905 | W13: Heahea Beach | X13: Circle Controls | Y13: Big Wave Beach | AA13: Hau'oli Photo Club | AB13: Konikoni Photo Club | AC13: Ula'ula Beach | AD13: =HEX2DEC(U13)-HEX2DEC("330138D0") -> 53
A14: Malie City Hau Battle | B14: 65 | C14: 7A00 | E14: =HEX2DEC(RIGHT(C14,2)&LEFT(C14,2)) -> 122 | F14: =C14&DEC2HEX(B14,2) -> 7A0041 | H14: 1F00 | I14: After Dexio, before Hau | L14: {=_xlfn.LET(_xlpm.x,INDIRECT(ADDRESS(INT((ROW(M14)-12)/8)+5,MOD(ROW(M14)-12,8)+22)),IF(_xlpm.x=0,"",_xlpm.x))} | M14: =IF(L14="","","Fly - "&L14) | N14: 330138E0 | O14: 4 | P14: =_xlfn.XLOOKUP(N14,U:U,AD:AD) -> 16 | R14: Flags 10 | S14: 1 | T14: 00002802 | U14: =DEC2HEX(855707908+HEX2DEC(T14),8) -> 33013906 | V14: Poni Beach | AD14: =HEX2DEC(U14)-HEX2DEC("330138D0") -> 54
A15: Mt. Hokulani Bus | B15: 70 | C15: 8100 | E15: =HEX2DEC(RIGHT(C15,2)&LEFT(C15,2)) -> 129 | F15: =C15&DEC2HEX(B15,2) -> 810046 | H15: 2400 | I15: After Hau, before gladion | L15: {=_xlfn.LET(_xlpm.x,INDIRECT(ADDRESS(INT((ROW(M15)-12)/8)+5,MOD(ROW(M15)-12,8)+22)),IF(_xlpm.x=0,"",_xlpm.x))} | M15: =IF(L15="","","Fly - "&L15) | N15: 330138E0 | O15: 8 | P15: =_xlfn.XLOOKUP(N15,U:U,AD:AD) -> 16 | R15: Mantine Surf Moves | S15: 1 | T15: 00002808 | U15: =DEC2HEX(855707908+HEX2DEC(T15),8) -> 3301390C | W15: Lanturn 360 | X15: Primarina Twist | Y15: Starmie 720 | Z15: Over the Gyarados | AD15: =HEX2DEC(U15)-HEX2DEC("330138D0") -> 60
A16: Totem Togedemaru | B16: 72 | C16: 9100 | E16: =HEX2DEC(RIGHT(C16,2)&LEFT(C16,2)) -> 145 | F16: =C16&DEC2HEX(B16,2) -> 910048 | H16: 2C00 | I16: After Gladion before Brooklet Hill | L16: {=_xlfn.LET(_xlpm.x,INDIRECT(ADDRESS(INT((ROW(M16)-12)/8)+5,MOD(ROW(M16)-12,8)+22)),IF(_xlpm.x=0,"",_xlpm.x))} | M16: =IF(L16="","","Fly - "&L16) | N16: 330138E0 | O16: 16 | P16: =_xlfn.XLOOKUP(N16,U:U,AD:AD) -> 16
A17: Arrive Tapu Village | B17: 75 | C17: 9A00 | E17: =HEX2DEC(RIGHT(C17,2)&LEFT(C17,2)) -> 154 | F17: =C17&DEC2HEX(B17,2) -> 9A004B | H17: 3100 | I17: Right before Water totem | L17: {=_xlfn.LET(_xlpm.x,INDIRECT(ADDRESS(INT((ROW(M17)-12)/8)+5,MOD(ROW(M17)-12,8)+22)),IF(_xlpm.x=0,"",_xlpm.x))} -> Pokemon League | M17: =IF(L17="","","Fly - "&L17) -> Fly - Pokemon League | N17: 330138E0 | O17: 32 | P17: =_xlfn.XLOOKUP(N17,U:U,AD:AD) -> 16
A18: Totem Mimikyu | B18: 80 | C18: A200 | E18: =HEX2DEC(RIGHT(C18,2)&LEFT(C18,2)) -> 162 | F18: =C18&DEC2HEX(B18,2) -> A20050 | H18: 3300 | I18: Before double battle before Battle Royale | L18: {=_xlfn.LET(_xlpm.x,INDIRECT(ADDRESS(INT((ROW(M18)-12)/8)+5,MOD(ROW(M18)-12,8)+22)),IF(_xlpm.x=0,"",_xlpm.x))} -> Ruins of Abundance | M18: =IF(L18="","","Fly - "&L18) -> Fly - Ruins of Abundance | N18: 330138E0 | O18: 64 | P18: =_xlfn.XLOOKUP(N18,U:U,AD:AD) -> 16
A19: Po Town | B19: 85 | C19: AA00 | E19: =HEX2DEC(RIGHT(C19,2)&LEFT(C19,2)) -> 170 | F19: =C19&DEC2HEX(B19,2) -> AA0055 | H19: 3F00 | I19: After first, scripted Battle Royale | L19: {=_xlfn.LET(_xlpm.x,INDIRECT(ADDRESS(INT((ROW(M19)-12)/8)+5,MOD(ROW(M19)-12,8)+22)),IF(_xlpm.x=0,"",_xlpm.x))} -> Paniola Ranch | M19: =IF(L19="","","Fly - "&L19) -> Fly - Paniola Ranch | N19: 330138E0 | O19: 128 | P19: =_xlfn.XLOOKUP(N19,U:U,AD:AD) -> 16
A20: Kahuna Nanu | B20: 87 | C20: BA00 | E20: =HEX2DEC(RIGHT(C20,2)&LEFT(C20,2)) -> 186 | F20: =C20&DEC2HEX(B20,2) -> BA0057 | H20: 4600 | I20: Before Grass trial | L20: {=_xlfn.LET(_xlpm.x,INDIRECT(ADDRESS(INT((ROW(M20)-12)/8)+5,MOD(ROW(M20)-12,8)+22)),IF(_xlpm.x=0,"",_xlpm.x))} -> Route 1 | M20: =IF(L20="","","Fly - "&L20) -> Fly - Route 1 | N20: {=INDIRECT(ADDRESS(INT((ROW(N20)-12)/8)+5,21))} -> 330138E1 | O20: 1 | P20: =_xlfn.XLOOKUP(N20,U:U,AD:AD) -> 17
A21: Aether Branch Chief Faba | B21: 90 | C21: CA00 | E21: =HEX2DEC(RIGHT(C21,2)&LEFT(C21,2)) -> 202 | F21: =C21&DEC2HEX(B21,2) -> CA005A | H21: 5100 | I21: Before entering Diglett tunnel | L21: {=_xlfn.LET(_xlpm.x,INDIRECT(ADDRESS(INT((ROW(M21)-12)/8)+5,MOD(ROW(M21)-12,8)+22)),IF(_xlpm.x=0,"",_xlpm.x))} -> Hau'oli City | M21: =IF(L21="","","Fly - "&L21) -> Fly - Hau'oli City | N21: {=INDIRECT(ADDRESS(INT((ROW(N21)-12)/8)+5,21))} -> 330138E1 | O21: 2 | P21: =_xlfn.XLOOKUP(N21,U:U,AD:AD) -> 17
A22: Final Ultra Recon Squad Battle | B22: 96 | C22: CC00 | E22: =HEX2DEC(RIGHT(C22,2)&LEFT(C22,2)) -> 204 | F22: =C22&DEC2HEX(B22,2) -> CC0060 | H22: 5200 | I22: Some point in trainers between exiting Diglett Tunnel and Olivia | L22: {=_xlfn.LET(_xlpm.x,INDIRECT(ADDRESS(INT((ROW(M22)-12)/8)+5,MOD(ROW(M22)-12,8)+22)),IF(_xlpm.x=0,"",_xlpm.x))} -> Route 2 | M22: =IF(L22="","","Fly - "&L22) -> Fly - Route 2 | N22: {=INDIRECT(ADDRESS(INT((ROW(N22)-12)/8)+5,21))} -> 330138E1 | O22: 4 | P22: =_xlfn.XLOOKUP(N22,U:U,AD:AD) -> 17
A23: Vast Poni Canyon | B23: 100 | C23: DE00 | E23: =HEX2DEC(RIGHT(C23,2)&LEFT(C23,2)) -> 222 | F23: =C23&DEC2HEX(B23,2) -> DE0064 | H23: 5800 | I23: Some point in trainers between exiting Diglett Tunnel and Olivia | L23: {=_xlfn.LET(_xlpm.x,INDIRECT(ADDRESS(INT((ROW(M23)-12)/8)+5,MOD(ROW(M23)-12,8)+22)),IF(_xlpm.x=0,"",_xlpm.x))} -> Iki Town | M23: =IF(L23="","","Fly - "&L23) -> Fly - Iki Town | N23: {=INDIRECT(ADDRESS(INT((ROW(N23)-12)/8)+5,21))} -> 330138E1 | O23: 8 | P23: =_xlfn.XLOOKUP(N23,U:U,AD:AD) -> 17
H24: 5900 | I24: Some point in trainers between exiting Diglett Tunnel and Olivia | L24: {=_xlfn.LET(_xlpm.x,INDIRECT(ADDRESS(INT((ROW(M24)-12)/8)+5,MOD(ROW(M24)-12,8)+22)),IF(_xlpm.x=0,"",_xlpm.x))} -> Your House | M24: =IF(L24="","","Fly - "&L24) -> Fly - Your House | N24: {=INDIRECT(ADDRESS(INT((ROW(N24)-12)/8)+5,21))} -> 330138E1 | O24: 16 | P24: =_xlfn.XLOOKUP(N24,U:U,AD:AD) -> 17
H25: 5D00 | I25: Some point in trainers between exiting Diglett Tunnel and Olivia | L25: {=_xlfn.LET(_xlpm.x,INDIRECT(ADDRESS(INT((ROW(M25)-12)/8)+5,MOD(ROW(M25)-12,8)+22)),IF(_xlpm.x=0,"",_xlpm.x))} -> Ten Carat Hill | M25: =IF(L25="","","Fly - "&L25) -> Fly - Ten Carat Hill | N25: {=INDIRECT(ADDRESS(INT((ROW(N25)-12)/8)+5,21))} -> 330138E1 | O25: 32 | P25: =_xlfn.XLOOKUP(N25,U:U,AD:AD) -> 17
H26: 7300 | I26: Before Malie Hau(?) | L26: {=_xlfn.LET(_xlpm.x,INDIRECT(ADDRESS(INT((ROW(M26)-12)/8)+5,MOD(ROW(M26)-12,8)+22)),IF(_xlpm.x=0,"",_xlpm.x))} -> Melemele Meadow | M26: =IF(L26="","","Fly - "&L26) -> Fly - Melemele Meadow | N26: {=INDIRECT(ADDRESS(INT((ROW(N26)-12)/8)+5,21))} -> 330138E1 | O26: 64 | P26: =_xlfn.XLOOKUP(N26,U:U,AD:AD) -> 17
H27: 7500 | I27: Before Team Skull at foot of observatory | L27: {=_xlfn.LET(_xlpm.x,INDIRECT(ADDRESS(INT((ROW(M27)-12)/8)+5,MOD(ROW(M27)-12,8)+22)),IF(_xlpm.x=0,"",_xlpm.x))} -> Verdant Cave | M27: =IF(L27="","","Fly - "&L27) -> Fly - Verdant Cave | N27: {=INDIRECT(ADDRESS(INT((ROW(N27)-12)/8)+5,21))} -> 330138E1 | O27: 128 | P27: =_xlfn.XLOOKUP(N27,U:U,AD:AD) -> 17
H28: 7A00 | I28: After Team Skull? | L28: {=_xlfn.LET(_xlpm.x,INDIRECT(ADDRESS(INT((ROW(M28)-12)/8)+5,MOD(ROW(M28)-12,8)+22)),IF(_xlpm.x=0,"",_xlpm.x))} -> Ruins of Conflict | M28: =IF(L28="","","Fly - "&L28) -> Fly - Ruins of Conflict | N28: {=INDIRECT(ADDRESS(INT((ROW(N28)-12)/8)+5,21))} -> 330138E2 | O28: =O20 -> 1 | P28: =_xlfn.XLOOKUP(N28,U:U,AD:AD) -> 18
H29: 7C00 | I29: Reached summit | L29: {=_xlfn.LET(_xlpm.x,INDIRECT(ADDRESS(INT((ROW(M29)-12)/8)+5,MOD(ROW(M29)-12,8)+22)),IF(_xlpm.x=0,"",_xlpm.x))} -> Hau'oli Cemetery | M29: =IF(L29="","","Fly - "&L29) -> Fly - Hau'oli Cemetery | N29: {=INDIRECT(ADDRESS(INT((ROW(N29)-12)/8)+5,21))} -> 330138E2 | O29: =O21 -> 2 | P29: =_xlfn.XLOOKUP(N29,U:U,AD:AD) -> 18
H30: 8800 | I30: pre electric trial | L30: {=_xlfn.LET(_xlpm.x,INDIRECT(ADDRESS(INT((ROW(M30)-12)/8)+5,MOD(ROW(M30)-12,8)+22)),IF(_xlpm.x=0,"",_xlpm.x))} -> Heahea City | M30: =IF(L30="","","Fly - "&L30) -> Fly - Heahea City | N30: {=INDIRECT(ADDRESS(INT((ROW(N30)-12)/8)+5,21))} -> 330138E2 | O30: =O22 -> 4 | P30: =_xlfn.XLOOKUP(N30,U:U,AD:AD) -> 18
H31: 8A00 | I31: After Electric Trial | L31: {=_xlfn.LET(_xlpm.x,INDIRECT(ADDRESS(INT((ROW(M31)-12)/8)+5,MOD(ROW(M31)-12,8)+22)),IF(_xlpm.x=0,"",_xlpm.x))} -> Royal Avenue | M31: =IF(L31="","","Fly - "&L31) -> Fly - Royal Avenue | N31: {=INDIRECT(ADDRESS(INT((ROW(N31)-12)/8)+5,21))} -> 330138E2 | O31: =O23 -> 8 | P31: =_xlfn.XLOOKUP(N31,U:U,AD:AD) -> 18
H32: 9300 | I32: After reaching Tapu Village | L32: {=_xlfn.LET(_xlpm.x,INDIRECT(ADDRESS(INT((ROW(M32)-12)/8)+5,MOD(ROW(M32)-12,8)+22)),IF(_xlpm.x=0,"",_xlpm.x))} -> Route 8 | M32: =IF(L32="","","Fly - "&L32) -> Fly - Route 8 | N32: {=INDIRECT(ADDRESS(INT((ROW(N32)-12)/8)+5,21))} -> 330138E2 | O32: =O24 -> 16 | P32: =_xlfn.XLOOKUP(N32,U:U,AD:AD) -> 18
H33: A300 | I33: partway through Po Town (halfway into Mansion) | L33: {=_xlfn.LET(_xlpm.x,INDIRECT(ADDRESS(INT((ROW(M33)-12)/8)+5,MOD(ROW(M33)-12,8)+22)),IF(_xlpm.x=0,"",_xlpm.x))} -> Konikoni City | M33: =IF(L33="","","Fly - "&L33) -> Fly - Konikoni City | N33: {=INDIRECT(ADDRESS(INT((ROW(N33)-12)/8)+5,21))} -> 330138E2 | O33: =O25 -> 32 | P33: =_xlfn.XLOOKUP(N33,U:U,AD:AD) -> 18
H34: C300 | I34: Aether Foundation | L34: {=_xlfn.LET(_xlpm.x,INDIRECT(ADDRESS(INT((ROW(M34)-12)/8)+5,MOD(ROW(M34)-12,8)+22)),IF(_xlpm.x=0,"",_xlpm.x))} -> Paniola Town | M34: =IF(L34="","","Fly - "&L34) -> Fly - Paniola Town | N34: {=INDIRECT(ADDRESS(INT((ROW(N34)-12)/8)+5,21))} -> 330138E2 | O34: =O26 -> 64 | P34: =_xlfn.XLOOKUP(N34,U:U,AD:AD) -> 18
H35: C500 | I35: Battle with Dulse | L35: {=_xlfn.LET(_xlpm.x,INDIRECT(ADDRESS(INT((ROW(M35)-12)/8)+5,MOD(ROW(M35)-12,8)+22)),IF(_xlpm.x=0,"",_xlpm.x))} -> Battle Royale Dome | M35: =IF(L35="","","Fly - "&L35) -> Fly - Battle Royale Dome | N35: {=INDIRECT(ADDRESS(INT((ROW(N35)-12)/8)+5,21))} -> 330138E2 | O35: =O27 -> 128 | P35: =_xlfn.XLOOKUP(N35,U:U,AD:AD) -> 18
H36: D400 | I36: Vast Poni Canyon | L36: {=_xlfn.LET(_xlpm.x,INDIRECT(ADDRESS(INT((ROW(M36)-12)/8)+5,MOD(ROW(M36)-12,8)+22)),IF(_xlpm.x=0,"",_xlpm.x))} -> Hano Grand Resort | M36: =IF(L36="","","Fly - "&L36) -> Fly - Hano Grand Resort | N36: {=INDIRECT(ADDRESS(INT((ROW(N36)-12)/8)+5,21))} -> 330138E3 | O36: =O28 -> 1 | P36: =_xlfn.XLOOKUP(N36,U:U,AD:AD) -> 19
H37: D700 | I37: Deeper into canyon | L37: {=_xlfn.LET(_xlpm.x,INDIRECT(ADDRESS(INT((ROW(M37)-12)/8)+5,MOD(ROW(M37)-12,8)+22)),IF(_xlpm.x=0,"",_xlpm.x))} -> Route 5/Brooklet Hill | M37: =IF(L37="","","Fly - "&L37) -> Fly - Route 5/Brooklet Hill | N37: {=INDIRECT(ADDRESS(INT((ROW(N37)-12)/8)+5,21))} -> 330138E3 | O37: =O29 -> 2 | P37: =_xlfn.XLOOKUP(N37,U:U,AD:AD) -> 19
H38: 4001 | I38: Pokemon League | L38: {=_xlfn.LET(_xlpm.x,INDIRECT(ADDRESS(INT((ROW(M38)-12)/8)+5,MOD(ROW(M38)-12,8)+22)),IF(_xlpm.x=0,"",_xlpm.x))} -> Lush Jungle | M38: =IF(L38="","","Fly - "&L38) -> Fly - Lush Jungle | N38: {=INDIRECT(ADDRESS(INT((ROW(N38)-12)/8)+5,21))} -> 330138E3 | O38: =O30 -> 4 | P38: =_xlfn.XLOOKUP(N38,U:U,AD:AD) -> 19
L39: {=_xlfn.LET(_xlpm.x,INDIRECT(ADDRESS(INT((ROW(M39)-12)/8)+5,MOD(ROW(M39)-12,8)+22)),IF(_xlpm.x=0,"",_xlpm.x))} -> Route 7/Wela Volcano Park | M39: =IF(L39="","","Fly - "&L39) -> Fly - Route 7/Wela Volcano Park | N39: {=INDIRECT(ADDRESS(INT((ROW(N39)-12)/8)+5,21))} -> 330138E3 | O39: =O31 -> 8 | P39: =_xlfn.XLOOKUP(N39,U:U,AD:AD) -> 19
L40: {=_xlfn.LET(_xlpm.x,INDIRECT(ADDRESS(INT((ROW(M40)-12)/8)+5,MOD(ROW(M40)-12,8)+22)),IF(_xlpm.x=0,"",_xlpm.x))} -> Ruins of Life | M40: =IF(L40="","","Fly - "&L40) -> Fly - Ruins of Life | N40: {=INDIRECT(ADDRESS(INT((ROW(N40)-12)/8)+5,21))} -> 330138E3 | O40: =O32 -> 16 | P40: =_xlfn.XLOOKUP(N40,U:U,AD:AD) -> 19
...

Sheet original
A1: in-file code.bin | B1: Address | C1: Hex | D1: instruction | E1: notes
B2: Section in exp calc function
B3: 00015AD4 | D3: cmp r0, 0x64 | E3: function just loaded current level, compare against 100
B4: =DEC2HEX(HEX2DEC(B3)+4,8) -> 00015AD8 | D4: nop | E4: extremely convenient nop
B5: =DEC2HEX(HEX2DEC(B4)+4,8) -> 00015ADC | D5: bge 0x00015AF4 | E5: if level >= 100, skip over instructions that set up exp gain
E6: (note this is neccessary but not sufficient to allow levels over 100)
D7: Section in code.bin for rare candy
A8: =DEC2HEX(HEX2DEC(B8)-HEX2DEC(100000),8) -> 00225ACC | B8: 00325ACC | C8: 640055E3 | D8: cmp r5, 0x64 | E8: checks if current level + 1 > 100
A9: =DEC2HEX(HEX2DEC(A8)+4,8) -> 00225AD0 | B9: =DEC2HEX(HEX2DEC(B8)+4,8) -> 00325AD0 | C9: 6450A083 | D9: movhi r5, 0x64 | E9: if so, set it to 100
A10: =DEC2HEX(HEX2DEC(A9)+4,8) -> 00225AD4 | B10: =DEC2HEX(HEX2DEC(B9)+4,8) -> 00325AD4 | C10: 000055E1 | D10: cmp r5, r0 | E10: compare new level to old level
A11: =DEC2HEX(HEX2DEC(A10)+4,8) -> 00225AD8 | B11: =DEC2HEX(HEX2DEC(B10)+4,8) -> 00325AD8 | C11: 1E00000A | D11: beq 0x325B58 | E11: if they are equal, exit

Sheet Sheet1
I5: offset in game
B7: Offset | C7: Base
A8: 1478 | B8: 33012890 | C8: 33012810 | D8: bit 2 is Z-moves enabled | G8: =HEX2DEC(B8)-HEX2DEC(C8) -> 128 | I8: =DEC2HEX(G8) -> 80
A9: 001EA6 | B9: 33012FAA | C9: 33012810 | D9: "Important battles" | G9: =HEX2DEC(B9)-HEX2DEC(C9) -> 1946 | I9: =DEC2HEX(G9) -> 79A
A10: 25F2 | D10: Poipole 0x20
A11: 27CC | D11: Rides
A13: 27CC | B13: 330138D0 | C13: 33012810 | G13: =HEX2DEC(B13)-HEX2DEC(C8) -> 4288 | I13: =DEC2HEX(G13) -> 10C0
A15: 2808 | B15: 3301390C | C15: 33012810 | D15: Mantine Surf moves | G15: =HEX2DEC(B15)-HEX2DEC(C15) -> 4348 | I15: =DEC2HEX(G15) -> 10FC
E18: 02 00 04 2F
C19: 33012810
A20: 321674 | B20: 30009FE5 | C20: =_xlfn.CONCAT("ldr r0, [pc, #",HEX2DEC(A34)-HEX2DEC(A20)-8,"]") -> ldr r0, [pc, #48]
A21: =DEC2HEX(HEX2DEC(A20)+4) -> 321678 | B21: B812DFE1 | C21: =_xlfn.CONCAT("ldrh r1, [pc, #",HEX2DEC(A33)-HEX2DEC(A21)-8,"]") -> ldrh r1, [pc, #40]
A22: =DEC2HEX(HEX2DEC(A21)+4) -> 32167C | B22: 0020A0E3 | C22: mov r2, 0x0
A23: =DEC2HEX(HEX2DEC(A22)+4) -> 321680 | B23: B23090E1 | C23: ldrh r3, [r0, r2] | H23: F80
A24: =DEC2HEX(HEX2DEC(A23)+4) -> 321684 | B24: 030051E1 | C24: cmp r1, r3
A25: =DEC2HEX(HEX2DEC(A24)+4) -> 321688 | B25: 02008000 | C25: addeq r0, r0, r2 | I25: Found | J25: Base
A26: =DEC2HEX(HEX2DEC(A25)+4) -> 32168C | B26: 00409005 | C26: ldreq r4, [r0] | I26: 31055f62 | J26: 30034B14 | K26: =DEC2HEX(HEX2DEC(I26)-HEX2DEC(J26)) -> 102144E
A27: =DEC2HEX(HEX2DEC(A26)+4) -> 321690 | B27: 04509005 | C27: ldreq r5, [r0, 0x4] | I27: 32F86236 | J27: 30034B14 | K27: =DEC2HEX(HEX2DEC(I27)-HEX2DEC(J27)) -> 2F51722
A28: =DEC2HEX(HEX2DEC(A27)+4) -> 321694 | B28: 08609005 | C28: ldreq r6, [r0, 0x8]
A29: =DEC2HEX(HEX2DEC(A28)+4) -> 321698 | B29: 0C709005 | C29: ldreq r7, [r0, 0xC] | H29: 3B (zflag) | I29: 30034B94 | J29: 30034B14 | K29: =DEC2HEX(HEX2DEC(I29)-HEX2DEC(J29)) -> 80
A30: =DEC2HEX(HEX2DEC(A29)+4) -> 32169C | B30: FEFFFF0A | C30: =_xlfn.CONCAT("beq 0x",A30) -> beq 0x32169C | I30: 33012FA8 | J30: 33012810 | K30: =DEC2HEX(HEX2DEC(I30)-HEX2DEC(J30)) -> 798
A31: =DEC2HEX(HEX2DEC(A30)+4) -> 3216A0 | B31: 022082E2 | C31: add r2, r2, 0x2 | I31: 33012FA8 | J31: 30036614 | K31: =DEC2HEX(HEX2DEC(I31)-HEX2DEC(J31)) -> 2FDC994 | L31: 2366C | M31: 3000000
A32: =DEC2HEX(HEX2DEC(A31)+4) -> 3216A4 | B32: F5FFFFEA | C32: =_xlfn.CONCAT("b 0x",A23) -> b 0x321680 | I32: 33012FA8 | J32: 3003811C | K32: =DEC2HEX(HEX2DEC(I32)-HEX2DEC(J32)) -> 2FDAE8C | L32: 2366C | M32: 3000000
A33: =DEC2HEX(HEX2DEC(A32)+4) -> 3216A8 | B33: 1C010000 | C33: PID
A34: =DEC2HEX(HEX2DEC(A33)+4) -> 3216AC | B34: 0000FE33 | C34: pointer
I35: 1EA4 | J35: =HEX2DEC(I35) -> 7844
I36: 27CC | J36: =HEX2DEC(I36) -> 10188 | K36: =J36-J35 -> 2344
I38: 33012FA8 | J38: =HEX2DEC(I38) -> 855715752
C39: 33FE011C | I39: 330138D0 | J39: =HEX2DEC(I39) -> 855718096 | K39: =J39-J38 -> 2344

Sheet important values
A1: Value (hex) | B1: Where in game | C1: Max Level
A2: 0 | B2: Start
A3: 1 | B3: before first hau | C3: 9
A4: 5 | B4: after first Hau | C4: 10
A5: 9 | B5: partway through Trainer School | C5: 15
A6: C | B6: before ilima | C6: 17
A7: D | B7: After beating ilima
A8: 14 | B8: Before Normal Trial
A9: 15 | B9: During Normal Trial | C9: 20
A10: 16 | B10: Post Normal Trial | C10: 25
A11: 19 | B11: Before Hala Grand Trial | C11: 27
A12: 1B | B12: Before Dexio
A13: 1D | B13: Before Dexio | C13: 29
A14: 1F | B14: After Dexio, before Hau | C14: 32
A15: 24 | B15: After Hau, before gladion | C15: 37
A16: 2C | B16: After Gladion before Brooklet Hill
A17: 31 | B17: Right before Water totem | C17: 40
A18: 33 | B18: Before double battle before Battle Royale | C18: 48
A19: 3F | B19: After first, scripted Battle Royale | C19: 50
A20: 46 | B20: Before Grass trial | C20: 55
A21: 51 | B21: Before entering Diglett tunnel | C21: 60
A22: 52 | B22: Some point in trainers between exiting Diglett Tunnel and Olivia
A23: 58 | B23: Some point in trainers between exiting Diglett Tunnel and Olivia
A24: 59 | B24: Some point in trainers between exiting Diglett Tunnel and Olivia
A25: 5D | B25: Some point in trainers between exiting Diglett Tunnel and Olivia | C25: 63
A26: 73 | B26: Before Malie Hau(?) | C26: 65
A27: 75 | B27: Before Team Skull at foot of observatory
A28: 7A | B28: After Team Skull? | C28: 70
A29: 7C | B29: Reached summit | C29: 72
A30: 88 | B30: pre electric trial
A31: 8A | B31: After Electric Trial
A32: 93 | B32: After reaching Tapu Village | C32: 75
A33: A3 | B33: partway through Po Town (halfway into Mansion) | C33: 85
A34: C3 | B34: Aether Foundation | C34: 90
A35: C5 | B35: Battle with Dulse | C35: 96
A36: D4 | B36: Vast Poni Canyon
A37: D7 | B37: Deeper into canyon | C37: 100
A38: 140 | B38: Pokemon League
