Workbook

Sheet Copy Output
A1: US code.bin
A2: Address | B2: Thing to paste starting there | C2: Length (bytes, hex)
A3: ='Edited main'!A3 -> 0029A048 | B3: =_xlfn.CONCAT('Edited main'!B3) -> CF7F08EB | C3: =DEC2HEX(LEN(B3)/2,3) -> 004
A4: ='Edited main'!A9 -> 00341654 | B4: =_xlfn.CONCAT('Edited main'!B9:B10) -> F0472DE95CE205EB | C4: =DEC2HEX(LEN(B4)/2,3) -> 008
A5: ='Edited main'!A13 -> 003417D8 | B5: =_xlfn.CONCAT('Edited main'!B13:B14) -> FFE105EA00F020E3 | C5: =DEC2HEX(LEN(B5)/2,3) -> 008
A6: ='Edited main'!A17 -> 003418EC | B6: =_xlfn.CONCAT('Edited main'!B17) -> F087BDE8 | C6: =DEC2HEX(LEN(B6)/2,3) -> 004
A7: ='Edited main'!A25 -> 004B9F8C | B7: =_xlfn.CONCAT('Edited main'!B25:B67) -> 0CD04DE20C402DE9052B41E2AA2052E2090000BA0E0052E30700008A033002E22221A0E1033082E0030053E303304322010053E3B410DF31B210DF810C80BDE87C15171601A0A0E10CD04DE21EFF2FE11F402DE90040A0E10A00A0E134A6F5EB040050E11F40BDE8321EFABA020050E3F61DFAEA | C7: =DEC2HEX(LEN(B7)/2,3) -> 074
A9: UM code.bin
A10: Address | B10: Thing to paste starting there | C10: Length (bytes, hex)
A11: ='Edited main'!E3 -> 0029A048 | B11: =_xlfn.CONCAT('Edited main'!F3) -> CF7F08EB | C11: =DEC2HEX(LEN(B11)/2,3) -> 004
A12: ='Edited main'!E9 -> 00341658 | B12: =_xlfn.CONCAT('Edited main'!F9:F10) -> F0472DE95BE205EB | C12: =DEC2HEX(LEN(B12)/2,3) -> 008
A13: ='Edited main'!E13 -> 003417DC | B13: =_xlfn.CONCAT('Edited main'!F13:F14) -> FEE105EA00F020E3 | C13: =DEC2HEX(LEN(B13)/2,3) -> 008
A14: ='Edited main'!E17 -> 003418F0 | B14: =_xlfn.CONCAT('Edited main'!F17) -> F087BDE8 | C14: =DEC2HEX(LEN(B14)/2,3) -> 004
A15: ='Edited main'!E25 -> 004B9F8C | B15: =_xlfn.CONCAT('Edited main'!F25:F67) -> 0CD04DE20C402DE9052B41E2AA2052E2090000BA0E0052E30700008A033002E22221A0E1033082E0030053E303304322010053E3B410DF31B210DF810C80BDE87C15171601A0A0E10CD04DE21EFF2FE11F402DE90040A0E10A00A0E134A6F5EB040050E11F40BDE8331EFABA020050E3F71DFAEA | C15: =DEC2HEX(LEN(B15)/2,3) -> 074

Sheet Edited main
A1: Address US | B1: Hex US | C1: Instruction US | D1: notes | E1: Address UM | F1: Hex UM | G1: Instruction UM
A2: Café NPC
A3: 0029A048 | B3: CF7F08EB | C3: =_xlfn.CONCAT("bl 0x",A25) -> bl 0x004B9F8C | E3: 0029A048 | F3: CF7F08EB | G3: =_xlfn.CONCAT("bl 0x",E25) -> bl 0x004B9F8C
A5: Return level
A6: 002238C0 | E6: 002238C0
A8: Relearner Move Display Function Start
A9: 00341654 | B9: F0472DE9 | C9: push {r4, r5, r6, r7, r8, r9, r10, lr} | E9: 00341658 | F9: F0472DE9 | G9: push {r4, r5, r6, r7, r8, r9, r10, lr}
A10: =DEC2HEX(HEX2DEC(A9)+4,8) -> 00341658 | B10: 5CE205EB | C10: =_xlfn.CONCAT("bl 0x",A44) -> bl 0x004B9FD0 | E10: =DEC2HEX(HEX2DEC(E9)+4,8) -> 0034165C | F10: 5BE205EB | G10: =_xlfn.CONCAT("bl 0x",E44) -> bl 0x004B9FD0
A12: Final Check
A13: 003417D8 | B13: FFE105EA | C13: =_xlfn.CONCAT("b 0x",A49) -> b 0x004B9FDC | E13: 003417DC | F13: FEE105EA | G13: =_xlfn.CONCAT("b 0x",E49) -> b 0x004B9FDC
A14: =DEC2HEX(HEX2DEC(A13)+4,8) -> 003417DC | B14: 00F020E3 | C14: nop | E14: =DEC2HEX(HEX2DEC(E13)+4,8) -> 003417E0 | F14: 00F020E3 | G14: nop
A16: Modify Pop
A17: 003418EC | B17: F087BDE8 | C17: pop {r4, r5, r6, r7, r8, r9, r10, pc} | E17: =DEC2HEX(HEX2DEC(A17)-HEX2DEC(A14)+HEX2DEC(E14),8) -> 003418F0 | F17: F087BDE8 | G17: pop {r4, r5, r6, r7, r8, r9, r10, pc}
A21: Skip to if fail check
A22: 003418C4 | B22: 080295E5 | C22: ldr r0, [r5, #0x208] | E22: 003418C8 | F22: 080295E5 | G22: ldr r0, [r5, #0x208]
A24: Replace Café NPC with Move Relearner
A25: 004B9F8C | B25: 0CD04DE2 | C25: sub sp, sp, #0xc | E25: 004B9F8C | F25: =B25 -> 0CD04DE2 | G25: =C25 -> sub sp, sp, #0xc
A26: =DEC2HEX(HEX2DEC(A25)+4,8) -> 004B9F90 | B26: 0C402DE9 | C26: push {r2, r3, lr} | E26: =DEC2HEX(HEX2DEC(E25)+4,8) -> 004B9F90 | F26: =B26 -> 0C402DE9 | G26: =C26 -> push {r2, r3, lr}
A27: =DEC2HEX(HEX2DEC(A26)+4,8) -> 004B9F94 | B27: 052B41E2 | C27: sub r2, r1, 0x1400 | D27: lowest PC now 0 | E27: =DEC2HEX(HEX2DEC(E26)+4,8) -> 004B9F94 | F27: =B27 -> 052B41E2 | G27: =C27 -> sub r2, r1, 0x1400
A28: =DEC2HEX(HEX2DEC(A27)+4,8) -> 004B9F98 | B28: AA2052E2 | C28: subs r2, r2, 0xAA | E28: =DEC2HEX(HEX2DEC(E27)+4,8) -> 004B9F98 | F28: =B28 -> AA2052E2 | G28: =C28 -> subs r2, r2, 0xAA
A29: =DEC2HEX(HEX2DEC(A28)+4,8) -> 004B9F9C | B29: 090000BA | C29: =_xlfn.CONCAT("blt 0x",A40) -> blt 0x004B9FC8 | D29: Highest now E | E29: =DEC2HEX(HEX2DEC(E28)+4,8) -> 004B9F9C | F29: =B29 -> 090000BA | G29: =C29 -> blt 0x004B9FC8
A30: =DEC2HEX(HEX2DEC(A29)+4,8) -> 004B9FA0 | B30: 0E0052E3 | C30: cmp r2, 0xE | E30: =DEC2HEX(HEX2DEC(E29)+4,8) -> 004B9FA0 | F30: =B30 -> 0E0052E3 | G30: =C30 -> cmp r2, 0xE
A31: =DEC2HEX(HEX2DEC(A30)+4,8) -> 004B9FA4 | B31: 0700008A | C31: =_xlfn.CONCAT("bhi 0x",A40) -> bhi 0x004B9FC8 | D31: take module 3 | E31: =DEC2HEX(HEX2DEC(E30)+4,8) -> 004B9FA4 | F31: =B31 -> 0700008A | G31: =C31 -> bhi 0x004B9FC8
A32: =DEC2HEX(HEX2DEC(A31)+4,8) -> 004B9FA8 | B32: 033002E2 | C32: and r3, r2, 0x3 | E32: =DEC2HEX(HEX2DEC(E31)+4,8) -> 004B9FA8 | F32: =B32 -> 033002E2 | G32: =C32 -> and r3, r2, 0x3
A33: =DEC2HEX(HEX2DEC(A32)+4,8) -> 004B9FAC | B33: 2221A0E1 | C33: lsr r2, r2, #2 | E33: =DEC2HEX(HEX2DEC(E32)+4,8) -> 004B9FAC | F33: =B33 -> 2221A0E1 | G33: =C33 -> lsr r2, r2, #2
A34: =DEC2HEX(HEX2DEC(A33)+4,8) -> 004B9FB0 | B34: 033082E0 | C34: add r3, r2, r3 | E34: =DEC2HEX(HEX2DEC(E33)+4,8) -> 004B9FB0 | F34: =B34 -> 033082E0 | G34: =C34 -> add r3, r2, r3
A35: =DEC2HEX(HEX2DEC(A34)+4,8) -> 004B9FB4 | B35: 030053E3 | C35: cmp r3, 0x3 | E35: =DEC2HEX(HEX2DEC(E34)+4,8) -> 004B9FB4 | F35: =B35 -> 030053E3 | G35: =C35 -> cmp r3, 0x3
A36: =DEC2HEX(HEX2DEC(A35)+4,8) -> 004B9FB8 | B36: 03304322 | C36: subhs r3, r3, 0x3 | E36: =DEC2HEX(HEX2DEC(E35)+4,8) -> 004B9FB8 | F36: =B36 -> 03304322 | G36: =C36 -> subhs r3, r3, 0x3
A37: =DEC2HEX(HEX2DEC(A36)+4,8) -> 004B9FBC | B37: 010053E3 | C37: cmp r3, 0x1 | D37: Move Relearner | E37: =DEC2HEX(HEX2DEC(E36)+4,8) -> 004B9FBC | F37: =B37 -> 010053E3 | G37: =C37 -> cmp r3, 0x1
A38: =DEC2HEX(HEX2DEC(A37)+4,8) -> 004B9FC0 | B38: B410DF31 | C38: =_xlfn.CONCAT("ldrhlo r1, [pc, #",HEX2DEC(A$41)-HEX2DEC(A38)-8,"]") -> ldrhlo r1, [pc, #4] | D38: Hyper Training | E38: =DEC2HEX(HEX2DEC(E37)+4,8) -> 004B9FC0 | F38: =B38 -> B410DF31 | G38: =C38 -> ldrhlo r1, [pc, #4]
A39: =DEC2HEX(HEX2DEC(A38)+4,8) -> 004B9FC4 | B39: B210DF81 | C39: =_xlfn.CONCAT("ldrhhi r1, [pc, #",HEX2DEC(A$41)-HEX2DEC(A39)-8+2,"]") -> ldrhhi r1, [pc, #2] | E39: =DEC2HEX(HEX2DEC(E38)+4,8) -> 004B9FC4 | F39: =B39 -> B210DF81 | G39: =C39 -> ldrhhi r1, [pc, #2]
A40: =DEC2HEX(HEX2DEC(A39)+4,8) -> 004B9FC8 | B40: 0C80BDE8 | C40: =SUBSTITUTE(SUBSTITUTE(C26,"push","pop"),"lr","pc") -> pop {r2, r3, pc} | E40: =DEC2HEX(HEX2DEC(E39)+4,8) -> 004B9FC8 | F40: =B40 -> 0C80BDE8 | G40: =C40 -> pop {r2, r3, pc}
A41: =DEC2HEX(HEX2DEC(A40)+4,8) -> 004B9FCC | B41: 7C151716 | D41: Relearner ID | Hyper Training ID | E41: =DEC2HEX(HEX2DEC(E40)+4,8) -> 004B9FCC | F41: =B41 -> 7C151716
A43: Prevent too-high-level moves from appearing
A44: =DEC2HEX(HEX2DEC(A41)+4,8) -> 004B9FD0 | B44: 01A0A0E1 | C44: mov r10, r1 | D44: move pointer into r10 | E44: =DEC2HEX(HEX2DEC(E41)+4,8) -> 004B9FD0 | F44: 01A0A0E1 | G44: mov r10, r1
A45: =DEC2HEX(HEX2DEC(A44)+4,8) -> 004B9FD4 | B45: 0CD04DE2 | C45: sub sp, sp, #0xc | D45: adjust stack pointer (from org) | E45: =DEC2HEX(HEX2DEC(E44)+4,8) -> 004B9FD4 | F45: 0CD04DE2 | G45: sub sp, sp, #0xc
A46: =DEC2HEX(HEX2DEC(A45)+4,8) -> 004B9FD8 | B46: 1EFF2FE1 | C46: bx lr | D46: return | E46: =DEC2HEX(HEX2DEC(E45)+4,8) -> 004B9FD8 | F46: 1EFF2FE1 | G46: bx lr
A48: Check change
A49: =DEC2HEX(HEX2DEC(A46)+4,8) -> 004B9FDC | B49: 1F402DE9 | C49: push {r0, r1, r2, r3, r4, lr} | E49: =DEC2HEX(HEX2DEC(E46)+4,8) -> 004B9FDC | F49: 1F402DE9 | G49: push {r0, r1, r2, r3, r4, lr}
A50: =DEC2HEX(HEX2DEC(A49)+4,8) -> 004B9FE0 | B50: 0040A0E1 | C50: mov r4, r0 | E50: =DEC2HEX(HEX2DEC(E49)+4,8) -> 004B9FE0 | F50: 0040A0E1 | G50: mov r4, r0
...

Sheet Cafe Script IDs
A1: Dec | B1: Hex | C1: Pokemon Center | E1: Plan
A2: 5290 | B2: =DEC2HEX(A2) -> 14AA | C2: Route 1 | E2: =M2 -> 0 | F2: =_xlfn.XLOOKUP(E2,D$19:D$21,C$19:C$21) -> Move Relearner | H2: =A2-5290 -> 0 | I2: =DEC2HEX(H2) -> 0 | J2: =_xlfn.BITAND(H2,3) -> 0 | K2: =_xlfn.BITRSHIFT(H2,2) -> 0 | L2: =SUM(J2:K2) -> 0 | M2: =IF(L2>=3,L2-3,L2) -> 0
A3: 5291 | B3: =DEC2HEX(A3) -> 14AB | C3: Hau'oli City | E3: =M3 -> 1 | F3: =_xlfn.XLOOKUP(E3,D$19:D$21,C$19:C$21) -> Café | H3: =A3-5290 -> 1 | I3: =DEC2HEX(H3) -> 1 | J3: =_xlfn.BITAND(H3,3) -> 1 | K3: =_xlfn.BITRSHIFT(H3,2) -> 0 | L3: =SUM(J3:K3) -> 1 | M3: =IF(L3>=3,L3-3,L3) -> 1
A4: 5292 | B4: =DEC2HEX(A4) -> 14AC | C4: Route 2 | E4: =M4 -> 2 | F4: =_xlfn.XLOOKUP(E4,D$19:D$21,C$19:C$21) -> Super Training | H4: =A4-5290 -> 2 | I4: =DEC2HEX(H4) -> 2 | J4: =_xlfn.BITAND(H4,3) -> 2 | K4: =_xlfn.BITRSHIFT(H4,2) -> 0 | L4: =SUM(J4:K4) -> 2 | M4: =IF(L4>=3,L4-3,L4) -> 2
A5: 5293 | B5: =DEC2HEX(A5) -> 14AD | C5: Heahea City | E5: =M5 -> 0 | F5: =_xlfn.XLOOKUP(E5,D$19:D$21,C$19:C$21) -> Move Relearner | H5: =A5-5290 -> 3 | I5: =DEC2HEX(H5) -> 3 | J5: =_xlfn.BITAND(H5,3) -> 3 | K5: =_xlfn.BITRSHIFT(H5,2) -> 0 | L5: =SUM(J5:K5) -> 3 | M5: =IF(L5>=3,L5-3,L5) -> 0
A6: 5294 | B6: =DEC2HEX(A6) -> 14AE | C6: Royal Avenue | E6: =M6 -> 1 | F6: =_xlfn.XLOOKUP(E6,D$19:D$21,C$19:C$21) -> Café | H6: =A6-5290 -> 4 | I6: =DEC2HEX(H6) -> 4 | J6: =_xlfn.BITAND(H6,3) -> 0 | K6: =_xlfn.BITRSHIFT(H6,2) -> 1 | L6: =SUM(J6:K6) -> 1 | M6: =IF(L6>=3,L6-3,L6) -> 1
A7: 5295 | B7: =DEC2HEX(A7) -> 14AF | C7: Route 8 | E7: =M7 -> 2 | F7: =_xlfn.XLOOKUP(E7,D$19:D$21,C$19:C$21) -> Super Training | H7: =A7-5290 -> 5 | I7: =DEC2HEX(H7) -> 5 | J7: =_xlfn.BITAND(H7,3) -> 1 | K7: =_xlfn.BITRSHIFT(H7,2) -> 1 | L7: =SUM(J7:K7) -> 2 | M7: =IF(L7>=3,L7-3,L7) -> 2
A8: 5296 | B8: =DEC2HEX(A8) -> 14B0 | C8: Konikoni City | E8: =M8 -> 0 | F8: =_xlfn.XLOOKUP(E8,D$19:D$21,C$19:C$21) -> Move Relearner | H8: =A8-5290 -> 6 | I8: =DEC2HEX(H8) -> 6 | J8: =_xlfn.BITAND(H8,3) -> 2 | K8: =_xlfn.BITRSHIFT(H8,2) -> 1 | L8: =SUM(J8:K8) -> 3 | M8: =IF(L8>=3,L8-3,L8) -> 0
A9: 5297 | B9: =DEC2HEX(A9) -> 14B1 | C9: Malie City | E9: =M9 -> 1 | F9: =_xlfn.XLOOKUP(E9,D$19:D$21,C$19:C$21) -> Café | H9: =A9-5290 -> 7 | I9: =DEC2HEX(H9) -> 7 | J9: =_xlfn.BITAND(H9,3) -> 3 | K9: =_xlfn.BITRSHIFT(H9,2) -> 1 | L9: =SUM(J9:K9) -> 4 | M9: =IF(L9>=3,L9-3,L9) -> 1
A10: 5298 | B10: =DEC2HEX(A10) -> 14B2 | C10: Tapu Village | E10: =M10 -> 2 | F10: =_xlfn.XLOOKUP(E10,D$19:D$21,C$19:C$21) -> Super Training | H10: =A10-5290 -> 8 | I10: =DEC2HEX(H10) -> 8 | J10: =_xlfn.BITAND(H10,3) -> 0 | K10: =_xlfn.BITRSHIFT(H10,2) -> 2 | L10: =SUM(J10:K10) -> 2 | M10: =IF(L10>=3,L10-3,L10) -> 2
A11: 5299 | B11: =DEC2HEX(A11) -> 14B3 | C11: Route 16 | E11: =M11 -> 0 | F11: =_xlfn.XLOOKUP(E11,D$19:D$21,C$19:C$21) -> Move Relearner | H11: =A11-5290 -> 9 | I11: =DEC2HEX(H11) -> 9 | J11: =_xlfn.BITAND(H11,3) -> 1 | K11: =_xlfn.BITRSHIFT(H11,2) -> 2 | L11: =SUM(J11:K11) -> 3 | M11: =IF(L11>=3,L11-3,L11) -> 0
A12: 5300 | B12: =DEC2HEX(A12) -> 14B4 | C12: Seafolk Village | E12: =M12 -> 1 | F12: =_xlfn.XLOOKUP(E12,D$19:D$21,C$19:C$21) -> Café | H12: =A12-5290 -> 10 | I12: =DEC2HEX(H12) -> A | J12: =_xlfn.BITAND(H12,3) -> 2 | K12: =_xlfn.BITRSHIFT(H12,2) -> 2 | L12: =SUM(J12:K12) -> 4 | M12: =IF(L12>=3,L12-3,L12) -> 1
A13: 5301 | B13: =DEC2HEX(A13) -> 14B5 | C13: Paniola Town | E13: =M13 -> 2 | F13: =_xlfn.XLOOKUP(E13,D$19:D$21,C$19:C$21) -> Super Training | H13: =A13-5290 -> 11 | I13: =DEC2HEX(H13) -> B | J13: =_xlfn.BITAND(H13,3) -> 3 | K13: =_xlfn.BITRSHIFT(H13,2) -> 2 | L13: =SUM(J13:K13) -> 5 | M13: =IF(L13>=3,L13-3,L13) -> 2
... A16: 5304 | B16: =DEC2HEX(A16) -> 14B8 | C16: Mount Hokulani/Route 10 | E16: =M16 -> 2 | F16: =_xlfn.XLOOKUP(E16,D$19:D$21,C$19:C$21) -> Super Training | H16: =A16-5290 -> 14 | I16: =DEC2HEX(H16) -> E | J16: =_xlfn.BITAND(H16,3) -> 2 | K16: =_xlfn.BITRSHIFT(H16,2) -> 3 | L16: =SUM(J16:K16) -> 5 | M16: =IF(L16>=3,L16-3,L16) -> 2
A19: 5655 | B19: =DEC2HEX(A19) -> 1617 | C19: Super Training | D19: 2 | E19: 2
A20: 5500 | B20: =DEC2HEX(A20) -> 157C | C20: Move Relearner | D20: 0 | E20: 0
C21: Café | D21: 1 | E21: 1

Sheet original
A1: Address | B1: Hex | C1: instruction | D1: notes
A2: Café NPC
A3: 0029A044 | B3: F04F2DE9 | C3: push {r4, r5, r6, r7, r8, sb, sl, fp, lr} | D3: starts function that makes NPC do thing or something
A4: =DEC2HEX(HEX2DEC(A3)+4,8) -> 0029A048 | B4: 0CD04DE2 | C4: sub sp, sp, #0xc
A6: Return level
A7: 002238c0
A10: Relearner Move Display Function Start
A11: 00341654 | B11: F0432DE9 | C11: push {r4, r5, r6, r7, r8, sb, lr}
A12: =DEC2HEX(HEX2DEC(A11)+4,8) -> 00341658 | B12: 0CD04DE2 | C12: sub sp, sp, #0xc
A17: Function Final Check
A18: 003417D8 | B18: 020050E3 | C18: cmp r0, #2
A19: =DEC2HEX(HEX2DEC(A18)+4,8) -> 003417DC | B19: 00F020E3 | C19: nop
A21: Skip to if fail check
A22: 003418c4 | B22: 080295E5 | C22: ldr r0, [r5, #0x208]
A23: =DEC2HEX(HEX2DEC(A22)+4,8) -> 003418C8 | B23: 014084E2 | C23: add r4, r4, #1
A24: =DEC2HEX(HEX2DEC(A23)+4,8) -> 003418CC | B24: 0800D0E5 | C24: ldrb r0, [r0, #8]
A25: =DEC2HEX(HEX2DEC(A24)+4,8) -> 003418D0 | B25: 040050E1 | C25: cmp r0, r4
