Workbook

Sheet edited bag.cro
A1: Address | B1: Hex | C1: instruction | D1: notes
A2: 0000F0D8 | B2: 471B00EB | C2: =_xlfn.CONCAT("bl 0x",A5) -> bl 0x00015DFC | D2: original mov r4, r0
A4: Set Flags
A5: 00015DFC | B5: 0040A0E1 | C5: mov r4, r0
A6: =DEC2HEX(HEX2DEC(A5)+4,8) -> 00015E00 | B6: 1F402DE9 | C6: push {r0, r1, r2, r3, r4, lr}
A7: =DEC2HEX(HEX2DEC(A6)+4,8) -> 00015E04 | B7: 34008FE2 | C7: =_xlfn.CONCAT("add r0, pc, 0x",DEC2HEX(HEX2DEC(A22)-HEX2DEC(A7)-8)) -> add r0, pc, 0x34 | D7: get pointer to table of changes to make
A8: =DEC2HEX(HEX2DEC(A7)+4,8) -> 00015E08 | B8: 2C109FE5 | C8: =_xlfn.CONCAT("ldr r1, [pc, #",HEX2DEC(A21)-HEX2DEC(A8)-8,"]") -> ldr r1, [pc, #44] | D8: get pointer to data to modify
A9: =DEC2HEX(HEX2DEC(A8)+4,8) -> 00015E0C | B9: 0220D0E5 | C9: ldrb r2, [r0, 0x2] | D9: get target bit
A10: =DEC2HEX(HEX2DEC(A9)+4,8) -> 00015E10 | B10: 010052E3 | C10: cmp r2, 0x01
A11: =DEC2HEX(HEX2DEC(A10)+4,8) -> 00015E14 | B11: 0700008A | C11: =_xlfn.CONCAT("bhi 0x",A20) -> bhi 0x00015E38 | D11: FF is terminator, other two values are 0 and 1
A12: =DEC2HEX(HEX2DEC(A11)+4,8) -> 00015E18 | B12: 0030D0E5 | C12: ldrb r3, [r0, 0x0] | D12: get offset from base
A13: =DEC2HEX(HEX2DEC(A12)+4,8) -> 00015E1C | B13: 0320D1E7 | C13: ldrb r2, [r1, r3] | D13: get byte containing flag
A14: =DEC2HEX(HEX2DEC(A13)+4,8) -> 00015E20 | B14: 0140D0E5 | C14: ldrb r4, [r0, 0x1] | D14: get bit to change
A15: =DEC2HEX(HEX2DEC(A14)+4,8) -> 00015E24 | B15: 02208401 | C15: orreq r2, r4, r2 | D15: if flip value is 1, just OR the loaded bit and store
A16: =DEC2HEX(HEX2DEC(A15)+4,8) -> 00015E28 | B16: 0220C431 | C16: biclo r2, r4, r2 | D16: otherwise clear the bitflag
A17: =DEC2HEX(HEX2DEC(A16)+4,8) -> 00015E2C | B17: 0320C1E7 | C17: strb r2, [r1, r3]
A18: =DEC2HEX(HEX2DEC(A17)+4,8) -> 00015E30 | B18: 030080E2 | C18: add r0, r0, 0x3 | D18: add 3 to get next entry
A19: =DEC2HEX(HEX2DEC(A18)+4,8) -> 00015E34 | B19: F4FFFFEA | C19: =_xlfn.CONCAT("b 0x",A9) -> b 0x00015E0C
A20: =DEC2HEX(HEX2DEC(A19)+4,8) -> 00015E38 | B20: 1F80BDE8 | C20: =SUBSTITUTE(SUBSTITUTE(C6,"push","pop"),"lr","pc") -> pop {r0, r1, r2, r3, r4, pc}
A21: =DEC2HEX(HEX2DEC(A20)+4,8) -> 00015E3C | B21: D0380133 | D21: Flags location
A22: =DEC2HEX(HEX2DEC(A21)+4,8) -> 00015E40 | B22: {=_xlfn._xlws.FILTER('Flags to Set'!G:G,'Flags to Set'!G:G<>"")} -> 144001 | C22: {=_xlfn._xlws.FILTER('Flags to Set'!A:A,'Flags to Set'!G:G<>"")} -> Fly - Battle Tree
A23: =DEC2HEX(HEX2DEC(A22)+3,8) -> 00015E43 | B23: 010401 | C23: Tauros Charge
A24: =DEC2HEX(HEX2DEC(A23)+3,8) -> 00015E46 | B24: 010801 | C24: Stoutland Search
A25: =DEC2HEX(HEX2DEC(A24)+3,8) -> 00015E49 | B25: 011001 | C25: Machamp Shove
A26: =DEC2HEX(HEX2DEC(A25)+3,8) -> 00015E4C | B26: 018001 | C26: Sharpedo Jet
A27: =DEC2HEX(HEX2DEC(A26)+3,8) -> 00015E4F | B27: 020101 | C27: Charizard Fly
A28: =DEC2HEX(HEX2DEC(A27)+3,8) -> 00015E52 | B28: 010201 | C28: Ride Pager
A29: =DEC2HEX(HEX2DEC(A28)+3,8) -> 00015E55 | B29: FFFFFF | C29: 0

Sheet Flags to Set
A1: Flag | B1: Flip to | D1: Offset | E1: Bit
A2: Fly - Battle Tree | B2: 1 | D2: =IF(A2<>"",DEC2HEX(_xlfn.XLOOKUP($A2,'Known Flags'!$A:$A,'Known Flags'!D:D),2),"") -> 14 | E2: =IF(B2<>"",DEC2HEX(_xlfn.XLOOKUP($A2,'Known Flags'!$A:$A,'Known Flags'!C:C),2),"") -> 40 | G2: =IF(A2<>"",_xlfn.CONCAT(D2:E2,DEC2HEX(B2,2)),"") -> 144001
A3: Tauros Charge | B3: 1 | D3: =IF(A3<>"",DEC2HEX(_xlfn.XLOOKUP($A3,'Known Flags'!$A:$A,'Known Flags'!D:D),2),"") -> 01 | E3: =IF(B3<>"",DEC2HEX(_xlfn.XLOOKUP($A3,'Known Flags'!$A:$A,'Known Flags'!C:C),2),"") -> 04 | G3: =IF(A3<>"",_xlfn.CONCAT(D3:E3,DEC2HEX(B3,2)),"") -> 010401
A4: Stoutland Search | B4: 1 | D4: =IF(A4<>"",DEC2HEX(_xlfn.XLOOKUP($A4,'Known Flags'!$A:$A,'Known Flags'!D:D),2),"") -> 01 | E4: =IF(B4<>"",DEC2HEX(_xlfn.XLOOKUP($A4,'Known Flags'!$A:$A,'Known Flags'!C:C),2),"") -> 08 | G4: =IF(A4<>"",_xlfn.CONCAT(D4:E4,DEC2HEX(B4,2)),"") -> 010801
A5: Machamp Shove | B5: 1 | D5: =IF(A5<>"",DEC2HEX(_xlfn.XLOOKUP($A5,'Known Flags'!$A:$A,'Known Flags'!D:D),2),"") -> 01 | E5: =IF(B5<>"",DEC2HEX(_xlfn.XLOOKUP($A5,'Known Flags'!$A:$A,'Known Flags'!C:C),2),"") -> 10 | G5: =IF(A5<>"",_xlfn.CONCAT(D5:E5,DEC2HEX(B5,2)),"") -> 011001
A6: Sharpedo Jet | B6: 1 | D6: =IF(A6<>"",DEC2HEX(_xlfn.XLOOKUP($A6,'Known Flags'!$A:$A,'Known Flags'!D:D),2),"") -> 01 | E6: =IF(B6<>"",DEC2HEX(_xlfn.XLOOKUP($A6,'Known Flags'!$A:$A,'Known Flags'!C:C),2),"") -> 80 | G6: =IF(A6<>"",_xlfn.CONCAT(D6:E6,DEC2HEX(B6,2)),"") -> 018001
A7: Charizard Fly | B7: 1 | D7: =IF(A7<>"",DEC2HEX(_xlfn.XLOOKUP($A7,'Known Flags'!$A:$A,'Known Flags'!D:D),2),"") -> 02 | E7: =IF(B7<>"",DEC2HEX(_xlfn.XLOOKUP($A7,'Known Flags'!$A:$A,'Known Flags'!C:C),2),"") -> 01 | G7: =IF(A7<>"",_xlfn.CONCAT(D7:E7,DEC2HEX(B7,2)),"") -> 020101
A8: Ride Pager | B8: 1 | D8: =IF(A8<>"",DEC2HEX(_xlfn.XLOOKUP($A8,'Known Flags'!$A:$A,'Known Flags'!D:D),2),"") -> 01 | E8: =IF(B8<>"",DEC2HEX(_xlfn.XLOOKUP($A8,'Known Flags'!$A:$A,'Known Flags'!C:C),2),"") -> 02 | G8: =IF(A8<>"",_xlfn.CONCAT(D8:E8,DEC2HEX(B8,2)),"") -> 010201
D9: =IF(A9<>"",DEC2HEX(_xlfn.XLOOKUP($A9,'Known Flags'!$A:$A,'Known Flags'!D:D),2),"") | E9: =IF(B9<>"",DEC2HEX(_xlfn.XLOOKUP($A9,'Known Flags'!$A:$A,'Known Flags'!C:C),2),"") | G9: =IF(A9<>"",_xlfn.CONCAT(D9:E9,DEC2HEX(B9,2)),IF(A8="","",REPT("F",6))) -> FFFFFF
D10: =IF(A10<>"",DEC2HEX(_xlfn.XLOOKUP($A10,'Known Flags'!$A:$A,'Known Flags'!D:D),2),"") | E10: =IF(B10<>"",DEC2HEX(_xlfn.XLOOKUP($A10,'Known Flags'!$A:$A,'Known Flags'!C:C),2),"") | G10: =IF(A10<>"",_xlfn.CONCAT(D10:E10,DEC2HEX(B10,2)),"")
D11: =IF(A11<>"",DEC2HEX(_xlfn.XLOOKUP($A11,'Known Flags'!$A:$A,'Known Flags'!D:D),2),"") | E11: =IF(B11<>"",DEC2HEX(_xlfn.XLOOKUP($A11,'Known Flags'!$A:$A,'Known Flags'!C:C),2),"") | G11: =IF(A11<>"",_xlfn.CONCAT(D11:E11,DEC2HEX(B11,2)),"")
D12: =IF(A12<>"",DEC2HEX(_xlfn.XLOOKUP($A12,'Known Flags'!$A:$A,'Known Flags'!D:D),2),"") | E12: =IF(B12<>"",DEC2HEX(_xlfn.XLOOKUP($A12,'Known Flags'!$A:$A,'Known Flags'!C:C),2),"") | G12: =IF(A12<>"",_xlfn.CONCAT(D12:E12,DEC2HEX(B12,2)),"")
D13: =IF(A13<>"",DEC2HEX(_xlfn.XLOOKUP($A13,'Known Flags'!$A:$A,'Known Flags'!D:D),2),"") | E13: =IF(B13<>"",DEC2HEX(_xlfn.XLOOKUP($A13,'Known Flags'!$A:$A,'Known Flags'!C:C),2),"") | G13: =IF(A13<>"",_xlfn.CONCAT(D13:E13,DEC2HEX(B13,2)),"")
D14: =IF(A14<>"",DEC2HEX(_xlfn.XLOOKUP($A14,'Known Flags'!$A:$A,'Known Flags'!D:D),2),"") | E14: =IF(B14<>"",DEC2HEX(_xlfn.XLOOKUP($A14,'Known Flags'!$A:$A,'Known Flags'!C:C),2),"") | G14: =IF(A14<>"",_xlfn.CONCAT(D14:E14,DEC2HEX(B14,2)),"")
D15: =IF(A15<>"",DEC2HEX(_xlfn.XLOOKUP($A15,'Known Flags'!$A:$A,'Known Flags'!D:D),2),"") | E15: =IF(B15<>"",DEC2HEX(_xlfn.XLOOKUP($A15,'Known Flags'!$A:$A,'Known Flags'!C:C),2),"") | G15: =IF(A15<>"",_xlfn.CONCAT(D15:E15,DEC2HEX(B15,2)),"")
D16: =IF(A16<>"",DEC2HEX(_xlfn.XLOOKUP($A16,'Known Flags'!$A:$A,'Known Flags'!D:D),2),"") | E16: =IF(B16<>"",DEC2HEX(_xlfn.XLOOKUP($A16,'Known Flags'!$A:$A,'Known Flags'!C:C),2),"") | G16: =IF(A16<>"",_xlfn.CONCAT(D16:E16,DEC2HEX(B16,2)),"")
D17: =IF(A17<>"",DEC2HEX(_xlfn.XLOOKUP($A17,'Known Flags'!$A:$A,'Known Flags'!D:D),2),"") | E17: =IF(B17<>"",DEC2HEX(_xlfn.XLOOKUP($A17,'Known Flags'!$A:$A,'Known Flags'!C:C),2),"") | G17: =IF(A17<>"",_xlfn.CONCAT(D17:E17,DEC2HEX(B17,2)),"")
D18: =IF(A18<>"",DEC2HEX(_xlfn.XLOOKUP($A18,'Known Flags'!$A:$A,'Known Flags'!D:D),2),"") | E18: =IF(B18<>"",DEC2HEX(_xlfn.XLOOKUP($A18,'Known Flags'!$A:$A,'Known Flags'!C:C),2),"") | G18: =IF(A18<>"",_xlfn.CONCAT(D18:E18,DEC2HEX(B18,2)),"")
D19: =IF(A19<>"",DEC2HEX(_xlfn.XLOOKUP($A19,'Known Flags'!$A:$A,'Known Flags'!D:D),2),"") | E19: =IF(B19<>"",DEC2HEX(_xlfn.XLOOKUP($A19,'Known Flags'!$A:$A,'Known Flags'!C:C),2),"") | G19: =IF(A19<>"",_xlfn.CONCAT(D19:E19,DEC2HEX(B19,2)),"")
D20: =IF(A20<>"",DEC2HEX(_xlfn.XLOOKUP($A20,'Known Flags'!$A:$A,'Known Flags'!D:D),2),"") | E20: =IF(B20<>"",DEC2HEX(_xlfn.XLOOKUP($A20,'Known Flags'!$A:$A,'Known Flags'!C:C),2),"") | G20: =IF(A20<>"",_xlfn.CONCAT(D20:E20,DEC2HEX(B20,2)),"")
D21: =IF(A21<>"",DEC2HEX(_xlfn.XLOOKUP($A21,'Known Flags'!$A:$A,'Known Flags'!D:D),2),"") | E21: =IF(B21<>"",DEC2HEX(_xlfn.XLOOKUP($A21,'Known Flags'!$A:$A,'Known Flags'!C:C),2),"") | G21: =IF(A21<>"",_xlfn.CONCAT(D21:E21,DEC2HEX(B21,2)),"")
... D24: =IF(A24<>"",DEC2HEX(_xlfn.XLOOKUP($A24,'Known Flags'!$A:$A,'Known Flags'!D:D),2),"") | E24: =IF(B24<>"",DEC2HEX(_xlfn.XLOOKUP($A24,'Known Flags'!$A:$A,'Known Flags'!C:C),2),"") | G24: =IF(A24<>"",_xlfn.CONCAT(D24:E24,DEC2HEX(B24,2)),"")

Sheet Known Flags
A1: Flag | B1: Offset | C1: Bit | D1: From 330138D0 | J1: 0
A2: Always 1? | B2: 330138D1 | C2: 1 | D2: 1 | J2: 1
A3: Ride Pager | B3: 330138D1 | C3: 2 | D3: 1
A4: Tauros Charge | B4: 330138D1 | C4: 4 | D4: 1
A5: Stoutland Search | B5: 330138D1 | C5: 8 | D5: 1
A6: Machamp Shove | B6: 330138D1 | C6: 16 | D6: 1
A7: Mudsdale Ride | B7: 330138D1 | C7: 32 | D7: 1
A8: Lapras Surf | B8: 330138D1 | C8: 64 | D8: 1
A9: Sharpedo Jet | B9: 330138D1 | C9: 128 | D9: 1
A10: Charizard Fly | B10: 330138D2 | C10: 1 | D10: 2
A11: Always 1? | B11: 330138D2 | C11: 2 | D11: 2
B12: 330138E0 | C12: 1 | D12: 16
B13: 330138E0 | C13: 2 | D13: 16
B14: 330138E0 | C14: 4 | D14: 16
B15: 330138E0 | C15: 8 | D15: 16
B16: 330138E0 | C16: 16 | D16: 16
A17: Fly - Pokemon League | B17: 330138E0 | C17: 32 | D17: 16
A18: Fly - Ruins of Abundance | B18: 330138E0 | C18: 64 | D18: 16
A19: Fly - Paniola Ranch | B19: 330138E0 | C19: 128 | D19: 16
A20: Fly - Route 1 | B20: 330138E1 | C20: 1 | D20: 17
A21: Fly - Hau'oli City | B21: 330138E1 | C21: 2 | D21: 17
A22: Fly - Route 2 | B22: 330138E1 | C22: 4 | D22: 17
A23: Fly - Iki Town | B23: 330138E1 | C23: 8 | D23: 17
A24: Fly - Your House | B24: 330138E1 | C24: 16 | D24: 17
A25: Fly - Ten Carat Hill | B25: 330138E1 | C25: 32 | D25: 17
A26: Fly - Melemele Meadow | B26: 330138E1 | C26: 64 | D26: 17
A27: Fly - Verdant Cave | B27: 330138E1 | C27: 128 | D27: 17
A28: Fly - Ruins of Conflict | B28: 330138E2 | C28: 1 | D28: 18
... A42: Fly - Malie City | B42: 330138E3 | C42: 64 | D42: 19
B43: 330138E3 | C43: 128 | D43: 19
A44: Fly - Tapu Village | B44: 330138E4 | C44: 1 | D44: 20
A45: Fly - Route 16 | B45: 330138E4 | C45: 2 | D45: 20
A46: Fly - Mount Hokulani | B46: 330138E4 | C46: 4 | D46: 20
A47: Fly - Blush Mountain | B47: 330138E4 | C47: 8 | D47: 20
B48: 330138E4 | C48: 16 | D48: 20
A49: Fly - Seafolk Village | B49: 330138E4 | C49: 32 | D49: 20
A50: Fly - Battle Tree | B50: 330138E4 | C50: 64 | D50: 20
A51: Fly - Vast Poni Canyon | B51: 330138E4 | C51: 128 | D51: 20
A52: Fly - Ruins of Hope | B52: 330138E5 | C52: 1 | D52: 21
A53: Fly - Poni Meadow | B53: 330138E5 | C53: 2 | D53: 21
...
