Workbook

Sheet Table locations and sizes
B1: Code Location | I1: Table Data
B2: Original | C2: Post-Load (Ghidra) | D2: Original Entry Param Address | E2: Entry Param Address | F2: # entries | G2: Logic | H2: Edited | I2: Original | J2: Post-Load (Ghidra) | K2: Edited
A3: Field Items | B3: =DEC2HEX(HEX2DEC(C3)-HEX2DEC("6dd000"),8) -> 00084990 | C3: 00761990 | D3: 0008497C | E3: 12B88 | F3: D | G3: eq | H3: E | K3: 00021F8C | N3: item count: | O3: 259
E4: 12BCC | F4: D | G4: bcc | H4: E
G13: 0x0000012C | K13: 2D8 | L13: =HEX2DEC(K13) -> 728
E14: #relocation patches | F14: Hex | G14: Little-Endian | K14: 2D0 | L14: =HEX2DEC(K14) -> 720
A15: =DEC2HEX(MAX('Custom Relocation Patches'!L:L),8) -> 00021D34 | E15: =(MAX('Custom Relocation Patches'!L:L)-Data!F6+12)/12 -> 529 | F15: =DEC2HEX(E15,8) -> 00000211 | G15: =MID(F15,7,2)&MID(F15,5,2)&MID(F15,3,2)&MID(F15,1,2) -> 11020000 | K15: 003F | L15: =HEX2DEC(K15) -> 63
B17: Hex | C17: Dec
A18: Original Number | B18: 210 | C18: =HEX2DEC(B18) -> 528 | N18: =HEX2DEC(O18) -> 234 | O18: ea
A19: New | B19: =DEC2HEX(C19,4) -> 0001 | C19: =E15-C18 -> 1 | N19: =HEX2DEC(O19) -> 224 | O19: e0
A20: % Total | C20: =C19/E15 -> 0.0018903592 | N20: =N18-N19 -> 10
A21: % increase | C21: =C19/C18 -> 0.0018939394

Sheet Custom Relocation Patches
A1: Category | B1: Specific | C1: Target | D1: Patch Address | E1: Write-to | F1: Pointer | G1: Output | H1: .bss | I1: word 1 | J1: word 2 | K1: word 3 | L1: Dec Patch address for sorting | M1: dec write | N1: dec point | O1: Write Segment | P1: Pointer Segment | R1: =DEC2HEX(MAX(L:L)+12,8) -> 00021D40 | S1: =HEX2DEC(103974) -> 1063284
A2: Function Pointer | B2: Toggle Vs Seeker | D2: 00021D34 | E2: 0002302C | F2: 00015EB8 | G2: {=_xlfn.CONCAT(IFERROR(I2:K2,""))} -> 822F000002000000385D0100 | I2: =_xlfn.LET(_xlpm.big,DEC2HEX(_xlfn.BITLSHIFT(M2-_xlfn.XLOOKUP(O2,Data!A:A,Data!F:F),4)+O2,8),_xlfn.CONCAT(MID(_xlpm.big,7,2),MID(_xlpm.big,5,2),MID(_xlpm.big,3,2),MID(_xlpm.big,1,2))) -> 822F0000 | J2: =_xlfn.CONCAT("02",DEC2HEX(P2,2),"0000") -> 02000000 | K2: =_xlfn.LET(_xlpm.big,IF(H2,DEC2HEX(HEX2DEC(F2),8),DEC2HEX(N2-_xlfn.XLOOKUP(P2,Data!A:A,Data!F:F),8)),_xlfn.CONCAT(MID(_xlpm.big,7,2),MID(_xlpm.big,5,2),MID(_xlpm.big,3,2),MID(_xlpm.big,1,2))) -> 385D0100 | L2: =HEX2DEC(D2) -> 138548 | M2: =HEX2DEC(E2) -> 143404 | N2: =HEX2DEC(F2) -> 89784 | O2: {=_xlfn.IFS(M2<Data!$F$3,0,M2<Data!$F$4,1,TRUE,2)} -> 2 | P2: {=_xlfn.IFS(H2,3,N2<Data!$F$3,0,N2<Data!$F$4,1,TRUE,2)} -> 0
G3: {=_xlfn.CONCAT(IFERROR(I3:K3,""))} -> 02000000FEFFFFFF | I3: =_xlfn.LET(_xlpm.big,DEC2HEX(_xlfn.BITLSHIFT(M3-_xlfn.XLOOKUP(O3,Data!A:A,Data!F:F),4)+O3,8),_xlfn.CONCAT(MID(_xlpm.big,7,2),MID(_xlpm.big,5,2),MID(_xlpm.big,3,2),MID(_xlpm.big,1,2))) -> #NUM! | J3: =_xlfn.CONCAT("02",DEC2HEX(P3,2),"0000") -> 02000000 | K3: =_xlfn.LET(_xlpm.big,IF(H3,DEC2HEX(HEX2DEC(F3),8),DEC2HEX(N3-_xlfn.XLOOKUP(P3,Data!A:A,Data!F:F),8)),_xlfn.CONCAT(MID(_xlpm.big,7,2),MID(_xlpm.big,5,2),MID(_xlpm.big,3,2),MID(_xlpm.big,1,2))) -> FEFFFFFF | L3: =HEX2DEC(D3) -> 0 | M3: =HEX2DEC(E3) -> 0 | N3: =HEX2DEC(F3) -> 0 | O3: {=_xlfn.IFS(M3<Data!$F$3,0,M3<Data!$F$4,1,TRUE,2)} -> 0 | P3: {=_xlfn.IFS(H3,3,N3<Data!$F$3,0,N3<Data!$F$4,1,TRUE,2)} -> 0
G4: {=_xlfn.CONCAT(IFERROR(I4:K4,""))} -> 02000000FEFFFFFF | I4: =_xlfn.LET(_xlpm.big,DEC2HEX(_xlfn.BITLSHIFT(M4-_xlfn.XLOOKUP(O4,Data!A:A,Data!F:F),4)+O4,8),_xlfn.CONCAT(MID(_xlpm.big,7,2),MID(_xlpm.big,5,2),MID(_xlpm.big,3,2),MID(_xlpm.big,1,2))) -> #NUM! | J4: =_xlfn.CONCAT("02",DEC2HEX(P4,2),"0000") -> 02000000 | K4: =_xlfn.LET(_xlpm.big,IF(H4,DEC2HEX(HEX2DEC(F4),8),DEC2HEX(N4-_xlfn.XLOOKUP(P4,Data!A:A,Data!F:F),8)),_xlfn.CONCAT(MID(_xlpm.big,7,2),MID(_xlpm.big,5,2),MID(_xlpm.big,3,2),MID(_xlpm.big,1,2))) -> FEFFFFFF | L4: =HEX2DEC(D4) -> 0 | M4: =HEX2DEC(E4) -> 0 | N4: =HEX2DEC(F4) -> 0 | O4: {=_xlfn.IFS(M4<Data!$F$3,0,M4<Data!$F$4,1,TRUE,2)} -> 0 | P4: {=_xlfn.IFS(H4,3,N4<Data!$F$3,0,N4<Data!$F$4,1,TRUE,2)} -> 0
G5: {=_xlfn.CONCAT(IFERROR(I5:K5,""))} -> 02000000FEFFFFFF | I5: =_xlfn.LET(_xlpm.big,DEC2HEX(_xlfn.BITLSHIFT(M5-_xlfn.XLOOKUP(O5,Data!A:A,Data!F:F),4)+O5,8),_xlfn.CONCAT(MID(_xlpm.big,7,2),MID(_xlpm.big,5,2),MID(_xlpm.big,3,2),MID(_xlpm.big,1,2))) -> #NUM! | J5: =_xlfn.CONCAT("02",DEC2HEX(P5,2),"0000") -> 02000000 | K5: =_xlfn.LET(_xlpm.big,IF(H5,DEC2HEX(HEX2DEC(F5),8),DEC2HEX(N5-_xlfn.XLOOKUP(P5,Data!A:A,Data!F:F),8)),_xlfn.CONCAT(MID(_xlpm.big,7,2),MID(_xlpm.big,5,2),MID(_xlpm.big,3,2),MID(_xlpm.big,1,2))) -> FEFFFFFF | L5: =HEX2DEC(D5) -> 0 | M5: =HEX2DEC(E5) -> 0 | N5: =HEX2DEC(F5) -> 0 | O5: {=_xlfn.IFS(M5<Data!$F$3,0,M5<Data!$F$4,1,TRUE,2)} -> 0 | P5: {=_xlfn.IFS(H5,3,N5<Data!$F$3,0,N5<Data!$F$4,1,TRUE,2)} -> 0
G6: {=_xlfn.CONCAT(IFERROR(I6:K6,""))} -> 02000000FEFFFFFF | I6: =_xlfn.LET(_xlpm.big,DEC2HEX(_xlfn.BITLSHIFT(M6-_xlfn.XLOOKUP(O6,Data!A:A,Data!F:F),4)+O6,8),_xlfn.CONCAT(MID(_xlpm.big,7,2),MID(_xlpm.big,5,2),MID(_xlpm.big,3,2),MID(_xlpm.big,1,2))) -> #NUM! | J6: =_xlfn.CONCAT("02",DEC2HEX(P6,2),"0000") -> 02000000 | K6: =_xlfn.LET(_xlpm.big,IF(H6,DEC2HEX(HEX2DEC(F6),8),DEC2HEX(N6-_xlfn.XLOOKUP(P6,Data!A:A,Data!F:F),8)),_xlfn.CONCAT(MID(_xlpm.big,7,2),MID(_xlpm.big,5,2),MID(_xlpm.big,3,2),MID(_xlpm.big,1,2))) -> FEFFFFFF | L6: =HEX2DEC(D6) -> 0 | M6: =HEX2DEC(E6) -> 0 | N6: =HEX2DEC(F6) -> 0 | O6: {=_xlfn.IFS(M6<Data!$F$3,0,M6<Data!$F$4,1,TRUE,2)} -> 0 | P6: {=_xlfn.IFS(H6,3,N6<Data!$F$3,0,N6<Data!$F$4,1,TRUE,2)} -> 0
G7: {=_xlfn.CONCAT(IFERROR(I7:K7,""))} -> 02000000FEFFFFFF | I7: =_xlfn.LET(_xlpm.big,DEC2HEX(_xlfn.BITLSHIFT(M7-_xlfn.XLOOKUP(O7,Data!A:A,Data!F:F),4)+O7,8),_xlfn.CONCAT(MID(_xlpm.big,7,2),MID(_xlpm.big,5,2),MID(_xlpm.big,3,2),MID(_xlpm.big,1,2))) -> #NUM! | J7: =_xlfn.CONCAT("02",DEC2HEX(P7,2),"0000") -> 02000000 | K7: =_xlfn.LET(_xlpm.big,IF(H7,DEC2HEX(HEX2DEC(F7),8),DEC2HEX(N7-_xlfn.XLOOKUP(P7,Data!A:A,Data!F:F),8)),_xlfn.CONCAT(MID(_xlpm.big,7,2),MID(_xlpm.big,5,2),MID(_xlpm.big,3,2),MID(_xlpm.big,1,2))) -> FEFFFFFF | L7: =HEX2DEC(D7) -> 0 | M7: =HEX2DEC(E7) -> 0 | N7: =HEX2DEC(F7) -> 0 | O7: {=_xlfn.IFS(M7<Data!$F$3,0,M7<Data!$F$4,1,TRUE,2)} -> 0 | P7: {=_xlfn.IFS(H7,3,N7<Data!$F$3,0,N7<Data!$F$4,1,TRUE,2)} -> 0
G8: {=_xlfn.CONCAT(IFERROR(I8:K8,""))} -> 02000000FEFFFFFF | I8: =_xlfn.LET(_xlpm.big,DEC2HEX(_xlfn.BITLSHIFT(M8-_xlfn.XLOOKUP(O8,Data!A:A,Data!F:F),4)+O8,8),_xlfn.CONCAT(MID(_xlpm.big,7,2),MID(_xlpm.big,5,2),MID(_xlpm.big,3,2),MID(_xlpm.big,1,2))) -> #NUM! | J8: =_xlfn.CONCAT("02",DEC2HEX(P8,2),"0000") -> 02000000 | K8: =_xlfn.LET(_xlpm.big,IF(H8,DEC2HEX(HEX2DEC(F8),8),DEC2HEX(N8-_xlfn.XLOOKUP(P8,Data!A:A,Data!F:F),8)),_xlfn.CONCAT(MID(_xlpm.big,7,2),MID(_xlpm.big,5,2),MID(_xlpm.big,3,2),MID(_xlpm.big,1,2))) -> FEFFFFFF | L8: =HEX2DEC(D8) -> 0 | M8: =HEX2DEC(E8) -> 0 | N8: =HEX2DEC(F8) -> 0 | O8: {=_xlfn.IFS(M8<Data!$F$3,0,M8<Data!$F$4,1,TRUE,2)} -> 0 | P8: {=_xlfn.IFS(H8,3,N8<Data!$F$3,0,N8<Data!$F$4,1,TRUE,2)} -> 0
G9: {=_xlfn.CONCAT(IFERROR(I9:K9,""))} -> 02000000FEFFFFFF | I9: =_xlfn.LET(_xlpm.big,DEC2HEX(_xlfn.BITLSHIFT(M9-_xlfn.XLOOKUP(O9,Data!A:A,Data!F:F),4)+O9,8),_xlfn.CONCAT(MID(_xlpm.big,7,2),MID(_xlpm.big,5,2),MID(_xlpm.big,3,2),MID(_xlpm.big,1,2))) -> #NUM! | J9: =_xlfn.CONCAT("02",DEC2HEX(P9,2),"0000") -> 02000000 | K9: =_xlfn.LET(_xlpm.big,IF(H9,DEC2HEX(HEX2DEC(F9),8),DEC2HEX(N9-_xlfn.XLOOKUP(P9,Data!A:A,Data!F:F),8)),_xlfn.CONCAT(MID(_xlpm.big,7,2),MID(_xlpm.big,5,2),MID(_xlpm.big,3,2),MID(_xlpm.big,1,2))) -> FEFFFFFF | L9: =HEX2DEC(D9) -> 0 | M9: =HEX2DEC(E9) -> 0 | N9: =HEX2DEC(F9) -> 0 | O9: {=_xlfn.IFS(M9<Data!$F$3,0,M9<Data!$F$4,1,TRUE,2)} -> 0 | P9: {=_xlfn.IFS(H9,3,N9<Data!$F$3,0,N9<Data!$F$4,1,TRUE,2)} -> 0
G10: {=_xlfn.CONCAT(IFERROR(I10:K10,""))} -> 02000000FEFFFFFF | I10: =_xlfn.LET(_xlpm.big,DEC2HEX(_xlfn.BITLSHIFT(M10-_xlfn.XLOOKUP(O10,Data!A:A,Data!F:F),4)+O10,8),_xlfn.CONCAT(MID(_xlpm.big,7,2),MID(_xlpm.big,5,2),MID(_xlpm.big,3,2),MID(_xlpm.big,1,2))) -> #NUM! | J10: =_xlfn.CONCAT("02",DEC2HEX(P10,2),"0000") -> 02000000 | K10: =_xlfn.LET(_xlpm.big,IF(H10,DEC2HEX(HEX2DEC(F10),8),DEC2HEX(N10-_xlfn.XLOOKUP(P10,Data!A:A,Data!F:F),8)),_xlfn.CONCAT(MID(_xlpm.big,7,2),MID(_xlpm.big,5,2),MID(_xlpm.big,3,2),MID(_xlpm.big,1,2))) -> FEFFFFFF | L10: =HEX2DEC(D10) -> 0 | M10: =HEX2DEC(E10) -> 0 | N10: =HEX2DEC(F10) -> 0 | O10: {=_xlfn.IFS(M10<Data!$F$3,0,M10<Data!$F$4,1,TRUE,2)} -> 0 | P10: {=_xlfn.IFS(H10,3,N10<Data!$F$3,0,N10<Data!$F$4,1,TRUE,2)} -> 0
G11: {=_xlfn.CONCAT(IFERROR(I11:K11,""))} -> 02000000FEFFFFFF | I11: =_xlfn.LET(_xlpm.big,DEC2HEX(_xlfn.BITLSHIFT(M11-_xlfn.XLOOKUP(O11,Data!A:A,Data!F:F),4)+O11,8),_xlfn.CONCAT(MID(_xlpm.big,7,2),MID(_xlpm.big,5,2),MID(_xlpm.big,3,2),MID(_xlpm.big,1,2))) -> #NUM! | J11: =_xlfn.CONCAT("02",DEC2HEX(P11,2),"0000") -> 02000000 | K11: =_xlfn.LET(_xlpm.big,IF(H11,DEC2HEX(HEX2DEC(F11),8),DEC2HEX(N11-_xlfn.XLOOKUP(P11,Data!A:A,Data!F:F),8)),_xlfn.CONCAT(MID(_xlpm.big,7,2),MID(_xlpm.big,5,2),MID(_xlpm.big,3,2),MID(_xlpm.big,1,2))) -> FEFFFFFF | L11: =HEX2DEC(D11) -> 0 | M11: =HEX2DEC(E11) -> 0 | N11: =HEX2DEC(F11) -> 0 | O11: {=_xlfn.IFS(M11<Data!$F$3,0,M11<Data!$F$4,1,TRUE,2)} -> 0 | P11: {=_xlfn.IFS(H11,3,N11<Data!$F$3,0,N11<Data!$F$4,1,TRUE,2)} -> 0
G12: {=_xlfn.CONCAT(IFERROR(I12:K12,""))} -> 02000000FEFFFFFF | I12: =_xlfn.LET(_xlpm.big,DEC2HEX(_xlfn.BITLSHIFT(M12-_xlfn.XLOOKUP(O12,Data!A:A,Data!F:F),4)+O12,8),_xlfn.CONCAT(MID(_xlpm.big,7,2),MID(_xlpm.big,5,2),MID(_xlpm.big,3,2),MID(_xlpm.big,1,2))) -> #NUM! | J12: =_xlfn.CONCAT("02",DEC2HEX(P12,2),"0000") -> 02000000 | K12: =_xlfn.LET(_xlpm.big,IF(H12,DEC2HEX(HEX2DEC(F12),8),DEC2HEX(N12-_xlfn.XLOOKUP(P12,Data!A:A,Data!F:F),8)),_xlfn.CONCAT(MID(_xlpm.big,7,2),MID(_xlpm.big,5,2),MID(_xlpm.big,3,2),MID(_xlpm.big,1,2))) -> FEFFFFFF | L12: =HEX2DEC(D12) -> 0 | M12: =HEX2DEC(E12) -> 0 | N12: =HEX2DEC(F12) -> 0 | O12: {=_xlfn.IFS(M12<Data!$F$3,0,M12<Data!$F$4,1,TRUE,2)} -> 0 | P12: {=_xlfn.IFS(H12,3,N12<Data!$F$3,0,N12<Data!$F$4,1,TRUE,2)} -> 0
G13: {=_xlfn.CONCAT(IFERROR(I13:K13,""))} -> 02000000FEFFFFFF | I13: =_xlfn.LET(_xlpm.big,DEC2HEX(_xlfn.BITLSHIFT(M13-_xlfn.XLOOKUP(O13,Data!A:A,Data!F:F),4)+O13,8),_xlfn.CONCAT(MID(_xlpm.big,7,2),MID(_xlpm.big,5,2),MID(_xlpm.big,3,2),MID(_xlpm.big,1,2))) -> #NUM! | J13: =_xlfn.CONCAT("02",DEC2HEX(P13,2),"0000") -> 02000000 | K13: =_xlfn.LET(_xlpm.big,IF(H13,DEC2HEX(HEX2DEC(F13),8),DEC2HEX(N13-_xlfn.XLOOKUP(P13,Data!A:A,Data!F:F),8)),_xlfn.CONCAT(MID(_xlpm.big,7,2),MID(_xlpm.big,5,2),MID(_xlpm.big,3,2),MID(_xlpm.big,1,2))) -> FEFFFFFF | L13: =HEX2DEC(D13) -> 0 | M13: =HEX2DEC(E13) -> 0 | N13: =HEX2DEC(F13) -> 0 | O13: {=_xlfn.IFS(M13<Data!$F$3,0,M13<Data!$F$4,1,TRUE,2)} -> 0 | P13: {=_xlfn.IFS(H13,3,N13<Data!$F$3,0,N13<Data!$F$4,1,TRUE,2)} -> 0
G14: {=_xlfn.CONCAT(IFERROR(I14:K14,""))} -> 02000000FEFFFFFF | I14: =_xlfn.LET(_xlpm.big,DEC2HEX(_xlfn.BITLSHIFT(M14-_xlfn.XLOOKUP(O14,Data!A:A,Data!F:F),4)+O14,8),_xlfn.CONCAT(MID(_xlpm.big,7,2),MID(_xlpm.big,5,2),MID(_xlpm.big,3,2),MID(_xlpm.big,1,2))) -> #NUM! | J14: =_xlfn.CONCAT("02",DEC2HEX(P14,2),"0000") -> 02000000 | K14: =_xlfn.LET(_xlpm.big,IF(H14,DEC2HEX(HEX2DEC(F14),8),DEC2HEX(N14-_xlfn.XLOOKUP(P14,Data!A:A,Data!F:F),8)),_xlfn.CONCAT(MID(_xlpm.big,7,2),MID(_xlpm.big,5,2),MID(_xlpm.big,3,2),MID(_xlpm.big,1,2))) -> FEFFFFFF | L14: =HEX2DEC(D14) -> 0 | M14: =HEX2DEC(E14) -> 0 | N14: =HEX2DEC(F14) -> 0 | O14: {=_xlfn.IFS(M14<Data!$F$3,0,M14<Data!$F$4,1,TRUE,2)} -> 0 | P14: {=_xlfn.IFS(H14,3,N14<Data!$F$3,0,N14<Data!$F$4,1,TRUE,2)} -> 0
... G127: {=_xlfn.CONCAT(IFERROR(I127:K127,""))} -> 02000000FEFFFFFF | I127: =_xlfn.LET(_xlpm.big,DEC2HEX(_xlfn.BITLSHIFT(M127-_xlfn.XLOOKUP(O127,Data!A:A,Data!F:F),4)+O127,8),_xlfn.CONCAT(MID(_xlpm.big,7,2),MID(_xlpm.big,5,2),MID(_xlpm.big,3,2),MID(_xlpm.big,1,2))) -> #NUM! | J127: =_xlfn.CONCAT("02",DEC2HEX(P127,2),"0000") -> 02000000 | K127: =_xlfn.LET(_xlpm.big,IF(H127,DEC2HEX(HEX2DEC(F127),8),DEC2HEX(N127-_xlfn.XLOOKUP(P127,Data!A:A,Data!F:F),8)),_xlfn.CONCAT(MID(_xlpm.big,7,2),MID(_xlpm.big,5,2),MID(_xlpm.big,3,2),MID(_xlpm.big,1,2))) -> FEFFFFFF | L127: =HEX2DEC(D127) -> 0 | M127: =HEX2DEC(E127) -> 0 | N127: =HEX2DEC(F127) -> 0 | O127: {=_xlfn.IFS(M127<Data!$F$3,0,M127<Data!$F$4,1,TRUE,2)} -> 0 | P127: {=_xlfn.IFS(H127,3,N127<Data!$F$3,0,N127<Data!$F$4,1,TRUE,2)} -> 0
G128: {=_xlfn.CONCAT(IFERROR(I128:K128,""))} -> 0203000000000000 | H128: TRUE | I128: =_xlfn.LET(_xlpm.big,DEC2HEX(_xlfn.BITLSHIFT(M128-_xlfn.XLOOKUP(O128,Data!A:A,Data!F:F),4)+O128,8),_xlfn.CONCAT(MID(_xlpm.big,7,2),MID(_xlpm.big,5,2),MID(_xlpm.big,3,2),MID(_xlpm.big,1,2))) -> #NUM! | J128: =_xlfn.CONCAT("02",DEC2HEX(P128,2),"0000") -> 02030000 | K128: =_xlfn.LET(_xlpm.big,IF(H128,DEC2HEX(HEX2DEC(F128),8),DEC2HEX(N128-_xlfn.XLOOKUP(P128,Data!A:A,Data!F:F),8)),_xlfn.CONCAT(MID(_xlpm.big,7,2),MID(_xlpm.big,5,2),MID(_xlpm.big,3,2),MID(_xlpm.big,1,2))) -> 00000000 | L128: =HEX2DEC(D128) -> 0 | M128: =HEX2DEC(E128) -> 0 | N128: =HEX2DEC(F128) -> 0 | O128: {=_xlfn.IFS(M128<Data!$F$3,0,M128<Data!$F$4,1,TRUE,2)} -> 0 | P128: {=_xlfn.IFS(H128,3,N128<Data!$F$3,0,N128<Data!$F$4,1,TRUE,2)} -> 3
G129: {=_xlfn.CONCAT(IFERROR(I129:K129,""))} -> 02000000FEFFFFFF | I129: =_xlfn.LET(_xlpm.big,DEC2HEX(_xlfn.BITLSHIFT(M129-_xlfn.XLOOKUP(O129,Data!A:A,Data!F:F),4)+O129,8),_xlfn.CONCAT(MID(_xlpm.big,7,2),MID(_xlpm.big,5,2),MID(_xlpm.big,3,2),MID(_xlpm.big,1,2))) -> #NUM! | J129: =_xlfn.CONCAT("02",DEC2HEX(P129,2),"0000") -> 02000000 | K129: =_xlfn.LET(_xlpm.big,IF(H129,DEC2HEX(HEX2DEC(F129),8),DEC2HEX(N129-_xlfn.XLOOKUP(P129,Data!A:A,Data!F:F),8)),_xlfn.CONCAT(MID(_xlpm.big,7,2),MID(_xlpm.big,5,2),MID(_xlpm.big,3,2),MID(_xlpm.big,1,2))) -> FEFFFFFF | L129: =HEX2DEC(D129) -> 0 | M129: =HEX2DEC(E129) -> 0 | N129: =HEX2DEC(F129) -> 0 | O129: {=_xlfn.IFS(M129<Data!$F$3,0,M129<Data!$F$4,1,TRUE,2)} -> 0 | P129: {=_xlfn.IFS(H129,3,N129<Data!$F$3,0,N129<Data!$F$4,1,TRUE,2)} -> 0
G130: {=_xlfn.CONCAT(IFERROR(I130:K130,""))} -> 02000000FEFFFFFF | I130: =_xlfn.LET(_xlpm.big,DEC2HEX(_xlfn.BITLSHIFT(M130-_xlfn.XLOOKUP(O130,Data!A:A,Data!F:F),4)+O130,8),_xlfn.CONCAT(MID(_xlpm.big,7,2),MID(_xlpm.big,5,2),MID(_xlpm.big,3,2),MID(_xlpm.big,1,2))) -> #NUM! | J130: =_xlfn.CONCAT("02",DEC2HEX(P130,2),"0000") -> 02000000 | K130: =_xlfn.LET(_xlpm.big,IF(H130,DEC2HEX(HEX2DEC(F130),8),DEC2HEX(N130-_xlfn.XLOOKUP(P130,Data!A:A,Data!F:F),8)),_xlfn.CONCAT(MID(_xlpm.big,7,2),MID(_xlpm.big,5,2),MID(_xlpm.big,3,2),MID(_xlpm.big,1,2))) -> FEFFFFFF | L130: =HEX2DEC(D130) -> 0 | M130: =HEX2DEC(E130) -> 0 | N130: =HEX2DEC(F130) -> 0 | O130: {=_xlfn.IFS(M130<Data!$F$3,0,M130<Data!$F$4,1,TRUE,2)} -> 0 | P130: {=_xlfn.IFS(H130,3,N130<Data!$F$3,0,N130<Data!$F$4,1,TRUE,2)} -> 0
G131: {=_xlfn.CONCAT(IFERROR(I131:K131,""))} -> 02000000FEFFFFFF | I131: =_xlfn.LET(_xlpm.big,DEC2HEX(_xlfn.BITLSHIFT(M131-_xlfn.XLOOKUP(O131,Data!A:A,Data!F:F),4)+O131,8),_xlfn.CONCAT(MID(_xlpm.big,7,2),MID(_xlpm.big,5,2),MID(_xlpm.big,3,2),MID(_xlpm.big,1,2))) -> #NUM! | J131: =_xlfn.CONCAT("02",DEC2HEX(P131,2),"0000") -> 02000000 | K131: =_xlfn.LET(_xlpm.big,IF(H131,DEC2HEX(HEX2DEC(F131),8),DEC2HEX(N131-_xlfn.XLOOKUP(P131,Data!A:A,Data!F:F),8)),_xlfn.CONCAT(MID(_xlpm.big,7,2),MID(_xlpm.big,5,2),MID(_xlpm.big,3,2),MID(_xlpm.big,1,2))) -> FEFFFFFF | L131: =HEX2DEC(D131) -> 0 | M131: =HEX2DEC(E131) -> 0 | N131: =HEX2DEC(F131) -> 0 | O131: {=_xlfn.IFS(M131<Data!$F$3,0,M131<Data!$F$4,1,TRUE,2)} -> 0 | P131: {=_xlfn.IFS(H131,3,N131<Data!$F$3,0,N131<Data!$F$4,1,TRUE,2)} -> 0
G132: {=_xlfn.CONCAT(IFERROR(I132:K132,""))} -> 02000000FEFFFFFF | I132: =_xlfn.LET(_xlpm.big,DEC2HEX(_xlfn.BITLSHIFT(M132-_xlfn.XLOOKUP(O132,Data!A:A,Data!F:F),4)+O132,8),_xlfn.CONCAT(MID(_xlpm.big,7,2),MID(_xlpm.big,5,2),MID(_xlpm.big,3,2),MID(_xlpm.big,1,2))) -> #NUM! | J132: =_xlfn.CONCAT("02",DEC2HEX(P132,2),"0000") -> 02000000 | K132: =_xlfn.LET(_xlpm.big,IF(H132,DEC2HEX(HEX2DEC(F132),8),DEC2HEX(N132-_xlfn.XLOOKUP(P132,Data!A:A,Data!F:F),8)),_xlfn.CONCAT(MID(_xlpm.big,7,2),MID(_xlpm.big,5,2),MID(_xlpm.big,3,2),MID(_xlpm.big,1,2))) -> FEFFFFFF | L132: =HEX2DEC(D132) -> 0 | M132: =HEX2DEC(E132) -> 0 | N132: =HEX2DEC(F132) -> 0 | O132: {=_xlfn.IFS(M132<Data!$F$3,0,M132<Data!$F$4,1,TRUE,2)} -> 0 | P132: {=_xlfn.IFS(H132,3,N132<Data!$F$3,0,N132<Data!$F$4,1,TRUE,2)} -> 0
G133: {=_xlfn.CONCAT(IFERROR(I133:K133,""))} -> 02000000FEFFFFFF | I133: =_xlfn.LET(_xlpm.big,DEC2HEX(_xlfn.BITLSHIFT(M133-_xlfn.XLOOKUP(O133,Data!A:A,Data!F:F),4)+O133,8),_xlfn.CONCAT(MID(_xlpm.big,7,2),MID(_xlpm.big,5,2),MID(_xlpm.big,3,2),MID(_xlpm.big,1,2))) -> #NUM! | J133: =_xlfn.CONCAT("02",DEC2HEX(P133,2),"0000") -> 02000000 | K133: =_xlfn.LET(_xlpm.big,IF(H133,DEC2HEX(HEX2DEC(F133),8),DEC2HEX(N133-_xlfn.XLOOKUP(P133,Data!A:A,Data!F:F),8)),_xlfn.CONCAT(MID(_xlpm.big,7,2),MID(_xlpm.big,5,2),MID(_xlpm.big,3,2),MID(_xlpm.big,1,2))) -> FEFFFFFF | L133: =HEX2DEC(D133) -> 0 | M133: =HEX2DEC(E133) -> 0 | N133: =HEX2DEC(F133) -> 0 | O133: {=_xlfn.IFS(M133<Data!$F$3,0,M133<Data!$F$4,1,TRUE,2)} -> 0 | P133: {=_xlfn.IFS(H133,3,N133<Data!$F$3,0,N133<Data!$F$4,1,TRUE,2)} -> 0
G134: {=_xlfn.CONCAT(IFERROR(I134:K134,""))} -> 02000000FEFFFFFF | I134: =_xlfn.LET(_xlpm.big,DEC2HEX(_xlfn.BITLSHIFT(M134-_xlfn.XLOOKUP(O134,Data!A:A,Data!F:F),4)+O134,8),_xlfn.CONCAT(MID(_xlpm.big,7,2),MID(_xlpm.big,5,2),MID(_xlpm.big,3,2),MID(_xlpm.big,1,2))) -> #NUM! | J134: =_xlfn.CONCAT("02",DEC2HEX(P134,2),"0000") -> 02000000 | K134: =_xlfn.LET(_xlpm.big,IF(H134,DEC2HEX(HEX2DEC(F134),8),DEC2HEX(N134-_xlfn.XLOOKUP(P134,Data!A:A,Data!F:F),8)),_xlfn.CONCAT(MID(_xlpm.big,7,2),MID(_xlpm.big,5,2),MID(_xlpm.big,3,2),MID(_xlpm.big,1,2))) -> FEFFFFFF | L134: =HEX2DEC(D134) -> 0 | M134: =HEX2DEC(E134) -> 0 | N134: =HEX2DEC(F134) -> 0 | O134: {=_xlfn.IFS(M134<Data!$F$3,0,M134<Data!$F$4,1,TRUE,2)} -> 0 | P134: {=_xlfn.IFS(H134,3,N134<Data!$F$3,0,N134<Data!$F$4,1,TRUE,2)} -> 0
G135: {=_xlfn.CONCAT(IFERROR(I135:K135,""))} -> 02000000FEFFFFFF | I135: =_xlfn.LET(_xlpm.big,DEC2HEX(_xlfn.BITLSHIFT(M135-_xlfn.XLOOKUP(O135,Data!A:A,Data!F:F),4)+O135,8),_xlfn.CONCAT(MID(_xlpm.big,7,2),MID(_xlpm.big,5,2),MID(_xlpm.big,3,2),MID(_xlpm.big,1,2))) -> #NUM! | J135: =_xlfn.CONCAT("02",DEC2HEX(P135,2),"0000") -> 02000000 | K135: =_xlfn.LET(_xlpm.big,IF(H135,DEC2HEX(HEX2DEC(F135),8),DEC2HEX(N135-_xlfn.XLOOKUP(P135,Data!A:A,Data!F:F),8)),_xlfn.CONCAT(MID(_xlpm.big,7,2),MID(_xlpm.big,5,2),MID(_xlpm.big,3,2),MID(_xlpm.big,1,2))) -> FEFFFFFF | L135: =HEX2DEC(D135) -> 0 | M135: =HEX2DEC(E135) -> 0 | N135: =HEX2DEC(F135) -> 0 | O135: {=_xlfn.IFS(M135<Data!$F$3,0,M135<Data!$F$4,1,TRUE,2)} -> 0 | P135: {=_xlfn.IFS(H135,3,N135<Data!$F$3,0,N135<Data!$F$4,1,TRUE,2)} -> 0
G136: {=_xlfn.CONCAT(IFERROR(I136:K136,""))} -> 02000000FEFFFFFF | I136: =_xlfn.LET(_xlpm.big,DEC2HEX(_xlfn.BITLSHIFT(M136-_xlfn.XLOOKUP(O136,Data!A:A,Data!F:F),4)+O136,8),_xlfn.CONCAT(MID(_xlpm.big,7,2),MID(_xlpm.big,5,2),MID(_xlpm.big,3,2),MID(_xlpm.big,1,2))) -> #NUM! | J136: =_xlfn.CONCAT("02",DEC2HEX(P136,2),"0000") -> 02000000 | K136: =_xlfn.LET(_xlpm.big,IF(H136,DEC2HEX(HEX2DEC(F136),8),DEC2HEX(N136-_xlfn.XLOOKUP(P136,Data!A:A,Data!F:F),8)),_xlfn.CONCAT(MID(_xlpm.big,7,2),MID(_xlpm.big,5,2),MID(_xlpm.big,3,2),MID(_xlpm.big,1,2))) -> FEFFFFFF | L136: =HEX2DEC(D136) -> 0 | M136: =HEX2DEC(E136) -> 0 | N136: =HEX2DEC(F136) -> 0 | O136: {=_xlfn.IFS(M136<Data!$F$3,0,M136<Data!$F$4,1,TRUE,2)} -> 0 | P136: {=_xlfn.IFS(H136,3,N136<Data!$F$3,0,N136<Data!$F$4,1,TRUE,2)} -> 0
G137: {=_xlfn.CONCAT(IFERROR(I137:K137,""))} -> 02000000FEFFFFFF | I137: =_xlfn.LET(_xlpm.big,DEC2HEX(_xlfn.BITLSHIFT(M137-_xlfn.XLOOKUP(O137,Data!A:A,Data!F:F),4)+O137,8),_xlfn.CONCAT(MID(_xlpm.big,7,2),MID(_xlpm.big,5,2),MID(_xlpm.big,3,2),MID(_xlpm.big,1,2))) -> #NUM! | J137: =_xlfn.CONCAT("02",DEC2HEX(P137,2),"0000") -> 02000000 | K137: =_xlfn.LET(_xlpm.big,IF(H137,DEC2HEX(HEX2DEC(F137),8),DEC2HEX(N137-_xlfn.XLOOKUP(P137,Data!A:A,Data!F:F),8)),_xlfn.CONCAT(MID(_xlpm.big,7,2),MID(_xlpm.big,5,2),MID(_xlpm.big,3,2),MID(_xlpm.big,1,2))) -> FEFFFFFF | L137: =HEX2DEC(D137) -> 0 | M137: =HEX2DEC(E137) -> 0 | N137: =HEX2DEC(F137) -> 0 | O137: {=_xlfn.IFS(M137<Data!$F$3,0,M137<Data!$F$4,1,TRUE,2)} -> 0 | P137: {=_xlfn.IFS(H137,3,N137<Data!$F$3,0,N137<Data!$F$4,1,TRUE,2)} -> 0
G138: {=_xlfn.CONCAT(IFERROR(I138:K138,""))} -> 02000000FEFFFFFF | I138: =_xlfn.LET(_xlpm.big,DEC2HEX(_xlfn.BITLSHIFT(M138-_xlfn.XLOOKUP(O138,Data!A:A,Data!F:F),4)+O138,8),_xlfn.CONCAT(MID(_xlpm.big,7,2),MID(_xlpm.big,5,2),MID(_xlpm.big,3,2),MID(_xlpm.big,1,2))) -> #NUM! | J138: =_xlfn.CONCAT("02",DEC2HEX(P138,2),"0000") -> 02000000 | K138: =_xlfn.LET(_xlpm.big,IF(H138,DEC2HEX(HEX2DEC(F138),8),DEC2HEX(N138-_xlfn.XLOOKUP(P138,Data!A:A,Data!F:F),8)),_xlfn.CONCAT(MID(_xlpm.big,7,2),MID(_xlpm.big,5,2),MID(_xlpm.big,3,2),MID(_xlpm.big,1,2))) -> FEFFFFFF | L138: =HEX2DEC(D138) -> 0 | M138: =HEX2DEC(E138) -> 0 | N138: =HEX2DEC(F138) -> 0 | O138: {=_xlfn.IFS(M138<Data!$F$3,0,M138<Data!$F$4,1,TRUE,2)} -> 0 | P138: {=_xlfn.IFS(H138,3,N138<Data!$F$3,0,N138<Data!$F$4,1,TRUE,2)} -> 0
G139: {=_xlfn.CONCAT(IFERROR(I139:K139,""))} -> 02000000FEFFFFFF | I139: =_xlfn.LET(_xlpm.big,DEC2HEX(_xlfn.BITLSHIFT(M139-_xlfn.XLOOKUP(O139,Data!A:A,Data!F:F),4)+O139,8),_xlfn.CONCAT(MID(_xlpm.big,7,2),MID(_xlpm.big,5,2),MID(_xlpm.big,3,2),MID(_xlpm.big,1,2))) -> #NUM! | J139: =_xlfn.CONCAT("02",DEC2HEX(P139,2),"0000") -> 02000000 | K139: =_xlfn.LET(_xlpm.big,IF(H139,DEC2HEX(HEX2DEC(F139),8),DEC2HEX(N139-_xlfn.XLOOKUP(P139,Data!A:A,Data!F:F),8)),_xlfn.CONCAT(MID(_xlpm.big,7,2),MID(_xlpm.big,5,2),MID(_xlpm.big,3,2),MID(_xlpm.big,1,2))) -> FEFFFFFF | L139: =HEX2DEC(D139) -> 0 | M139: =HEX2DEC(E139) -> 0 | N139: =HEX2DEC(F139) -> 0 | O139: {=_xlfn.IFS(M139<Data!$F$3,0,M139<Data!$F$4,1,TRUE,2)} -> 0 | P139: {=_xlfn.IFS(H139,3,N139<Data!$F$3,0,N139<Data!$F$4,1,TRUE,2)} -> 0
G140: {=_xlfn.CONCAT(IFERROR(I140:K140,""))} -> 02000000FEFFFFFF | I140: =_xlfn.LET(_xlpm.big,DEC2HEX(_xlfn.BITLSHIFT(M140-_xlfn.XLOOKUP(O140,Data!A:A,Data!F:F),4)+O140,8),_xlfn.CONCAT(MID(_xlpm.big,7,2),MID(_xlpm.big,5,2),MID(_xlpm.big,3,2),MID(_xlpm.big,1,2))) -> #NUM! | J140: =_xlfn.CONCAT("02",DEC2HEX(P140,2),"0000") -> 02000000 | K140: =_xlfn.LET(_xlpm.big,IF(H140,DEC2HEX(HEX2DEC(F140),8),DEC2HEX(N140-_xlfn.XLOOKUP(P140,Data!A:A,Data!F:F),8)),_xlfn.CONCAT(MID(_xlpm.big,7,2),MID(_xlpm.big,5,2),MID(_xlpm.big,3,2),MID(_xlpm.big,1,2))) -> FEFFFFFF | L140: =HEX2DEC(D140) -> 0 | M140: =HEX2DEC(E140) -> 0 | N140: =HEX2DEC(F140) -> 0 | O140: {=_xlfn.IFS(M140<Data!$F$3,0,M140<Data!$F$4,1,TRUE,2)} -> 0 | P140: {=_xlfn.IFS(H140,3,N140<Data!$F$3,0,N140<Data!$F$4,1,TRUE,2)} -> 0
... G319: {=_xlfn.CONCAT(IFERROR(I319:K319,""))} -> 02000000FEFFFFFF | I319: =_xlfn.LET(_xlpm.big,DEC2HEX(_xlfn.BITLSHIFT(M319-_xlfn.XLOOKUP(O319,Data!A:A,Data!F:F),4)+O319,8),_xlfn.CONCAT(MID(_xlpm.big,7,2),MID(_xlpm.big,5,2),MID(_xlpm.big,3,2),MID(_xlpm.big,1,2))) -> #NUM! | J319: =_xlfn.CONCAT("02",DEC2HEX(P319,2),"0000") -> 02000000 | K319: =_xlfn.LET(_xlpm.big,IF(H319,DEC2HEX(HEX2DEC(F319),8),DEC2HEX(N319-_xlfn.XLOOKUP(P319,Data!A:A,Data!F:F),8)),_xlfn.CONCAT(MID(_xlpm.big,7,2),MID(_xlpm.big,5,2),MID(_xlpm.big,3,2),MID(_xlpm.big,1,2))) -> FEFFFFFF | L319: =HEX2DEC(D319) -> 0 | M319: =HEX2DEC(E319) -> 0 | N319: =HEX2DEC(F319) -> 0 | O319: {=_xlfn.IFS(M319<Data!$F$3,0,M319<Data!$F$4,1,TRUE,2)} -> 0 | P319: {=_xlfn.IFS(H319,3,N319<Data!$F$3,0,N319<Data!$F$4,1,TRUE,2)} -> 0
G320: {=_xlfn.CONCAT(IFERROR(I320:K320,""))} -> 0203000000000000 | H320: TRUE | I320: =_xlfn.LET(_xlpm.big,DEC2HEX(_xlfn.BITLSHIFT(M320-_xlfn.XLOOKUP(O320,Data!A:A,Data!F:F),4)+O320,8),_xlfn.CONCAT(MID(_xlpm.big,7,2),MID(_xlpm.big,5,2),MID(_xlpm.big,3,2),MID(_xlpm.big,1,2))) -> #NUM! | J320: =_xlfn.CONCAT("02",DEC2HEX(P320,2),"0000") -> 02030000 | K320: =_xlfn.LET(_xlpm.big,IF(H320,DEC2HEX(HEX2DEC(F320),8),DEC2HEX(N320-_xlfn.XLOOKUP(P320,Data!A:A,Data!F:F),8)),_xlfn.CONCAT(MID(_xlpm.big,7,2),MID(_xlpm.big,5,2),MID(_xlpm.big,3,2),MID(_xlpm.big,1,2))) -> 00000000 | L320: =HEX2DEC(D320) -> 0 | M320: =HEX2DEC(E320) -> 0 | N320: =HEX2DEC(F320) -> 0 | O320: {=_xlfn.IFS(M320<Data!$F$3,0,M320<Data!$F$4,1,TRUE,2)} -> 0 | P320: {=_xlfn.IFS(H320,3,N320<Data!$F$3,0,N320<Data!$F$4,1,TRUE,2)} -> 3
G321: {=_xlfn.CONCAT(IFERROR(I321:K321,""))} -> 0203000000000000 | H321: TRUE | I321: =_xlfn.LET(_xlpm.big,DEC2HEX(_xlfn.BITLSHIFT(M321-_xlfn.XLOOKUP(O321,Data!A:A,Data!F:F),4)+O321,8),_xlfn.CONCAT(MID(_xlpm.big,7,2),MID(_xlpm.big,5,2),MID(_xlpm.big,3,2),MID(_xlpm.big,1,2))) -> #NUM! | J321: =_xlfn.CONCAT("02",DEC2HEX(P321,2),"0000") -> 02030000 | K321: =_xlfn.LET(_xlpm.big,IF(H321,DEC2HEX(HEX2DEC(F321),8),DEC2HEX(N321-_xlfn.XLOOKUP(P321,Data!A:A,Data!F:F),8)),_xlfn.CONCAT(MID(_xlpm.big,7,2),MID(_xlpm.big,5,2),MID(_xlpm.big,3,2),MID(_xlpm.big,1,2))) -> 00000000 | L321: =HEX2DEC(D321) -> 0 | M321: =HEX2DEC(E321) -> 0 | N321: =HEX2DEC(F321) -> 0 | O321: {=_xlfn.IFS(M321<Data!$F$3,0,M321<Data!$F$4,1,TRUE,2)} -> 0 | P321: {=_xlfn.IFS(H321,3,N321<Data!$F$3,0,N321<Data!$F$4,1,TRUE,2)} -> 3
G322: {=_xlfn.CONCAT(IFERROR(I322:K322,""))} -> 02000000FEFFFFFF | I322: =_xlfn.LET(_xlpm.big,DEC2HEX(_xlfn.BITLSHIFT(M322-_xlfn.XLOOKUP(O322,Data!A:A,Data!F:F),4)+O322,8),_xlfn.CONCAT(MID(_xlpm.big,7,2),MID(_xlpm.big,5,2),MID(_xlpm.big,3,2),MID(_xlpm.big,1,2))) -> #NUM! | J322: =_xlfn.CONCAT("02",DEC2HEX(P322,2),"0000") -> 02000000 | K322: =_xlfn.LET(_xlpm.big,IF(H322,DEC2HEX(HEX2DEC(F322),8),DEC2HEX(N322-_xlfn.XLOOKUP(P322,Data!A:A,Data!F:F),8)),_xlfn.CONCAT(MID(_xlpm.big,7,2),MID(_xlpm.big,5,2),MID(_xlpm.big,3,2),MID(_xlpm.big,1,2))) -> FEFFFFFF | L322: =HEX2DEC(D322) -> 0 | M322: =HEX2DEC(E322) -> 0 | N322: =HEX2DEC(F322) -> 0 | O322: {=_xlfn.IFS(M322<Data!$F$3,0,M322<Data!$F$4,1,TRUE,2)} -> 0 | P322: {=_xlfn.IFS(H322,3,N322<Data!$F$3,0,N322<Data!$F$4,1,TRUE,2)} -> 0
G323: {=_xlfn.CONCAT(IFERROR(I323:K323,""))} -> 02000000FEFFFFFF | I323: =_xlfn.LET(_xlpm.big,DEC2HEX(_xlfn.BITLSHIFT(M323-_xlfn.XLOOKUP(O323,Data!A:A,Data!F:F),4)+O323,8),_xlfn.CONCAT(MID(_xlpm.big,7,2),MID(_xlpm.big,5,2),MID(_xlpm.big,3,2),MID(_xlpm.big,1,2))) -> #NUM! | J323: =_xlfn.CONCAT("02",DEC2HEX(P323,2),"0000") -> 02000000 | K323: =_xlfn.LET(_xlpm.big,IF(H323,DEC2HEX(HEX2DEC(F323),8),DEC2HEX(N323-_xlfn.XLOOKUP(P323,Data!A:A,Data!F:F),8)),_xlfn.CONCAT(MID(_xlpm.big,7,2),MID(_xlpm.big,5,2),MID(_xlpm.big,3,2),MID(_xlpm.big,1,2))) -> FEFFFFFF | L323: =HEX2DEC(D323) -> 0 | M323: =HEX2DEC(E323) -> 0 | N323: =HEX2DEC(F323) -> 0 | O323: {=_xlfn.IFS(M323<Data!$F$3,0,M323<Data!$F$4,1,TRUE,2)} -> 0 | P323: {=_xlfn.IFS(H323,3,N323<Data!$F$3,0,N323<Data!$F$4,1,TRUE,2)} -> 0
G324: {=_xlfn.CONCAT(IFERROR(I324:K324,""))} -> 02000000FEFFFFFF | I324: =_xlfn.LET(_xlpm.big,DEC2HEX(_xlfn.BITLSHIFT(M324-_xlfn.XLOOKUP(O324,Data!A:A,Data!F:F),4)+O324,8),_xlfn.CONCAT(MID(_xlpm.big,7,2),MID(_xlpm.big,5,2),MID(_xlpm.big,3,2),MID(_xlpm.big,1,2))) -> #NUM! | J324: =_xlfn.CONCAT("02",DEC2HEX(P324,2),"0000") -> 02000000 | K324: =_xlfn.LET(_xlpm.big,IF(H324,DEC2HEX(HEX2DEC(F324),8),DEC2HEX(N324-_xlfn.XLOOKUP(P324,Data!A:A,Data!F:F),8)),_xlfn.CONCAT(MID(_xlpm.big,7,2),MID(_xlpm.big,5,2),MID(_xlpm.big,3,2),MID(_xlpm.big,1,2))) -> FEFFFFFF | L324: =HEX2DEC(D324) -> 0 | M324: =HEX2DEC(E324) -> 0 | N324: =HEX2DEC(F324) -> 0 | O324: {=_xlfn.IFS(M324<Data!$F$3,0,M324<Data!$F$4,1,TRUE,2)} -> 0 | P324: {=_xlfn.IFS(H324,3,N324<Data!$F$3,0,N324<Data!$F$4,1,TRUE,2)} -> 0
G325: {=_xlfn.CONCAT(IFERROR(I325:K325,""))} -> 02000000FEFFFFFF | I325: =_xlfn.LET(_xlpm.big,DEC2HEX(_xlfn.BITLSHIFT(M325-_xlfn.XLOOKUP(O325,Data!A:A,Data!F:F),4)+O325,8),_xlfn.CONCAT(MID(_xlpm.big,7,2),MID(_xlpm.big,5,2),MID(_xlpm.big,3,2),MID(_xlpm.big,1,2))) -> #NUM! | J325: =_xlfn.CONCAT("02",DEC2HEX(P325,2),"0000") -> 02000000 | K325: =_xlfn.LET(_xlpm.big,IF(H325,DEC2HEX(HEX2DEC(F325),8),DEC2HEX(N325-_xlfn.XLOOKUP(P325,Data!A:A,Data!F:F),8)),_xlfn.CONCAT(MID(_xlpm.big,7,2),MID(_xlpm.big,5,2),MID(_xlpm.big,3,2),MID(_xlpm.big,1,2))) -> FEFFFFFF | L325: =HEX2DEC(D325) -> 0 | M325: =HEX2DEC(E325) -> 0 | N325: =HEX2DEC(F325) -> 0 | O325: {=_xlfn.IFS(M325<Data!$F$3,0,M325<Data!$F$4,1,TRUE,2)} -> 0 | P325: {=_xlfn.IFS(H325,3,N325<Data!$F$3,0,N325<Data!$F$4,1,TRUE,2)} -> 0
G326: {=_xlfn.CONCAT(IFERROR(I326:K326,""))} -> 02000000FEFFFFFF | I326: =_xlfn.LET(_xlpm.big,DEC2HEX(_xlfn.BITLSHIFT(M326-_xlfn.XLOOKUP(O326,Data!A:A,Data!F:F),4)+O326,8),_xlfn.CONCAT(MID(_xlpm.big,7,2),MID(_xlpm.big,5,2),MID(_xlpm.big,3,2),MID(_xlpm.big,1,2))) -> #NUM! | J326: =_xlfn.CONCAT("02",DEC2HEX(P326,2),"0000") -> 02000000 | K326: =_xlfn.LET(_xlpm.big,IF(H326,DEC2HEX(HEX2DEC(F326),8),DEC2HEX(N326-_xlfn.XLOOKUP(P326,Data!A:A,Data!F:F),8)),_xlfn.CONCAT(MID(_xlpm.big,7,2),MID(_xlpm.big,5,2),MID(_xlpm.big,3,2),MID(_xlpm.big,1,2))) -> FEFFFFFF | L326: =HEX2DEC(D326) -> 0 | M326: =HEX2DEC(E326) -> 0 | N326: =HEX2DEC(F326) -> 0 | O326: {=_xlfn.IFS(M326<Data!$F$3,0,M326<Data!$F$4,1,TRUE,2)} -> 0 | P326: {=_xlfn.IFS(H326,3,N326<Data!$F$3,0,N326<Data!$F$4,1,TRUE,2)} -> 0
G327: {=_xlfn.CONCAT(IFERROR(I327:K327,""))} -> 02000000FEFFFFFF | I327: =_xlfn.LET(_xlpm.big,DEC2HEX(_xlfn.BITLSHIFT(M327-_xlfn.XLOOKUP(O327,Data!A:A,Data!F:F),4)+O327,8),_xlfn.CONCAT(MID(_xlpm.big,7,2),MID(_xlpm.big,5,2),MID(_xlpm.big,3,2),MID(_xlpm.big,1,2))) -> #NUM! | J327: =_xlfn.CONCAT("02",DEC2HEX(P327,2),"0000") -> 02000000 | K327: =_xlfn.LET(_xlpm.big,IF(H327,DEC2HEX(HEX2DEC(F327),8),DEC2HEX(N327-_xlfn.XLOOKUP(P327,Data!A:A,Data!F:F),8)),_xlfn.CONCAT(MID(_xlpm.big,7,2),MID(_xlpm.big,5,2),MID(_xlpm.big,3,2),MID(_xlpm.big,1,2))) -> FEFFFFFF | L327: =HEX2DEC(D327) -> 0 | M327: =HEX2DEC(E327) -> 0 | N327: =HEX2DEC(F327) -> 0 | O327: {=_xlfn.IFS(M327<Data!$F$3,0,M327<Data!$F$4,1,TRUE,2)} -> 0 | P327: {=_xlfn.IFS(H327,3,N327<Data!$F$3,0,N327<Data!$F$4,1,TRUE,2)} -> 0
G328: {=_xlfn.CONCAT(IFERROR(I328:K328,""))} -> 02000000FEFFFFFF | I328: =_xlfn.LET(_xlpm.big,DEC2HEX(_xlfn.BITLSHIFT(M328-_xlfn.XLOOKUP(O328,Data!A:A,Data!F:F),4)+O328,8),_xlfn.CONCAT(MID(_xlpm.big,7,2),MID(_xlpm.big,5,2),MID(_xlpm.big,3,2),MID(_xlpm.big,1,2))) -> #NUM! | J328: =_xlfn.CONCAT("02",DEC2HEX(P328,2),"0000") -> 02000000 | K328: =_xlfn.LET(_xlpm.big,IF(H328,DEC2HEX(HEX2DEC(F328),8),DEC2HEX(N328-_xlfn.XLOOKUP(P328,Data!A:A,Data!F:F),8)),_xlfn.CONCAT(MID(_xlpm.big,7,2),MID(_xlpm.big,5,2),MID(_xlpm.big,3,2),MID(_xlpm.big,1,2))) -> FEFFFFFF | L328: =HEX2DEC(D328) -> 0 | M328: =HEX2DEC(E328) -> 0 | N328: =HEX2DEC(F328) -> 0 | O328: {=_xlfn.IFS(M328<Data!$F$3,0,M328<Data!$F$4,1,TRUE,2)} -> 0 | P328: {=_xlfn.IFS(H328,3,N328<Data!$F$3,0,N328<Data!$F$4,1,TRUE,2)} -> 0
G329: {=_xlfn.CONCAT(IFERROR(I329:K329,""))} -> 02000000FEFFFFFF | I329: =_xlfn.LET(_xlpm.big,DEC2HEX(_xlfn.BITLSHIFT(M329-_xlfn.XLOOKUP(O329,Data!A:A,Data!F:F),4)+O329,8),_xlfn.CONCAT(MID(_xlpm.big,7,2),MID(_xlpm.big,5,2),MID(_xlpm.big,3,2),MID(_xlpm.big,1,2))) -> #NUM! | J329: =_xlfn.CONCAT("02",DEC2HEX(P329,2),"0000") -> 02000000 | K329: =_xlfn.LET(_xlpm.big,IF(H329,DEC2HEX(HEX2DEC(F329),8),DEC2HEX(N329-_xlfn.XLOOKUP(P329,Data!A:A,Data!F:F),8)),_xlfn.CONCAT(MID(_xlpm.big,7,2),MID(_xlpm.big,5,2),MID(_xlpm.big,3,2),MID(_xlpm.big,1,2))) -> FEFFFFFF | L329: =HEX2DEC(D329) -> 0 | M329: =HEX2DEC(E329) -> 0 | N329: =HEX2DEC(F329) -> 0 | O329: {=_xlfn.IFS(M329<Data!$F$3,0,M329<Data!$F$4,1,TRUE,2)} -> 0 | P329: {=_xlfn.IFS(H329,3,N329<Data!$F$3,0,N329<Data!$F$4,1,TRUE,2)} -> 0
G330: {=_xlfn.CONCAT(IFERROR(I330:K330,""))} -> 02000000FEFFFFFF | I330: =_xlfn.LET(_xlpm.big,DEC2HEX(_xlfn.BITLSHIFT(M330-_xlfn.XLOOKUP(O330,Data!A:A,Data!F:F),4)+O330,8),_xlfn.CONCAT(MID(_xlpm.big,7,2),MID(_xlpm.big,5,2),MID(_xlpm.big,3,2),MID(_xlpm.big,1,2))) -> #NUM! | J330: =_xlfn.CONCAT("02",DEC2HEX(P330,2),"0000") -> 02000000 | K330: =_xlfn.LET(_xlpm.big,IF(H330,DEC2HEX(HEX2DEC(F330),8),DEC2HEX(N330-_xlfn.XLOOKUP(P330,Data!A:A,Data!F:F),8)),_xlfn.CONCAT(MID(_xlpm.big,7,2),MID(_xlpm.big,5,2),MID(_xlpm.big,3,2),MID(_xlpm.big,1,2))) -> FEFFFFFF | L330: =HEX2DEC(D330) -> 0 | M330: =HEX2DEC(E330) -> 0 | N330: =HEX2DEC(F330) -> 0 | O330: {=_xlfn.IFS(M330<Data!$F$3,0,M330<Data!$F$4,1,TRUE,2)} -> 0 | P330: {=_xlfn.IFS(H330,3,N330<Data!$F$3,0,N330<Data!$F$4,1,TRUE,2)} -> 0
...

Sheet Data
A1: Segment | C1: Address | D1: Hex LE | E1: Hex BE | F1: Dec | H1: Segment Table Address (little-Endian): | I1: 00900100 | L1: Big-End | M1: =MID(I1,7,)&MID(I1,5,2)&MID(I1,3,2)&MID(I1,1,2) -> 019000
A2: 0 | B2: code | C2: =DEC2HEX(8+HEX2DEC(M$1),8) -> 00019008 | D2: =MID(J$5,1,8) -> 80010000 | E2: =_xlfn.CONCAT(MID(D2,7,2),MID(D2,5,2),MID(D2,3,2),MID(D2,1,2)) -> 00000180 | F2: =HEX2DEC(E2) -> 384 | H2: Located at 0x84 | L2: Decimal | M2: =HEX2DEC(M1) -> 102400
A3: 1 | B3: rodata | C3: =DEC2HEX(20+HEX2DEC(M$1),8) -> 00019014 | D3: =MID(J$5,25,8) -> 00700100 | E3: =_xlfn.CONCAT(MID(D3,7,2),MID(D3,5,2),MID(D3,3,2),MID(D3,1,2)) -> 00017000 | F3: =HEX2DEC(E3) -> 94208 | H3: RPT Table address at 0x128 | I3: 74040200 | L3: Dif from original | M3: =M2-1097728 -> -995328
A4: 2 | B4: data | C4: =DEC2HEX(32+HEX2DEC(M$1),8) -> 00019020 | D4: =MID(J$5,49,8) -> 342D0200 | E4: =_xlfn.CONCAT(MID(D4,7,2),MID(D4,5,2),MID(D4,3,2),MID(D4,1,2)) -> 00022D34 | F4: =HEX2DEC(E4) -> 142644 | L4: hex | M4: =DEC2HEX(M3) -> FFFFF0D000
A5: 3 | B5: bss | C5: =DEC2HEX(48+HEX2DEC(M$1),8) -> 00019030 | D5: =MID(J$5,81,8) -> 20000000 | E5: =_xlfn.CONCAT(MID(D5,7,2),MID(D5,5,2),MID(D5,3,2),MID(D5,1,2)) -> 00000020 | F5: =HEX2DEC(E5) -> 32 | H5: =_xlfn.CONCAT("Paste the block from 0x",C2," to 0x",DEC2HEX(HEX2DEC(C5)+3,8)," here:") -> Paste the block from 0x00019008 to 0x00019033 here: | I5: 80 01 00 00 7C 6C 01 00 00 00 00 00 00 70 01 00 0C 10 00 00 01 00 00 00 34 2D 02 00 CC 12 00 00 02 00 00 00 00 00 00 00 20 00 00 00 | J5: =SUBSTITUTE(I5," ","") -> 800100007C6C010000000000007001000C10000001000000342D0200CC120000020000000000000020000000 | K5: =IF(LEN(J5)=88,"Length Good","Length Mismatch") -> Length Good
B6: RPT Start | D6: =I3 -> 74040200 | E6: =_xlfn.CONCAT(MID(D6,7,2),MID(D6,5,2),MID(D6,3,2),MID(D6,1,2)) -> 00020474 | F6: =HEX2DEC(E6) -> 132212
B7: RPT End | D7: =_xlfn.CONCAT(MID(E7,7,2),MID(E7,5,2),MID(E7,3,2),MID(E7,1,2)) -> 401D0200 | E7: =DEC2HEX(F7,8) -> 00021D40 | F7: =MAX('Custom Relocation Patches'!L:L)+12 -> 138560
F9: =F7-F6 -> 6348
F10: =F9/12 -> 529
F11: =DEC2HEX(F10) -> 211
H13: First Patch in unedited: | I13: 00DB03000203000084030000

Sheet Reverse Patch
A1: Paste Patch Hex: | B1: 80 C5 15 00 02 01 00 00 0C 10 00 00
A3: Removed whitespace | B3: =SUBSTITUTE(B1," ","") -> 80C51500020100000C100000
B4: 40A687000203000094030000
A5: Patch Type | B5: =MID(B3,9,2) -> 02
A7: Relative Write-to | B7: =DEC2HEX(_xlfn.BITRSHIFT(HEX2DEC(_xlfn.LET(_xlpm.in,LEFT(B3,8),_xlfn.CONCAT(MID(_xlpm.in,7,2),MID(_xlpm.in,5,2),MID(_xlpm.in,3,2),MID(_xlpm.in,1,2)))),4),7) -> 0015C58
A8: Write Segment | B8: =DEC2HEX(_xlfn.BITAND(15,HEX2DEC(_xlfn.LET(_xlpm.in,LEFT(B3,8),_xlfn.CONCAT(MID(_xlpm.in,7,2),MID(_xlpm.in,5,2),MID(_xlpm.in,3,2),MID(_xlpm.in,1,2))))),1) -> 0
A10: Relative Pointer | B10: =_xlfn.LET(_xlpm.in,RIGHT(B3,8),_xlfn.CONCAT(MID(_xlpm.in,7,2),MID(_xlpm.in,5,2),MID(_xlpm.in,3,2),MID(_xlpm.in,1,2))) -> 0000100C
A11: Pointer Segment | B11: =MID(B3,11,2) -> 01
A13: In-File Write-To | B13: In-File Pointer
A14: =DEC2HEX(HEX2DEC(B7)+_xlfn.XLOOKUP(VALUE(B8),Data!A:A,Data!F:F),8) -> 00015DD8 | B14: =IF(B11="03",B10,DEC2HEX(HEX2DEC(B10)+_xlfn.XLOOKUP(VALUE(B11),Data!A:A,Data!F:F),8)) -> 0001800C
A15: ^Column E | B15: ^Column F
