Workbook

Sheet Edit
A1: Address | B1: Hex | C1: instruction | D1: notes
A2: Call Function
A3: 000FCF48 | B3: =_xlfn.CONCAT("0",RIGHT(C3,1),"10A0E3") -> 0110A0E3 | C3: mov r1, 0x1
A4: =DEC2HEX(HEX2DEC(A3)+4,8) -> 000FCF4C | B4: 001080E5 | C4: str r1, [r0]
A5: =DEC2HEX(HEX2DEC(A4)+4,8) -> 000FCF50 | B5: 00009FE5 | C5: ldr r0, [pc]
A6: =DEC2HEX(HEX2DEC(A5)+4,8) -> 000FCF54 | B6: 1EFF2FE1 | C6: bx lr
A7: =DEC2HEX(HEX2DEC(A6)+4,8) -> 000FCF58 | B7: 00000000 | C7: andeq r0, r0, r0
A9: Remove Item 0xBF
A10: 000FF9A4 | B10: F0412DE9 | C10: push {r4, r5, r6, r7, r8, lr}
A11: =DEC2HEX(HEX2DEC(A10)+4,8) -> 000FF9A8 | B11: 0260A0E1 | C11: mov r6, r2
A12: =DEC2HEX(HEX2DEC(A11)+4,8) -> 000FF9AC | B12: 0180A0E1 | C12: mov r8, r1
A13: =DEC2HEX(HEX2DEC(A12)+4,8) -> 000FF9B0 | B13: 0300A0E3 | C13: mov r0, #3
A14: =DEC2HEX(HEX2DEC(A13)+4,8) -> 000FF9B4 | B14: 6720FEEB | C14: bl #0x87b58
A15: =DEC2HEX(HEX2DEC(A14)+4,8) -> 000FF9B8 | B15: 060050E1 | C15: cmp r0, r6
A16: =DEC2HEX(HEX2DEC(A15)+4,8) -> 000FF9BC | B16: 1200001A | C16: =_xlfn.CONCAT("bne 0x",A$57) -> bne 0x000FFA60
A17: =DEC2HEX(HEX2DEC(A16)+4,8) -> 000FF9C0 | B17: 0600A0E3 | C17: mov r0, #6
A18: =DEC2HEX(HEX2DEC(A17)+4,8) -> 000FF9C4 | B18: 6320FEEB | C18: bl #0x87b58
A19: =DEC2HEX(HEX2DEC(A18)+4,8) -> 000FF9C8 | B19: FF5000E2 | C19: and r5, r0, #0xff
A20: =DEC2HEX(HEX2DEC(A19)+4,8) -> 000FF9CC | B20: 0520A0E1 | C20: mov r2, r5
A21: =DEC2HEX(HEX2DEC(A20)+4,8) -> 000FF9D0 | B21: 0610A0E1 | C21: mov r1, r6
A22: =DEC2HEX(HEX2DEC(A21)+4,8) -> 000FF9D4 | B22: 0800A0E1 | C22: mov r0, r8
A23: =DEC2HEX(HEX2DEC(A22)+4,8) -> 000FF9D8 | B23: 7F82FDEB | C23: bl #0x603dc
A24: =DEC2HEX(HEX2DEC(A23)+4,8) -> 000FF9DC | B24: 000050E3 | C24: cmp r0, #0
A25: =DEC2HEX(HEX2DEC(A24)+4,8) -> 000FF9E0 | B25: 0900001A | C25: =_xlfn.CONCAT("bne 0x",A$57) -> bne 0x000FFA60
A26: =DEC2HEX(HEX2DEC(A25)+4,8) -> 000FF9E4 | B26: 0510A0E1 | C26: mov r1, r5
A27: =DEC2HEX(HEX2DEC(A26)+4,8) -> 000FF9E8 | B27: 0800A0E1 | C27: mov r0, r8
A28: =DEC2HEX(HEX2DEC(A27)+4,8) -> 000FF9EC | B28: 294AFEEB | C28: bl #0x92298
A29: =DEC2HEX(HEX2DEC(A28)+4,8) -> 000FF9F0 | B29: B201D0E1 | C29: ldrh r0, [r0, #0x12]
A30: =DEC2HEX(HEX2DEC(A29)+4,8) -> 000FF9F4 | B30: 0070B0E1 | C30: movs r7, r0
A31: =DEC2HEX(HEX2DEC(A30)+4,8) -> 000FF9F8 | B31: 0300001A | C31: =_xlfn.CONCAT("bne 0x",A$57) -> bne 0x000FFA60
A32: =DEC2HEX(HEX2DEC(A31)+4,8) -> 000FF9FC | B32: 0620A0E1 | C32: mov r2, r6
A33: =DEC2HEX(HEX2DEC(A32)+4,8) -> 000FFA00 | B33: 2410A0E3 | C33: mov r1, #0x24
A34: =DEC2HEX(HEX2DEC(A33)+4,8) -> 000FFA04 | B34: 0800A0E1 | C34: mov r0, r8
A35: =DEC2HEX(HEX2DEC(A34)+4,8) -> 000FFA08 | B35: 3A1FFEEB | C35: bl #0x876f8
A36: =DEC2HEX(HEX2DEC(A35)+4,8) -> 000FFA0C | B36: 0040A0E1 | C36: mov r4, r0
A37: =DEC2HEX(HEX2DEC(A36)+4,8) -> 000FFA10 | B37: 0000A0E3 | C37: mov r0, #0
A38: =DEC2HEX(HEX2DEC(A37)+4,8) -> 000FFA14 | B38: 0650C4E5 | C38: strb r5, [r4, #6]
A39: =DEC2HEX(HEX2DEC(A38)+4,8) -> 000FFA18 | B39: B400C4E1 | C39: strh r0, [r4, #4]
A40: =DEC2HEX(HEX2DEC(A39)+4,8) -> 000FFA1C | B40: 40209FE5 | C40: ldr r2, [pc, #0x40]
A41: =DEC2HEX(HEX2DEC(A40)+4,8) -> 000FFA20 | B41: 0210A0E3 | C41: mov r1, #2
...

Sheet Sheet1
A1: Address | B1: Hex | H1: 76 00 D6 00 A5 00 12 01 7F 01 7E 01 77 00 0B 01 C0 01 A6 00 66 00 44 00 F3 00 B6 00 C5 00 CB 00 C2 00 90 00 0A 01 DC 01 08 01 21 01 0E 01 A8 00 57 01 0F 01 9F 01 6C 01 FF 01 04 02 22 02 23 02 24 02 29 02 2A 02 2B 02 2D 02 AD 00 F5 01 D5 01 EF 01 4F 02 50 02 51 02 66 02 67 02 32 02 69 02 31 02 42 02 4C 02 54 02 5E 02 5F 02 6A 02 6B 02 6C 02 6D 02 D1 02 D0 02 D2 02 6E 02 6F 02 70 02 71 02 72 02 73 02 74 02 75 02 76 02 77 02 78 02 79 02 7A 02 7B 02 7C 02 7D 02 7E 02 7F 02 80 02 81 02 82 02 83 02 84 02 85 02 86 02 87 02 88 02 89 02 8A 02 8B 02 8C 02 8D 02 8E 02 8F 02 90 02 91 02 92 02 B7 02 B8 02 B9 02 BA 02 BB 02 BC 02 BD 02 BE 02 BF 02 CF 02 D7 02 D3 02 D4 02 D5 02 D6 02 D8 02 9F 02 C0 02 B2 02 95 02 B1 02 C1 02 C8 02 | I1: =SUBSTITUTE(H1," ","") -> 7600D600A50012017F017E0177000B01C001A60066004400F300B600C500CB00C20090000A01DC01080121010E01A80057010F019F016C01FF01040222022302240229022A022B022D02AD00F501D501EF014F02500251026602670232026902310242024C0254025E025F026A026B026C026D02D102D002D2026E026F0270027102720273027402750276027702780279027A027B027C027D027E027F0280028102820283028402850286028702880289028A028B028C028D028E028F02900291029202B702B802B902BA02BB02BC02BD02BE02BF02CF02D702D302D402D502D602D8029F02C002B2029502B102C102C802 | J1: =LEN(I1) -> 484 | L1: =_xlfn.CONCAT(E:E) -> 7600D600A50012017F017E0177006202CE00A60066004400F300B600C500CB00C20090000A01DC01080121010E01A80057010F019F016C01FF01AD00F501D501EF01310242024C0254026E026F0270027102720273027402750276027702780279027A027B027C027D027E027F0280028102820283028402850286028702880289028A028B028C028D028E028F02900291029202B702B802B902BA02BB02BC02BD02BE02BF02CF02D702D302D402D502D602D8029F02C002B2029502B10200000000000000000000000000000000000000000000000000000000000000000000000000000000000000000000000000000000 | M1: =LEN(L1) -> 484
A2: 001096AA | B2: =MID($I$1,1+(ROW(B2)-2)*4,4) -> 7600 | C2: =_xlfn.XLOOKUP(B2,Sheet2!C:C,Sheet2!B:B) -> Metronome | E2: =IF(D2="",B2,_xlfn.XLOOKUP(D2,Sheet2!B:B,Sheet2!C:C)) -> 7600
A3: =DEC2HEX(HEX2DEC(A2)+2,8) -> 001096AC | B3: =MID($I$1,1+(ROW(B3)-2)*4,4) -> D600 | C3: =_xlfn.XLOOKUP(B3,Sheet2!C:C,Sheet2!B:B) -> Sleep Talk | E3: =IF(D3="",B3,_xlfn.XLOOKUP(D3,Sheet2!B:B,Sheet2!C:C)) -> D600
A4: =DEC2HEX(HEX2DEC(A3)+2,8) -> 001096AE | B4: =MID($I$1,1+(ROW(B4)-2)*4,4) -> A500 | C4: =_xlfn.XLOOKUP(B4,Sheet2!C:C,Sheet2!B:B) -> Struggle | E4: =IF(D4="",B4,_xlfn.XLOOKUP(D4,Sheet2!B:B,Sheet2!C:C)) -> A500
A5: =DEC2HEX(HEX2DEC(A4)+2,8) -> 001096B0 | B5: =MID($I$1,1+(ROW(B5)-2)*4,4) -> 1201 | C5: =_xlfn.XLOOKUP(B5,Sheet2!C:C,Sheet2!B:B) -> Assist | E5: =IF(D5="",B5,_xlfn.XLOOKUP(D5,Sheet2!B:B,Sheet2!C:C)) -> 1201
A6: =DEC2HEX(HEX2DEC(A5)+2,8) -> 001096B2 | B6: =MID($I$1,1+(ROW(B6)-2)*4,4) -> 7F01 | C6: =_xlfn.XLOOKUP(B6,Sheet2!C:C,Sheet2!B:B) -> Copycat | E6: =IF(D6="",B6,_xlfn.XLOOKUP(D6,Sheet2!B:B,Sheet2!C:C)) -> 7F01
A7: =DEC2HEX(HEX2DEC(A6)+2,8) -> 001096B4 | B7: =MID($I$1,1+(ROW(B7)-2)*4,4) -> 7E01 | C7: =_xlfn.XLOOKUP(B7,Sheet2!C:C,Sheet2!B:B) -> Me First | E7: =IF(D7="",B7,_xlfn.XLOOKUP(D7,Sheet2!B:B,Sheet2!C:C)) -> 7E01
A8: =DEC2HEX(HEX2DEC(A7)+2,8) -> 001096B6 | B8: =MID($I$1,1+(ROW(B8)-2)*4,4) -> 7700 | C8: =_xlfn.XLOOKUP(B8,Sheet2!C:C,Sheet2!B:B) -> Mirror Move | E8: =IF(D8="",B8,_xlfn.XLOOKUP(D8,Sheet2!B:B,Sheet2!C:C)) -> 7700
A9: =DEC2HEX(HEX2DEC(A8)+2,8) -> 001096B8 | B9: =MID($I$1,1+(ROW(B9)-2)*4,4) -> 0B01 | C9: =_xlfn.XLOOKUP(B9,Sheet2!C:C,Sheet2!B:B) -> Nature Power | D9: Hold Back | E9: =IF(D9="",B9,_xlfn.XLOOKUP(D9,Sheet2!B:B,Sheet2!C:C)) -> 6202
A10: =DEC2HEX(HEX2DEC(A9)+2,8) -> 001096BA | B10: =MID($I$1,1+(ROW(B10)-2)*4,4) -> C001 | C10: =_xlfn.XLOOKUP(B10,Sheet2!C:C,Sheet2!B:B) -> Chatter | D10: False Swipe | E10: =IF(D10="",B10,_xlfn.XLOOKUP(D10,Sheet2!B:B,Sheet2!C:C)) -> CE00
A11: =DEC2HEX(HEX2DEC(A10)+2,8) -> 001096BC | B11: =MID($I$1,1+(ROW(B11)-2)*4,4) -> A600 | C11: =_xlfn.XLOOKUP(B11,Sheet2!C:C,Sheet2!B:B) -> Sketch | E11: =IF(D11="",B11,_xlfn.XLOOKUP(D11,Sheet2!B:B,Sheet2!C:C)) -> A600
A12: =DEC2HEX(HEX2DEC(A11)+2,8) -> 001096BE | B12: =MID($I$1,1+(ROW(B12)-2)*4,4) -> 6600 | C12: =_xlfn.XLOOKUP(B12,Sheet2!C:C,Sheet2!B:B) -> Mimic | E12: =IF(D12="",B12,_xlfn.XLOOKUP(D12,Sheet2!B:B,Sheet2!C:C)) -> 6600
A13: =DEC2HEX(HEX2DEC(A12)+2,8) -> 001096C0 | B13: =MID($I$1,1+(ROW(B13)-2)*4,4) -> 4400 | C13: =_xlfn.XLOOKUP(B13,Sheet2!C:C,Sheet2!B:B) -> Counter | E13: =IF(D13="",B13,_xlfn.XLOOKUP(D13,Sheet2!B:B,Sheet2!C:C)) -> 4400
A14: =DEC2HEX(HEX2DEC(A13)+2,8) -> 001096C2 | B14: =MID($I$1,1+(ROW(B14)-2)*4,4) -> F300 | C14: =_xlfn.XLOOKUP(B14,Sheet2!C:C,Sheet2!B:B) -> Mirror Coat | E14: =IF(D14="",B14,_xlfn.XLOOKUP(D14,Sheet2!B:B,Sheet2!C:C)) -> F300
A15: =DEC2HEX(HEX2DEC(A14)+2,8) -> 001096C4 | B15: =MID($I$1,1+(ROW(B15)-2)*4,4) -> B600 | C15: =_xlfn.XLOOKUP(B15,Sheet2!C:C,Sheet2!B:B) -> Protect | E15: =IF(D15="",B15,_xlfn.XLOOKUP(D15,Sheet2!B:B,Sheet2!C:C)) -> B600
A16: =DEC2HEX(HEX2DEC(A15)+2,8) -> 001096C6 | B16: =MID($I$1,1+(ROW(B16)-2)*4,4) -> C500 | C16: =_xlfn.XLOOKUP(B16,Sheet2!C:C,Sheet2!B:B) -> Detect | E16: =IF(D16="",B16,_xlfn.XLOOKUP(D16,Sheet2!B:B,Sheet2!C:C)) -> C500
A17: =DEC2HEX(HEX2DEC(A16)+2,8) -> 001096C8 | B17: =MID($I$1,1+(ROW(B17)-2)*4,4) -> CB00 | C17: =_xlfn.XLOOKUP(B17,Sheet2!C:C,Sheet2!B:B) -> Endure | E17: =IF(D17="",B17,_xlfn.XLOOKUP(D17,Sheet2!B:B,Sheet2!C:C)) -> CB00
A18: =DEC2HEX(HEX2DEC(A17)+2,8) -> 001096CA | B18: =MID($I$1,1+(ROW(B18)-2)*4,4) -> C200 | C18: =_xlfn.XLOOKUP(B18,Sheet2!C:C,Sheet2!B:B) -> Destiny Bond | E18: =IF(D18="",B18,_xlfn.XLOOKUP(D18,Sheet2!B:B,Sheet2!C:C)) -> C200
A19: =DEC2HEX(HEX2DEC(A18)+2,8) -> 001096CC | B19: =MID($I$1,1+(ROW(B19)-2)*4,4) -> 9000 | C19: =_xlfn.XLOOKUP(B19,Sheet2!C:C,Sheet2!B:B) -> Transform | E19: =IF(D19="",B19,_xlfn.XLOOKUP(D19,Sheet2!B:B,Sheet2!C:C)) -> 9000
A20: =DEC2HEX(HEX2DEC(A19)+2,8) -> 001096CE | B20: =MID($I$1,1+(ROW(B20)-2)*4,4) -> 0A01 | C20: =_xlfn.XLOOKUP(B20,Sheet2!C:C,Sheet2!B:B) -> Follow Me | E20: =IF(D20="",B20,_xlfn.XLOOKUP(D20,Sheet2!B:B,Sheet2!C:C)) -> 0A01
A21: =DEC2HEX(HEX2DEC(A20)+2,8) -> 001096D0 | B21: =MID($I$1,1+(ROW(B21)-2)*4,4) -> DC01 | C21: =_xlfn.XLOOKUP(B21,Sheet2!C:C,Sheet2!B:B) -> Rage Powder | E21: =IF(D21="",B21,_xlfn.XLOOKUP(D21,Sheet2!B:B,Sheet2!C:C)) -> DC01
A22: =DEC2HEX(HEX2DEC(A21)+2,8) -> 001096D2 | B22: =MID($I$1,1+(ROW(B22)-2)*4,4) -> 0801 | C22: =_xlfn.XLOOKUP(B22,Sheet2!C:C,Sheet2!B:B) -> Focus Punch | E22: =IF(D22="",B22,_xlfn.XLOOKUP(D22,Sheet2!B:B,Sheet2!C:C)) -> 0801
... A30: =DEC2HEX(HEX2DEC(A29)+2,8) -> 001096E2 | B30: =MID($I$1,1+(ROW(B30)-2)*4,4) -> FF01 | C30: =_xlfn.XLOOKUP(B30,Sheet2!C:C,Sheet2!B:B) -> Quash | E30: =IF(D30="",B30,_xlfn.XLOOKUP(D30,Sheet2!B:B,Sheet2!C:C)) -> FF01
A31: =DEC2HEX(HEX2DEC(A30)+2,8) -> 001096E4 | B31: =MID($I$1,1+(ROW(B31)-2)*4,4) -> 0402 | C31: =_xlfn.XLOOKUP(B31,Sheet2!C:C,Sheet2!B:B) -> Psycho Cannon | D31: =C39 -> Snore | E31: =IF(D31="",B31,_xlfn.XLOOKUP(D31,Sheet2!B:B,Sheet2!C:C)) -> AD00
A32: =DEC2HEX(HEX2DEC(A31)+2,8) -> 001096E6 | B32: =MID($I$1,1+(ROW(B32)-2)*4,4) -> 2202 | C32: =_xlfn.XLOOKUP(B32,Sheet2!C:C,Sheet2!B:B) -> Techno Blast | D32: =C40 -> Quick Guard | E32: =IF(D32="",B32,_xlfn.XLOOKUP(D32,Sheet2!B:B,Sheet2!C:C)) -> F501
A33: =DEC2HEX(HEX2DEC(A32)+2,8) -> 001096E8 | B33: =MID($I$1,1+(ROW(B33)-2)*4,4) -> 2302 | C33: =_xlfn.XLOOKUP(B33,Sheet2!C:C,Sheet2!B:B) -> Relic Song | D33: =C41 -> Wide Guard | E33: =IF(D33="",B33,_xlfn.XLOOKUP(D33,Sheet2!B:B,Sheet2!C:C)) -> D501
A34: =DEC2HEX(HEX2DEC(A33)+2,8) -> 001096EA | B34: =MID($I$1,1+(ROW(B34)-2)*4,4) -> 2402 | C34: =_xlfn.XLOOKUP(B34,Sheet2!C:C,Sheet2!B:B) -> Secret Sword | D34: =C42 -> After You | E34: =IF(D34="",B34,_xlfn.XLOOKUP(D34,Sheet2!B:B,Sheet2!C:C)) -> EF01
A35: =DEC2HEX(HEX2DEC(A34)+2,8) -> 001096EC | B35: =MID($I$1,1+(ROW(B35)-2)*4,4) -> 2902 | C35: =_xlfn.XLOOKUP(B35,Sheet2!C:C,Sheet2!B:B) -> Freeze Shock | D35: =C50 -> Mat Block | E35: =IF(D35="",B35,_xlfn.XLOOKUP(D35,Sheet2!B:B,Sheet2!C:C)) -> 3102
A36: =DEC2HEX(HEX2DEC(A35)+2,8) -> 001096EE | B36: =MID($I$1,1+(ROW(B36)-2)*4,4) -> 2A02 | C36: =_xlfn.XLOOKUP(B36,Sheet2!C:C,Sheet2!B:B) -> Ice Burn | D36: =C51 -> Crafty Shield | E36: =IF(D36="",B36,_xlfn.XLOOKUP(D36,Sheet2!B:B,Sheet2!C:C)) -> 4202
A37: =DEC2HEX(HEX2DEC(A36)+2,8) -> 001096F0 | B37: =MID($I$1,1+(ROW(B37)-2)*4,4) -> 2B02 | C37: =_xlfn.XLOOKUP(B37,Sheet2!C:C,Sheet2!B:B) -> Snarl | D37: =C52 -> King’s Shield | E37: =IF(D37="",B37,_xlfn.XLOOKUP(D37,Sheet2!B:B,Sheet2!C:C)) -> 4C02
A38: =DEC2HEX(HEX2DEC(A37)+2,8) -> 001096F2 | B38: =MID($I$1,1+(ROW(B38)-2)*4,4) -> 2D02 | C38: =_xlfn.XLOOKUP(B38,Sheet2!C:C,Sheet2!B:B) -> V-create | D38: =C53 -> Spiky Shield | E38: =IF(D38="",B38,_xlfn.XLOOKUP(D38,Sheet2!B:B,Sheet2!C:C)) -> 5402
A39: =DEC2HEX(HEX2DEC(A38)+2,8) -> 001096F4 | B39: =MID($I$1,1+(ROW(B39)-2)*4,4) -> AD00 | C39: =_xlfn.XLOOKUP(B39,Sheet2!C:C,Sheet2!B:B) -> Snore | D39: =C63 -> Breakneck Blitz | E39: =IF(D39="",B39,_xlfn.XLOOKUP(D39,Sheet2!B:B,Sheet2!C:C)) -> 6E02
A40: =DEC2HEX(HEX2DEC(A39)+2,8) -> 001096F6 | B40: =MID($I$1,1+(ROW(B40)-2)*4,4) -> F501 | C40: =_xlfn.XLOOKUP(B40,Sheet2!C:C,Sheet2!B:B) -> Quick Guard | D40: =C64 -> Breakneck Cannon | E40: =IF(D40="",B40,_xlfn.XLOOKUP(D40,Sheet2!B:B,Sheet2!C:C)) -> 6F02
A41: =DEC2HEX(HEX2DEC(A40)+2,8) -> 001096F8 | B41: =MID($I$1,1+(ROW(B41)-2)*4,4) -> D501 | C41: =_xlfn.XLOOKUP(B41,Sheet2!C:C,Sheet2!B:B) -> Wide Guard | D41: =C65 -> All-Out Pummeling | E41: =IF(D41="",B41,_xlfn.XLOOKUP(D41,Sheet2!B:B,Sheet2!C:C)) -> 7002
A42: =DEC2HEX(HEX2DEC(A41)+2,8) -> 001096FA | B42: =MID($I$1,1+(ROW(B42)-2)*4,4) -> EF01 | C42: =_xlfn.XLOOKUP(B42,Sheet2!C:C,Sheet2!B:B) -> After You | D42: =C66 -> All-Out Soulpunch | E42: =IF(D42="",B42,_xlfn.XLOOKUP(D42,Sheet2!B:B,Sheet2!C:C)) -> 7102
A43: =DEC2HEX(HEX2DEC(A42)+2,8) -> 001096FC | B43: =MID($I$1,1+(ROW(B43)-2)*4,4) -> 4F02 | C43: =_xlfn.XLOOKUP(B43,Sheet2!C:C,Sheet2!B:B) -> Diamond Storm | D43: =C67 -> Supersonic Skystrike | E43: =IF(D43="",B43,_xlfn.XLOOKUP(D43,Sheet2!B:B,Sheet2!C:C)) -> 7202
A44: =DEC2HEX(HEX2DEC(A43)+2,8) -> 001096FE | B44: =MID($I$1,1+(ROW(B44)-2)*4,4) -> 5002 | C44: =_xlfn.XLOOKUP(B44,Sheet2!C:C,Sheet2!B:B) -> Steam Eruption | D44: =C68 -> Supersonic Skyblast | E44: =IF(D44="",B44,_xlfn.XLOOKUP(D44,Sheet2!B:B,Sheet2!C:C)) -> 7302
A45: =DEC2HEX(HEX2DEC(A44)+2,8) -> 00109700 | B45: =MID($I$1,1+(ROW(B45)-2)*4,4) -> 5102 | C45: =_xlfn.XLOOKUP(B45,Sheet2!C:C,Sheet2!B:B) -> Hyperspace Hole | D45: =C69 -> Acid Deluge | E45: =IF(D45="",B45,_xlfn.XLOOKUP(D45,Sheet2!B:B,Sheet2!C:C)) -> 7402
A46: =DEC2HEX(HEX2DEC(A45)+2,8) -> 00109702 | B46: =MID($I$1,1+(ROW(B46)-2)*4,4) -> 6602 | C46: =_xlfn.XLOOKUP(B46,Sheet2!C:C,Sheet2!B:B) -> Thousand Arrows | D46: =C70 -> Acid Downpour | E46: =IF(D46="",B46,_xlfn.XLOOKUP(D46,Sheet2!B:B,Sheet2!C:C)) -> 7502
A47: =DEC2HEX(HEX2DEC(A46)+2,8) -> 00109704 | B47: =MID($I$1,1+(ROW(B47)-2)*4,4) -> 6702 | C47: =_xlfn.XLOOKUP(B47,Sheet2!C:C,Sheet2!B:B) -> Thousand Waves | D47: =C71 -> Tectonic Fury | E47: =IF(D47="",B47,_xlfn.XLOOKUP(D47,Sheet2!B:B,Sheet2!C:C)) -> 7602
...

Sheet Sheet2
A1: 0 | B1: ——— | C1: 0000
A2: 1 | B2: Pound | C2: 0100
A3: 2 | B3: Karate Chop | C3: 0200
A4: 3 | B4: Double Slap | C4: 0300
A5: 4 | B5: Comet Punch | C5: 0400
A6: 5 | B6: Mega Punch | C6: 0500
A7: 6 | B7: Pay Day | C7: 0600
A8: 7 | B8: Fire Punch | C8: 0700
A9: 8 | B9: Ice Punch | C9: 0800
A10: 9 | B10: Thunder Punch | C10: 0900
A11: 10 | B11: Scratch | C11: 0A00
A12: 11 | B12: Vice Grip | C12: 0B00
... A757: 756 | B757: Poltergeist | C757: F402
A758: 757 | C758: F502
A759: 758 | C759: F602
A760: 759 | C760: F702
A761: 760 | C761: F802
A762: 761 | C762: F902
A763: 762 | C763: FA02
A764: 763 | C764: FB02
A765: 764 | C765: FC02
A766: 765 | C766: FD02
A767: 766 | C767: FE02
A768: 767 | C768: FF02
A769: 768 | C769: 0003
... A1453: 1452 | C1453: AC05

Sheet Original
A1: Address | B1: Hex | C1: instruction | D1: notes
A2: Call Function
A3: C24A8 | B3: =_xlfn.CONCAT("0",RIGHT(C3,1),"10A0E3") -> 0310A0E3 | C3: mov r1, 0x3
A4: =DEC2HEX(HEX2DEC(A3)+4,8) -> 000C24AC | B4: 001080E5 | C4: str r1, [r0]
A5: =DEC2HEX(HEX2DEC(A4)+4,8) -> 000C24B0 | B5: 00009FE5 | C5: ldr r0, [pc]
A6: =DEC2HEX(HEX2DEC(A5)+4,8) -> 000C24B4 | B6: 1EFF2FE1 | C6: bx lr
A7: =DEC2HEX(HEX2DEC(A6)+4,8) -> 000C24B8 | B7: 00000000 | C7: andeq r0, r0, r0
A9: Return_Random_Move_Index_Metronome
A10: 000B07F8 | B10: F0412DE9 | C10: push {r4, r5, r6, r7, r8, lr} | D10: push {r4, r5, r6, r7, r8, lr}
A11: =DEC2HEX(HEX2DEC(A10)+4,8) -> 000B07FC | B11: 0060A0E3 | C11: mov r6, #0 | D11: mov r6, #0
A12: =DEC2HEX(HEX2DEC(A11)+4,8) -> 000B0800 | B12: 0120A0E3 | C12: mov r2, #1 | D12: mov r2, #1
A13: =DEC2HEX(HEX2DEC(A12)+4,8) -> 000B0804 | B13: AC409FE5 | C13: ldr r4, [pc, #0xac] | D13: ldr r4, [pc, #0xac]
A14: =DEC2HEX(HEX2DEC(A13)+4,8) -> 000B0808 | B14: 0C7094E5 | C14: ldr r7, [r4, #0xc] | D14: ldr r7, [r4, #0xc]
A15: =DEC2HEX(HEX2DEC(A14)+4,8) -> 000B080C | B15: 000051E3 | C15: cmp r1, #0 | D15: cmp r1, #0
A16: =DEC2HEX(HEX2DEC(A15)+4,8) -> 000B0810 | B16: 1500000A | C16: beq #0xb086c | D16: beq #0xb086c
A17: =DEC2HEX(HEX2DEC(A16)+4,8) -> 000B0814 | B17: 013001E2 | C17: and r3, r1, #1 | D17: and r3, r1, #1
A18: =DEC2HEX(HEX2DEC(A17)+4,8) -> 000B0818 | B18: 000053E3 | C18: cmp r3, #0 | D18: cmp r3, #0
A19: =DEC2HEX(HEX2DEC(A18)+4,8) -> 000B081C | B19: 00C0A0E3 | C19: mov ip, #0 | D19: mov ip, #0
A20: =DEC2HEX(HEX2DEC(A19)+4,8) -> 000B0820 | B20: 0600009A | C20: bls #0xb0840 | D20: bls #0xb0840
A21: =DEC2HEX(HEX2DEC(A20)+4,8) -> 000B0824 | B21: 8C5080E0 | C21: add r5, r0, ip, lsl #1 | D21: add r5, r0, ip, lsl #1
A22: =DEC2HEX(HEX2DEC(A21)+4,8) -> 000B0828 | B22: B080D5E1 | C22: ldrh r8, [r5] | D22: ldrh r8, [r5]
... A43: =DEC2HEX(HEX2DEC(A42)+4,8) -> 000B087C | B43: 012082E2 | C43: add r2, r2, #1 | D43: add r2, r2, #1
A44: =DEC2HEX(HEX2DEC(A43)+4,8) -> 000B0880 | B44: 7220FFE6 | C44: uxth r2, r2 | D44: uxth r2, r2 | F44: Last move index:
A45: =DEC2HEX(HEX2DEC(A44)+4,8) -> 000B0884 | B45: 2F0E52E3 | C45: =_xlfn.CONCAT("cmp r2, 0x",DEC2HEX(MROUND(F45,4))) -> cmp r2, 0x2F0 | D45: cmp r2, #0x2d8 | F45: 751
A46: =DEC2HEX(HEX2DEC(A45)+4,8) -> 000B0888 | B46: DFFFFF9A | C46: =_xlfn.CONCAT("bls 0x",A15) -> bls 0x000B080C | D46: bls #0xb080c
A47: =DEC2HEX(HEX2DEC(A46)+4,8) -> 000B088C | B47: 000056E3 | C47: cmp r6, #0 | D47: cmp r6, #0
A48: =DEC2HEX(HEX2DEC(A47)+4,8) -> 000B0890 | B48: 0000A003 | C48: moveq r0, #0 | D48: moveq r0, #0
A49: =DEC2HEX(HEX2DEC(A48)+4,8) -> 000B0894 | B49: 0600000A | C49: beq #0xb08b4 | D49: beq #0xb08b4
A50: =DEC2HEX(HEX2DEC(A49)+4,8) -> 000B0898 | B50: 080094E5 | C50: ldr r0, [r4, #8] | D50: ldr r0, [r4, #8]
A51: =DEC2HEX(HEX2DEC(A50)+4,8) -> 000B089C | B51: 0610A0E1 | C51: mov r1, r6 | D51: mov r1, r6
A52: =DEC2HEX(HEX2DEC(A51)+4,8) -> 000B08A0 | B52: 603FFDEB | C52: bl #0x628 | D52: bl #0x628
A53: =DEC2HEX(HEX2DEC(A52)+4,8) -> 000B08A4 | B53: 0C1094E5 | C53: ldr r1, [r4, #0xc] | D53: ldr r1, [r4, #0xc]
A54: =DEC2HEX(HEX2DEC(A53)+4,8) -> 000B08A8 | B54: 7000FFE6 | C54: uxth r0, r0 | D54: uxth r0, r0
A55: =DEC2HEX(HEX2DEC(A54)+4,8) -> 000B08AC | B55: 800081E0 | C55: add r0, r1, r0, lsl #1 | D55: add r0, r1, r0, lsl #1
A56: =DEC2HEX(HEX2DEC(A55)+4,8) -> 000B08B0 | B56: B000D0E1 | C56: ldrh r0, [r0] | D56: ldrh r0, [r0]
A57: =DEC2HEX(HEX2DEC(A56)+4,8) -> 000B08B4 | B57: F081BDE8 | C57: =SUBSTITUTE(SUBSTITUTE(C10,"push","pop"),"lr","pc") -> pop {r4, r5, r6, r7, r8, pc} | D57: pop {r4, r5, r6, r7, r8, pc}
A58: =DEC2HEX(HEX2DEC(A57)+4,8) -> 000B08B8 | B58: 00000000 | C58: andeq r0, r0, r0 | D58: andeq r0, r0, r0
